Workbook

Sheet EvalTime
A3: 平均值项:eval_time | B3: 列标签
A4: 行标签 | B4: EC | C4: FD | D4: HB | E4: HW | F4: JV | G4: PEMS-SF | H4: SAD | I4: SRS1 | J4: SRS2 | K4: UWG
A5: MambaSL | B5: 1.46068 | C5: 67.526546 | D5: 3.261446 | E5: 1.3406881 | F5: 1.247594 | G5: 27.571946 | H5: 5.018808 | I5: 1.097938 | J5: 1.22386 | K5: 0.70174003
A6: PatchTST | B6: 1.7533619 | C6: 81.232084 | D6: 3.957448 | E6: 1.29819 | F6: 1.1373779 | G6: 33.57225 | H6: 6.117942 | I6: 1.296392 | J6: 1.474874 | K6: 1.2807981
A7: TimesNet | B7: 8.6224141 | C7: 276.27163 | D7: 18.020698 | E7: 14.025616 | F7: 8.975694 | G7: 47.095868 | H7: 17.073236 | I7: 11.91225 | J7: 6.779388 | K7: 4.4124361

Sheet mlflow-data
A1: run_id | B1: experiment_id | C1: status | D1: artifact_uri | E1: start_time | F1: end_time | G1: metrics.test_start | H1: metrics.accuracy | I1: metrics.f1 | J1: metrics.test_elapsed_seconds | K1: metrics.precision | L1: metrics.train_end | M1: metrics.recall | N1: metrics.test_end | O1: metrics.train_start | P1: metrics.train_elapsed_seconds | Q1: params.mask_rate | R1: params.num_kernels | S1: params.devices | T1: params.des | U1: params.permutation | V1: params.moving_avg | W1: params.pred_len | X1: params.num_workers | Y1: params.n_heads | Z1: params.wdba | AA1: params.d_conv | AB1: params.use_amp | AC1: params.inverse | AD1: params.lradj | AE1: params.run_cmd | AF1: params.down_sampling_window | AG1: params.spawner | AH1: params.use_dtw | AI1: params.features | AJ1: params.e_layers | AK1: params.individual | AL1: params.num_class | AM1: params.tv_B | AN1: params.augmentation_ratio | AO1: params.discdtw | AP1: params.learning_rate | AQ1: params.d_ff | AR1: params.use_gpu | AS1: params.use_norm | AT1: params.top_k | AU1: params.alpha | AV1: params.dropout | AW1: params.scaling | AX1: params.conv_channel | AY1: params.seed | AZ1: params.is_training | BA1: params.patch_len | BB1: params.root_path | BC1: params.seasonal_patterns | BD1: params.patience | BE1: params.discsdtw | BF1: params.task_name | BG1: params.__id | BH1: params.use_D | BI1: params.target | BJ1: params.gcn_depth | BK1: params.extra_tag | BL1: params.use_multi_gpu | BM1: params.down_sampling_layers | BN1: params.tv_dt | BO1: params.gpu_type | BP1: params.d_model | BQ1: params.data_path | BR1: params.expand | BS1: params.embed | BT1: params.tv_C | BU1: params.seg_len | BV1: params.windowwarp | BW1: params.train_epochs | BX1: params.gcn_dropout | BY1: params.timewarp | BZ1: params.args | CA1: params.model | CB1: params.settings | CC1: params.down_sampling_method | CD1: params.seq_len | CE1: params.batch_size | CF1: params.shapedtwwarp | CG1: params.data | CH1: params.label_len | CI1: params.d_layers | CJ1: params.anomaly_ratio | CK1: params.dec_in | CL1: params.envs | CM1: params.c_out | CN1: params.p_hidden_dims | CO1: params.gpu | CP1: params.model_id | CQ1: params.decomp_method | CR1: params.id | CS1: params.enc_in | CT1: params.randompermutation | CU1: params.loss | CV1: params.distil | CW1: params.jitter | CX1: params.channel_independence | CY1: params.p_hidden_layers | CZ1: params.windowslice | DA1: params.magwarp | DB1: params.rotation | DC1: params.device | DD1: params.freq | DE1: params.checkpoints | DF1: params.top_p | DG1: params.node_dim | DH1: params.propalpha | DI1: params.pos | DJ1: params.itr | DK1: params.activation | DL1: params.dtwwarp | DM1: params.skip_channel | DN1: params.factor | DO1: tags.mlflow.source.type | DP1: tags.mlflow.runName | DQ1: tags.mlflow.source.name | DR1: tags.mlflow.user | DS1: dataset | DT1: eval_time
A2: 78d2f29066614cd2a31d0c334cc83886 | B2: 32 | C2: FINISHED | D2: mlflow-artifacts:/32/78d2f29066614cd2a31d0c334cc83886/artifacts | E2: 2026-05-18 20:15:38.654000+00:00 | F2: 2026-05-18 20:19:50.728000+00:00 | G2: 1.7791353e+18 | H2: 0.8565442 | I2: 0.85075862 | J2: 1.5482758 | K2: 0.8565442 | L2: 1.7791353e+18 | M2: 0.84971098 | N2: 1.7791353e+18 | O2: 1.779135e+18 | P2: 172.19626 | Q2: 0.25 | R2: 6 | S2: 0,1,2,3 | T2: Exp | U2: FALSE | V2: 25 | W2: 0 | X2: 10 | Y2: 8 | Z2: FALSE | AA2: 4 | AB2: FALSE | AC2: FALSE | AD2: type1 | AE2: run.py --task_name classification --is_training 1 --root_path ./dataset/PEMS-SF/ --model_id PEMS-SF --model PatchTST --data UEA --e_layers 3 --batch_size 32 --d_model 128 --d_ff 256 --top_k 3 --des Exp --itr 1 --learning_rate 0.001 --train_epochs 1000 --patience 10 --seed 2026 --id 7e9c43feb5f057ebac7f88cf8f9ff7ec788086531e8a82f173ecc096de9232f1 | AF2: 1 | AG2: FALSE | AH2: FALSE | AI2: M | AJ2: 3 | AK2: FALSE | AL2: 7 | AM2: 0 | AN2: 0 | AO2: FALSE | AP2: 0.001 | AQ2: 256 | AR2: TRUE | AS2: 1 | AT2: 3 | AU2: 0.1 | AV2: 0.1 | AW2: FALSE | AX2: 32 | AY2: 2026 | AZ2: 1 | BA2: 16 | BB2: ./dataset/PEMS-SF/ | BC2: Monthly | BD2: 10 | BE2: FALSE | BF2: classification | BG2: 7e9c43feb5f057ebac7f88cf8f9ff7ec788086531e8a82f173ecc096de9232f1 | BH2: 0 | BI2: OT | BJ2: 2 | BL2: FALSE | BM2: 0 | BN2: 0 | BO2: cuda | BP2: 128 | BQ2: ETTh1.csv | BR2: 2 | BS2: timeF | BT2: 0 | BU2: 96 | BV2: FALSE | BW2: 1000 | BX2: 0.3 | BY2: FALSE | BZ2: Namespace(task_name='classification', is_training=1, model_id='PEMS-SF', model='PatchTST', data='UEA', root_path='./dataset/PEMS-SF/', data_path='ETTh1.csv', features='M', target='OT', freq='h', checkpoints='./checkpoints/', seq_len=np.int64(144), label_len=48, pred_len=0, seasonal_patterns='Monthly', inverse=False, mask_rate=0.25, anomaly_ratio=0.25, expand=2, d_conv=4, tv_dt=0, tv_B=0, tv_C=0, use_D=0, top_k=3, num_kernels=6, enc_in=963, dec_in=7, c_out=7, d_model=128, n_heads=8, e_layers=3, d_layers=1, d_ff=256, moving_avg=25, factor=1, distil=True, dropout=0.1, embed='timeF', activation='gelu', channel_independence=1, decomp_method='moving_avg', use_norm=1, down_sampling_layers=0, down_sampling_window=1, down_sampling_method=None, seg_len=96, num_workers=10, itr=1, train_epochs=1000, batch_size=32, patience=10, learning_rate=0.001, des='Exp', loss='MSE', lradj='type1', use_amp=False, use_gpu=True, gpu=0, gpu_type='cuda', use_multi_gpu=False, devices='0,1,2,3', p_hidden_dims=[128, 128], p_hidden_layers=2, use_dtw=False, augmentation_ratio=0, jitter=False, scaling=False, permutation=False, randompermutation=False, magwarp=False, timewarp=False, windowslice=False, windowwarp=False, rotation=False, spawner=False, dtwwarp=False, shapedtwwarp=False, wdba=False, discdtw=False, discsdtw=False, extra_tag='', patch_len=16, node_dim=10, gcn_depth=2, gcn_dropout=0.3, propalpha=0.3, conv_channel=32, skip_channel=32, individual=False, alpha=0.1, top_p=0.5, seed=2026, pos=1, id='7e9c43feb5f057ebac7f88cf8f9ff7ec788086531e8a82f173ecc096de9232f1', device=device(type='cuda', index=0), num_class=7) | CA2: PatchTST | CB2: classification_PEMS-SF_PatchTST_UEA_ftM_sl144_ll48_pl0_dm128_nh8_el3_dl1_df256_expand2_dc4_fc1_ebtimeF_dtTrue_Exp_07e9c43feb5f057ebac7f88cf8f9ff7ec788086531e8a82f173ecc096de9232f1 | CC2: None | CD2: 144 | CE2: 32 | CF2: FALSE | CG2: UEA | CH2: 48 | CI2: 1 | CJ2: 0.25 | CK2: 7 | CL2: {'TMUX': '/tmp/tmux-0/default,1344,0', 'USER': 'root', 'SSH_CLIENT': '10.233.106.128 41191 22', 'SHLVL': '3', 'MOTD_SHOWN': 'pam', 'HOME': '/root', 'OLDPWD': '/root', 'TERM_PROGRAM_VERSION': '3.2a', 'SSH_TTY': '/dev/pts/1', 'LC_CTYPE': 'C.UTF-8', 'CUDA_VISIBLE_DEVICES': '0', 'LOGNAME': 'root', '_': '/mnt/sw_exp_data/miniconda3/envs/tsc1/bin/python', 'TERM': 'screen', 'PATH': '/usr/local/nodejs/bin:/usr/local/nodejs/bin:/usr/local/sbin:/usr/local/bin:/usr/sbin:/usr/bin:/sbin:/bin:/usr/games:/usr/local/games:/snap/bin', 'LS_COLORS': 'rs=0:di=01;34:ln=01;36:mh=00:pi=40;33:so=01;35:do=01;35:bd=40;33;01:cd=40;33;01:or=40;31;01:mi=00:su=37;41:sg=30;43:ca=30;41:tw=30;42:ow=34;42:st=37;44:ex=01;32:*.tar=01;31:*.tgz=01;31:*.arc=01;31:*.arj=01;31:*.taz=01;31:*.lha=01;31:*.lz4=01;31:*.lzh=01;31:*.lzma=01;31:*.tlz=01;31:*.txz=01;31:*.tzo=01;31:*.t7z=01;31:*.zip=01;31:*.z=01;31:*.dz=01;31:*.gz=01;31:*.lrz=01;31:*.lz=01;31:*.lzo=01;31:*.xz=01;31:*.zst=01;31:*.tzst=01;31:*.bz2=01;31:*.bz=01;31:*.tbz=01;31:*.tbz2=01;31:*.tz=01;31:*.deb=01;31:*.rpm=01;31:*.jar=01;31:*.war=01;31:*.ear=01;31:*.sar=01;31:*.rar=01;31:*.alz=01;31:*.ace=01;31:*.zoo=01;31:*.cpio=01;31:*.7z=01;31:*.rz=01;31:*.cab=01;31:*.wim=01;31:*.swm=01;31:*.dwm=01;31:*.esd=01;31:*.jpg=01;35:*.jpeg=01;35:*.mjpg=01;35:*.mjpeg=01;35:*.gif=01;35:*.bmp=01;35:*.pbm=01;35:*.pgm=01;35:*.ppm=01;35:*.tga=01;35:*.xbm=01;35:*.xpm=01;35:*.tif=01;35:*.tiff=01;35:*.png=01;35:*.svg=01;35:*.svgz=01;35:*.mng=01;35:*.pcx=01;35:*.mov=01;35:*.mpg=01;35:*.mpeg=01;35:*.m2v=01;35:*.mkv=01;35:*.webm=01;35:*.webp=01;35:*.ogm=01;35:*.mp4=01;35:*.m4v=01;35:*.mp4v=01;35:*.vob=01;35:*.qt=01;35:*.nuv=01;35:*.wmv=01;35:*.asf=01;35:*.rm=01;35:*.rmvb=01;35:*.flc=01;35:*.avi=01;35:*.fli=01;35:*.flv=01;35:*.gl=01;35:*.dl=01;35:*.xcf=01;35:*.xwd=01;35:*.yuv=01;35:*.cgm=01;35:*.emf=01;35:*.ogv=01;35:*.ogx=01;35:*.aac=00;36:*.au=00;36:*.flac=00;36:*.m4a=00;36:*.mid=00;36:*.midi=00;36:*.mka=00;36:*.mp3=00;36:*.mpc=00;36:*.ogg=00;36:*.ra=00;36:*.wav=00;36:*.oga=00;36:*.opus=00;36:*.spx=00;36:*.xspf=00;36:', 'TERM_PROGRAM': 'tmux', 'MLFLOW_EXPERIMENT': 'time_exp_v3_five_seed', 'SHELL': '/bin/bash', 'PWD': '/mnt/sw_exp_data/tsc', 'SSH_CONNECTION': '10.233.106.128 41191 10.233.116.228 22', 'TZ': 'Asia/Shanghai', 'TMUX_PANE': '%0', '_MLFLOW_TELEMETRY_SESSION_ID': '3b140f3ae629427a9857538b76c16661', 'MLFLOW_TRACKING_USERNAME': 'sunwu', 'MLFLOW_TRACKING_PASSWORD': 'xxxxx', 'MLFLOW_TRACKING_URI': 'http://192.168.10.61:5000', 'MLFLOW_EXPERIMENT_ID': '32', 'KMP_DUPLICATE_LIB_OK': 'True', 'KMP_INIT_AT_FORK': 'FALSE', 'TORCHINDUCTOR_CACHE_DIR': '/tmp/torchinductor_root', 'TRAIN_START': '1779135018824289637', 'TRAIN_END': '1779135304975238686', 'TEST_START': '1779135304975320854', 'TEST_END': '1779135338618971407'} | CM2: 7 | CN2: [128, 128] | CO2: 0 | CP2: PEMS-SF | CQ2: moving_avg | CR2: 7e9c43feb5f057ebac7f88cf8f9ff7ec788086531e8a82f173ecc096de9232f1 | CS2: 963 | CT2: FALSE | CU2: MSE | CV2: TRUE | CW2: FALSE | CX2: 1 | CY2: 2 | CZ2: FALSE | DA2: FALSE | DB2: FALSE | DC2: cuda:0 | DD2: h | DE2: ./checkpoints/ | DF2: 0.5 | DG2: 10 | DH2: 0.3 | DI2: 1 | DJ2: 1 | DK2: gelu | DL2: FALSE | DM2: 32 | DN2: 1 | DO2: LOCAL | DP2: classification_PEMS-SF_PatchTST_UEA_ftM_sl144_ll48_pl0_dm128_nh8_el3_dl1_df256_expand2_dc4_fc1_ebtimeF_dtTrue_Exp_07e9c43feb5f057ebac7f88cf8f9ff7ec788086531e8a82f173ecc096de9232f1 | DQ2: run.py | DR2: sunwu | DS2: =_xlfn.XLOOKUP(CP2,datasetmap!B:B,datasetmap!A:A) -> PEMS-SF | DT2: =(N2-G2)/1000000000 -> 33.64365
A3: 45267c8c5cc24e2aa658de42f88e37fd | B3: 32 | C3: FINISHED | D3: mlflow-artifacts:/32/45267c8c5cc24e2aa658de42f88e37fd/artifacts | E3: 2026-05-18 20:07:43.725000+00:00 | F3: 2026-05-18 20:07:56.686000+00:00 | G3: 1.7791349e+18 | H3: 0.97951235 | I3: 0.97900016 | J3: 0.76139759 | K3: 0.97951235 | L3: 1.7791349e+18 | M3: 0.9790814 | N3: 1.7791349e+18 | O3: 1.7791347e+18 | P3: 171.14479 | Q3: 0.25 | R3: 6 | S3: 0,1,2,3 | T3: Exp | U3: FALSE | V3: 25 | W3: 0 | X3: 10 | Y3: 8 | Z3: FALSE | AA3: 4 | AB3: FALSE | AC3: FALSE | AD3: type1 | AE3: run.py --task_name classification --is_training 1 --root_path ./dataset/SpokenArabicDigits/ --model_id SpokenArabicDigits --model PatchTST --data UEA --e_layers 3 --batch_size 32 --d_model 128 --d_ff 256 --top_k 3 --des Exp --itr 1 --learning_rate 0.001 --train_epochs 1000 --patience 10 --seed 2026 --id 2bacfecb5df1f6c3aabad84b3459c51ee618378e4e06c574a8fbaea92f13f245 | AF3: 1 | AG3: FALSE | AH3: FALSE | AI3: M | AJ3: 3 | AK3: FALSE | AL3: 10 | AM3: 0 | AN3: 0 | AO3: FALSE | AP3: 0.001 | AQ3: 256 | AR3: TRUE | AS3: 1 | AT3: 3 | AU3: 0.1 | AV3: 0.1 | AW3: FALSE | AX3: 32 | AY3: 2026 | AZ3: 1 | BA3: 16 | BB3: ./dataset/SpokenArabicDigits/ | BC3: Monthly | BD3: 10 | BE3: FALSE | BF3: classification | BG3: 2bacfecb5df1f6c3aabad84b3459c51ee618378e4e06c574a8fbaea92f13f245 | BH3: 0 | BI3: OT | BJ3: 2 | BL3: FALSE | BM3: 0 | BN3: 0 | BO3: cuda | BP3: 128 | BQ3: ETTh1.csv | BR3: 2 | BS3: timeF | BT3: 0 | BU3: 96 | BV3: FALSE | BW3: 1000 | BX3: 0.3 | BY3: FALSE | BZ3: Namespace(task_name='classification', is_training=1, model_id='SpokenArabicDigits', model='PatchTST', data='UEA', root_path='./dataset/SpokenArabicDigits/', data_path='ETTh1.csv', features='M', target='OT', freq='h', checkpoints='./checkpoints/', seq_len=93, label_len=48, pred_len=0, seasonal_patterns='Monthly', inverse=False, mask_rate=0.25, anomaly_ratio=0.25, expand=2, d_conv=4, tv_dt=0, tv_B=0, tv_C=0, use_D=0, top_k=3, num_kernels=6, enc_in=13, dec_in=7, c_out=7, d_model=128, n_heads=8, e_layers=3, d_layers=1, d_ff=256, moving_avg=25, factor=1, distil=True, dropout=0.1, embed='timeF', activation='gelu', channel_independence=1, decomp_method='moving_avg', use_norm=1, down_sampling_layers=0, down_sampling_window=1, down_sampling_method=None, seg_len=96, num_workers=10, itr=1, train_epochs=1000, batch_size=32, patience=10, learning_rate=0.001, des='Exp', loss='MSE', lradj='type1', use_amp=False, use_gpu=True, gpu=0, gpu_type='cuda', use_multi_gpu=False, devices='0,1,2,3', p_hidden_dims=[128, 128], p_hidden_layers=2, use_dtw=False, augmentation_ratio=0, jitter=False, scaling=False, permutation=False, randompermutation=False, magwarp=False, timewarp=False, windowslice=False, windowwarp=False, rotation=False, spawner=False, dtwwarp=False, shapedtwwarp=False, wdba=False, discdtw=False, discsdtw=False, extra_tag='', patch_len=16, node_dim=10, gcn_depth=2, gcn_dropout=0.3, propalpha=0.3, conv_channel=32, skip_channel=32, individual=False, alpha=0.1, top_p=0.5, seed=2026, pos=1, id='2bacfecb5df1f6c3aabad84b3459c51ee618378e4e06c574a8fbaea92f13f245', device=device(type='cuda', index=0), num_class=10) | CA3: PatchTST | CB3: classification_SpokenArabicDigits_PatchTST_UEA_ftM_sl93_ll48_pl0_dm128_nh8_el3_dl1_df256_expand2_dc4_fc1_ebtimeF_dtTrue_Exp_02bacfecb5df1f6c3aabad84b3459c51ee618378e4e06c574a8fbaea92f13f245 | CC3: None | CD3: 93 | CE3: 32 | CF3: FALSE | CG3: UEA | CH3: 48 | CI3: 1 | CJ3: 0.25 | CK3: 7 | CL3: {'TMUX': '/tmp/tmux-0/default,1344,0', 'USER': 'root', 'SSH_CLIENT': '10.233.106.128 41191 22', 'SHLVL': '3', 'MOTD_SHOWN': 'pam', 'HOME': '/root', 'OLDPWD': '/root', 'TERM_PROGRAM_VERSION': '3.2a', 'SSH_TTY': '/dev/pts/1', 'LC_CTYPE': 'C.UTF-8', 'CUDA_VISIBLE_DEVICES': '0', 'LOGNAME': 'root', '_': '/mnt/sw_exp_data/miniconda3/envs/tsc1/bin/python', 'TERM': 'screen', 'PATH': '/usr/local/nodejs/bin:/usr/local/nodejs/bin:/usr/local/sbin:/usr/local/bin:/usr/sbin:/usr/bin:/sbin:/bin:/usr/games:/usr/local/games:/snap/bin', 'LS_COLORS': 'rs=0:di=01;34:ln=01;36:mh=00:pi=40;33:so=01;35:do=01;35:bd=40;33;01:cd=40;33;01:or=40;31;01:mi=00:su=37;41:sg=30;43:ca=30;41:tw=30;42:ow=34;42:st=37;44:ex=01;32:*.tar=01;31:*.tgz=01;31:*.arc=01;31:*.arj=01;31:*.taz=01;31:*.lha=01;31:*.lz4=01;31:*.lzh=01;31:*.lzma=01;31:*.tlz=01;31:*.txz=01;31:*.tzo=01;31:*.t7z=01;31:*.zip=01;31:*.z=01;31:*.dz=01;31:*.gz=01;31:*.lrz=01;31:*.lz=01;31:*.lzo=01;31:*.xz=01;31:*.zst=01;31:*.tzst=01;31:*.bz2=01;31:*.bz=01;31:*.tbz=01;31:*.tbz2=01;31:*.tz=01;31:*.deb=01;31:*.rpm=01;31:*.jar=01;31:*.war=01;31:*.ear=01;31:*.sar=01;31:*.rar=01;31:*.alz=01;31:*.ace=01;31:*.zoo=01;31:*.cpio=01;31:*.7z=01;31:*.rz=01;31:*.cab=01;31:*.wim=01;31:*.swm=01;31:*.dwm=01;31:*.esd=01;31:*.jpg=01;35:*.jpeg=01;35:*.mjpg=01;35:*.mjpeg=01;35:*.gif=01;35:*.bmp=01;35:*.pbm=01;35:*.pgm=01;35:*.ppm=01;35:*.tga=01;35:*.xbm=01;35:*.xpm=01;35:*.tif=01;35:*.tiff=01;35:*.png=01;35:*.svg=01;35:*.svgz=01;35:*.mng=01;35:*.pcx=01;35:*.mov=01;35:*.mpg=01;35:*.mpeg=01;35:*.m2v=01;35:*.mkv=01;35:*.webm=01;35:*.webp=01;35:*.ogm=01;35:*.mp4=01;35:*.m4v=01;35:*.mp4v=01;35:*.vob=01;35:*.qt=01;35:*.nuv=01;35:*.wmv=01;35:*.asf=01;35:*.rm=01;35:*.rmvb=01;35:*.flc=01;35:*.avi=01;35:*.fli=01;35:*.flv=01;35:*.gl=01;35:*.dl=01;35:*.xcf=01;35:*.xwd=01;35:*.yuv=01;35:*.cgm=01;35:*.emf=01;35:*.ogv=01;35:*.ogx=01;35:*.aac=00;36:*.au=00;36:*.flac=00;36:*.m4a=00;36:*.mid=00;36:*.midi=00;36:*.mka=00;36:*.mp3=00;36:*.mpc=00;36:*.ogg=00;36:*.ra=00;36:*.wav=00;36:*.oga=00;36:*.opus=00;36:*.spx=00;36:*.xspf=00;36:', 'TERM_PROGRAM': 'tmux', 'MLFLOW_EXPERIMENT': 'time_exp_v3_five_seed', 'SHELL': '/bin/bash', 'PWD': '/mnt/sw_exp_data/tsc', 'SSH_CONNECTION': '10.233.106.128 41191 10.233.116.228 22', 'TZ': 'Asia/Shanghai', 'TMUX_PANE': '%0', '_MLFLOW_TELEMETRY_SESSION_ID': 'cb4ae17985774fe98e569cfb8e285845', 'MLFLOW_TRACKING_USERNAME': 'sunwu', 'MLFLOW_TRACKING_PASSWORD': 'xxxxx', 'MLFLOW_TRACKING_URI': 'http://192.168.10.61:5000', 'MLFLOW_EXPERIMENT_ID': '32', 'KMP_DUPLICATE_LIB_OK': 'True', 'KMP_INIT_AT_FORK': 'FALSE', 'TORCHINDUCTOR_CACHE_DIR': '/tmp/torchinductor_root', 'TRAIN_START': '1779134661101720279', 'TRAIN_END': '1779134857671587728', 'TEST_START': '1779134857671654214', 'TEST_END': '1779134863676272724'} | CM3: 7 | CN3: [128, 128] | CO3: 0 | CP3: SpokenArabicDigits | CQ3: moving_avg | CR3: 2bacfecb5df1f6c3aabad84b3459c51ee618378e4e06c574a8fbaea92f13f245 | CS3: 13 | CT3: FALSE | CU3: MSE | CV3: TRUE | CW3: FALSE | CX3: 1 | CY3: 2 | CZ3: FALSE | DA3: FALSE | DB3: FALSE | DC3: cuda:0 | DD3: h | DE3: ./checkpoints/ | DF3: 0.5 | DG3: 10 | DH3: 0.3 | DI3: 1 | DJ3: 1 | DK3: gelu | DL3: FALSE | DM3: 32 | DN3: 1 | DO3: LOCAL | DP3: classification_SpokenArabicDigits_PatchTST_UEA_ftM_sl93_ll48_pl0_dm128_nh8_el3_dl1_df256_expand2_dc4_fc1_ebtimeF_dtTrue_Exp_02bacfecb5df1f6c3aabad84b3459c51ee618378e4e06c574a8fbaea92f13f245 | DQ3: run.py | DR3: sunwu | DS3: =_xlfn.XLOOKUP(CP3,datasetmap!B:B,datasetmap!A:A) -> SAD | DT3: =(N3-G3)/1000000000 -> 6.00462
A4: dc7af7c24f56469d968edf7f16c446ad | B4: 32 | C4: FINISHED | D4: mlflow-artifacts:/32/dc7af7c24f56469d968edf7f16c446ad/artifacts | E4: 2026-05-18 20:06:39.123000+00:00 | F4: 2026-05-18 20:06:51.162000+00:00 | G4: 1.7791347e+18 | H4: 0.66418864 | I4: 0.66264199 | J4: 2.2074112 | K4: 0.66418864 | L4: 1.7791347e+18 | M4: 0.66316686 | N4: 1.7791348e+18 | O4: 1.7791342e+18 | P4: 225.12234 | Q4: 0.25 | R4: 6 | S4: 0,1,2,3 | T4: Exp | U4: FALSE | V4: 25 | W4: 0 | X4: 10 | Y4: 8 | Z4: FALSE | AA4: 4 | AB4: FALSE | AC4: FALSE | AD4: type1 | AE4: run.py --task_name classification --is_training 1 --root_path ./dataset/FaceDetection/ --model_id FaceDetection --model PatchTST --data UEA --e_layers 3 --batch_size 32 --d_model 128 --d_ff 256 --top_k 3 --des Exp --itr 1 --learning_rate 0.001 --train_epochs 1000 --patience 10 --seed 2026 --id ae67fc8457cf97b1d2eb8b82076b9672b9546ecb66095ff792c5af39b3489eab | AF4: 1 | AG4: FALSE | AH4: FALSE | AI4: M | AJ4: 3 | AK4: FALSE | AL4: 2 | AM4: 0 | AN4: 0 | AO4: FALSE | AP4: 0.001 | AQ4: 256 | AR4: TRUE | AS4: 1 | AT4: 3 | AU4: 0.1 | AV4: 0.1 | AW4: FALSE | AX4: 32 | AY4: 2026 | AZ4: 1 | BA4: 16 | BB4: ./dataset/FaceDetection/ | BC4: Monthly | BD4: 10 | BE4: FALSE | BF4: classification | BG4: ae67fc8457cf97b1d2eb8b82076b9672b9546ecb66095ff792c5af39b3489eab | BH4: 0 | BI4: OT | BJ4: 2 | BL4: FALSE | BM4: 0 | BN4: 0 | BO4: cuda | BP4: 128 | BQ4: ETTh1.csv | BR4: 2 | BS4: timeF | BT4: 0 | BU4: 96 | BV4: FALSE | BW4: 1000 | BX4: 0.3 | BY4: FALSE | BZ4: Namespace(task_name='classification', is_training=1, model_id='FaceDetection', model='PatchTST', data='UEA', root_path='./dataset/FaceDetection/', data_path='ETTh1.csv', features='M', target='OT', freq='h', checkpoints='./checkpoints/', seq_len=np.int64(62), label_len=48, pred_len=0, seasonal_patterns='Monthly', inverse=False, mask_rate=0.25, anomaly_ratio=0.25, expand=2, d_conv=4, tv_dt=0, tv_B=0, tv_C=0, use_D=0, top_k=3, num_kernels=6, enc_in=144, dec_in=7, c_out=7, d_model=128, n_heads=8, e_layers=3, d_layers=1, d_ff=256, moving_avg=25, factor=1, distil=True, dropout=0.1, embed='timeF', activation='gelu', channel_independence=1, decomp_method='moving_avg', use_norm=1, down_sampling_layers=0, down_sampling_window=1, down_sampling_method=None, seg_len=96, num_workers=10, itr=1, train_epochs=1000, batch_size=32, patience=10, learning_rate=0.001, des='Exp', loss='MSE', lradj='type1', use_amp=False, use_gpu=True, gpu=0, gpu_type='cuda', use_multi_gpu=False, devices='0,1,2,3', p_hidden_dims=[128, 128], p_hidden_layers=2, use_dtw=False, augmentation_ratio=0, jitter=False, scaling=False, permutation=False, randompermutation=False, magwarp=False, timewarp=False, windowslice=False, windowwarp=False, rotation=False, spawner=False, dtwwarp=False, shapedtwwarp=False, wdba=False, discdtw=False, discsdtw=False, extra_tag='', patch_len=16, node_dim=10, gcn_depth=2, gcn_dropout=0.3, propalpha=0.3, conv_channel=32, skip_channel=32, individual=False, alpha=0.1, top_p=0.5, seed=2026, pos=1, id='ae67fc8457cf97b1d2eb8b82076b9672b9546ecb66095ff792c5af39b3489eab', device=device(type='cuda', index=0), num_class=2) | CA4: PatchTST | CB4: classification_FaceDetection_PatchTST_UEA_ftM_sl62_ll48_pl0_dm128_nh8_el3_dl1_df256_expand2_dc4_fc1_ebtimeF_dtTrue_Exp_0ae67fc8457cf97b1d2eb8b82076b9672b9546ecb66095ff792c5af39b3489eab | CC4: None | CD4: 62 | CE4: 32 | CF4: FALSE | CG4: UEA | CH4: 48 | CI4: 1 | CJ4: 0.25 | CK4: 7 | CL4: {'TMUX': '/tmp/tmux-0/default,1344,0', 'USER': 'root', 'SSH_CLIENT': '10.233.106.128 41191 22', 'SHLVL': '3', 'MOTD_SHOWN': 'pam', 'HOME': '/root', 'OLDPWD': '/root', 'TERM_PROGRAM_VERSION': '3.2a', 'SSH_TTY': '/dev/pts/1', 'LC_CTYPE': 'C.UTF-8', 'CUDA_VISIBLE_DEVICES': '0', 'LOGNAME': 'root', '_': '/mnt/sw_exp_data/miniconda3/envs/tsc1/bin/python', 'TERM': 'screen', 'PATH': '/usr/local/nodejs/bin:/usr/local/nodejs/bin:/usr/local/sbin:/usr/local/bin:/usr/sbin:/usr/bin:/sbin:/bin:/usr/games:/usr/local/games:/snap/bin', 'LS_COLORS': 'rs=0:di=01;34:ln=01;36:mh=00:pi=40;33:so=01;35:do=01;35:bd=40;33;01:cd=40;33;01:or=40;31;01:mi=00:su=37;41:sg=30;43:ca=30;41:tw=30;42:ow=34;42:st=37;44:ex=01;32:*.tar=01;31:*.tgz=01;31:*.arc=01;31:*.arj=01;31:*.taz=01;31:*.lha=01;31:*.lz4=01;31:*.lzh=01;31:*.lzma=01;31:*.tlz=01;31:*.txz=01;31:*.tzo=01;31:*.t7z=01;31:*.zip=01;31:*.z=01;31:*.dz=01;31:*.gz=01;31:*.lrz=01;31:*.lz=01;31:*.lzo=01;31:*.xz=01;31:*.zst=01;31:*.tzst=01;31:*.bz2=01;31:*.bz=01;31:*.tbz=01;31:*.tbz2=01;31:*.tz=01;31:*.deb=01;31:*.rpm=01;31:*.jar=01;31:*.war=01;31:*.ear=01;31:*.sar=01;31:*.rar=01;31:*.alz=01;31:*.ace=01;31:*.zoo=01;31:*.cpio=01;31:*.7z=01;31:*.rz=01;31:*.cab=01;31:*.wim=01;31:*.swm=01;31:*.dwm=01;31:*.esd=01;31:*.jpg=01;35:*.jpeg=01;35:*.mjpg=01;35:*.mjpeg=01;35:*.gif=01;35:*.bmp=01;35:*.pbm=01;35:*.pgm=01;35:*.ppm=01;35:*.tga=01;35:*.xbm=01;35:*.xpm=01;35:*.tif=01;35:*.tiff=01;35:*.png=01;35:*.svg=01;35:*.svgz=01;35:*.mng=01;35:*.pcx=01;35:*.mov=01;35:*.mpg=01;35:*.mpeg=01;35:*.m2v=01;35:*.mkv=01;35:*.webm=01;35:*.webp=01;35:*.ogm=01;35:*.mp4=01;35:*.m4v=01;35:*.mp4v=01;35:*.vob=01;35:*.qt=01;35:*.nuv=01;35:*.wmv=01;35:*.asf=01;35:*.rm=01;35:*.rmvb=01;35:*.flc=01;35:*.avi=01;35:*.fli=01;35:*.flv=01;35:*.gl=01;35:*.dl=01;35:*.xcf=01;35:*.xwd=01;35:*.yuv=01;35:*.cgm=01;35:*.emf=01;35:*.ogv=01;35:*.ogx=01;35:*.aac=00;36:*.au=00;36:*.flac=00;36:*.m4a=00;36:*.mid=00;36:*.midi=00;36:*.mka=00;36:*.mp3=00;36:*.mpc=00;36:*.ogg=00;36:*.ra=00;36:*.wav=00;36:*.oga=00;36:*.opus=00;36:*.spx=00;36:*.xspf=00;36:', 'TERM_PROGRAM': 'tmux', 'MLFLOW_EXPERIMENT': 'time_exp_v3_five_seed', 'SHELL': '/bin/bash', 'PWD': '/mnt/sw_exp_data/tsc', 'SSH_CONNECTION': '10.233.106.128 41191 10.233.116.228 22', 'TZ': 'Asia/Shanghai', 'TMUX_PANE': '%0', '_MLFLOW_TELEMETRY_SESSION_ID': 'b90f95f2c4f94f8482d4b4bc7f40e84b', 'MLFLOW_TRACKING_USERNAME': 'sunwu', 'MLFLOW_TRACKING_PASSWORD': 'xxxxx', 'MLFLOW_TRACKING_URI': 'http://192.168.10.61:5000', 'MLFLOW_EXPERIMENT_ID': '32', 'KMP_DUPLICATE_LIB_OK': 'True', 'KMP_INIT_AT_FORK': 'FALSE', 'TORCHINDUCTOR_CACHE_DIR': '/tmp/torchinductor_root', 'TRAIN_START': '1779134199090866439', 'TRAIN_END': '1779134717180068400', 'TEST_START': '1779134717180125225', 'TEST_END': '1779134799074922522'} | CM4: 7 | CN4: [128, 128] | CO4: 0 | CP4: FaceDetection | CQ4: moving_avg | CR4: ae67fc8457cf97b1d2eb8b82076b9672b9546ecb66095ff792c5af39b3489eab | CS4: 144 | CT4: FALSE | CU4: MSE | CV4: TRUE | CW4: FALSE | CX4: 1 | CY4: 2 | CZ4: FALSE | DA4: FALSE | DB4: FALSE | DC4: cuda:0 | DD4: h | DE4: ./checkpoints/ | DF4: 0.5 | DG4: 10 | DH4: 0.3 | DI4: 1 | DJ4: 1 | DK4: gelu | DL4: FALSE | DM4: 32 | DN4: 1 | DO4: LOCAL | DP4: classification_FaceDetection_PatchTST_UEA_ftM_sl62_ll48_pl0_dm128_nh8_el3_dl1_df256_expand2_dc4_fc1_ebtimeF_dtTrue_Exp_0ae67fc8457cf97b1d2eb8b82076b9672b9546ecb66095ff792c5af39b3489eab | DQ4: run.py | DR4: sunwu | DS4: =_xlfn.XLOOKUP(CP4,datasetmap!B:B,datasetmap!A:A) -> FD | DT4: =(N4-G4)/1000000000 -> 81.8948
A5: 20bae3b803fb4510901aadc48310ef3d | B5: 32 | C5: FINISHED | D5: mlflow-artifacts:/32/20bae3b803fb4510901aadc48310ef3d/artifacts | E5: 2026-05-18 20:03:31.532000+00:00 | F5: 2026-05-18 20:03:37.211000+00:00 | G5: 1.7791346e+18 | H5: 0.48316498 | I5: 0.48203843 | J5: 0.8390156 | K5: 0.48316498 | L5: 1.7791346e+18 | M5: 0.48333333 | N5: 1.7791346e+18 | O5: 1.7791345e+18 | P5: 64.371999 | Q5: 0.25 | R5: 6 | S5: 0,1,2,3 | T5: Exp | U5: FALSE | V5: 25 | W5: 0 | X5: 10 | Y5: 8 | Z5: FALSE | AA5: 4 | AB5: FALSE | AC5: FALSE | AD5: type1 | AE5: run.py --task_name classification --is_training 1 --root_path ./dataset/SelfRegulationSCP2/ --model_id SelfRegulationSCP2 --model PatchTST --data UEA --e_layers 3 --batch_size 32 --d_model 128 --d_ff 256 --top_k 3 --des Exp --itr 1 --learning_rate 0.001 --train_epochs 1000 --patience 10 --seed 2026 --id 5e0ec475124df73a8051fc0ef87242fe511915f156ae906e17e5ccb5ad333b8f | AF5: 1 | AG5: FALSE | AH5: FALSE | AI5: M | AJ5: 3 | AK5: FALSE | AL5: 2 | AM5: 0 | AN5: 0 | AO5: FALSE | AP5: 0.001 | AQ5: 256 | AR5: TRUE | AS5: 1 | AT5: 3 | AU5: 0.1 | AV5: 0.1 | AW5: FALSE | AX5: 32 | AY5: 2026 | AZ5: 1 | BA5: 16 | BB5: ./dataset/SelfRegulationSCP2/ | BC5: Monthly | BD5: 10 | BE5: FALSE | BF5: classification | BG5: 5e0ec475124df73a8051fc0ef87242fe511915f156ae906e17e5ccb5ad333b8f | BH5: 0 | BI5: OT | BJ5: 2 | BL5: FALSE | BM5: 0 | BN5: 0 | BO5: cuda | BP5: 128 | BQ5: ETTh1.csv | BR5: 2 | BS5: timeF | BT5: 0 | BU5: 96 | BV5: FALSE | BW5: 1000 | BX5: 0.3 | BY5: FALSE | BZ5: Namespace(task_name='classification', is_training=1, model_id='SelfRegulationSCP2', model='PatchTST', data='UEA', root_path='./dataset/SelfRegulationSCP2/', data_path='ETTh1.csv', features='M', target='OT', freq='h', checkpoints='./checkpoints/', seq_len=np.int64(1152), label_len=48, pred_len=0, seasonal_patterns='Monthly', inverse=False, mask_rate=0.25, anomaly_ratio=0.25, expand=2, d_conv=4, tv_dt=0, tv_B=0, tv_C=0, use_D=0, top_k=3, num_kernels=6, enc_in=7, dec_in=7, c_out=7, d_model=128, n_heads=8, e_layers=3, d_layers=1, d_ff=256, moving_avg=25, factor=1, distil=True, dropout=0.1, embed='timeF', activation='gelu', channel_independence=1, decomp_method='moving_avg', use_norm=1, down_sampling_layers=0, down_sampling_window=1, down_sampling_method=None, seg_len=96, num_workers=10, itr=1, train_epochs=1000, batch_size=32, patience=10, learning_rate=0.001, des='Exp', loss='MSE', lradj='type1', use_amp=False, use_gpu=True, gpu=0, gpu_type='cuda', use_multi_gpu=False, devices='0,1,2,3', p_hidden_dims=[128, 128], p_hidden_layers=2, use_dtw=False, augmentation_ratio=0, jitter=False, scaling=False, permutation=False, randompermutation=False, magwarp=False, timewarp=False, windowslice=False, windowwarp=False, rotation=False, spawner=False, dtwwarp=False, shapedtwwarp=False, wdba=False, discdtw=False, discsdtw=False, extra_tag='', patch_len=16, node_dim=10, gcn_depth=2, gcn_dropout=0.3, propalpha=0.3, conv_channel=32, skip_channel=32, individual=False, alpha=0.1, top_p=0.5, seed=2026, pos=1, id='5e0ec475124df73a8051fc0ef87242fe511915f156ae906e17e5ccb5ad333b8f', device=device(type='cuda', index=0), num_class=2) | CA5: PatchTST | CB5: classification_SelfRegulationSCP2_PatchTST_UEA_ftM_sl1152_ll48_pl0_dm128_nh8_el3_dl1_df256_expand2_dc4_fc1_ebtimeF_dtTrue_Exp_05e0ec475124df73a8051fc0ef87242fe511915f156ae906e17e5ccb5ad333b8f | CC5: None | CD5: 1152 | CE5: 32 | CF5: FALSE | CG5: UEA | CH5: 48 | CI5: 1 | CJ5: 0.25 | CK5: 7 | CL5: {'TMUX': '/tmp/tmux-0/default,1344,0', 'USER': 'root', 'SSH_CLIENT': '10.233.106.128 41191 22', 'SHLVL': '3', 'MOTD_SHOWN': 'pam', 'HOME': '/root', 'OLDPWD': '/root', 'TERM_PROGRAM_VERSION': '3.2a', 'SSH_TTY': '/dev/pts/1', 'LC_CTYPE': 'C.UTF-8', 'CUDA_VISIBLE_DEVICES': '0', 'LOGNAME': 'root', '_': '/mnt/sw_exp_data/miniconda3/envs/tsc1/bin/python', 'TERM': 'screen', 'PATH': '/usr/local/nodejs/bin:/usr/local/nodejs/bin:/usr/local/sbin:/usr/local/bin:/usr/sbin:/usr/bin:/sbin:/bin:/usr/games:/usr/local/games:/snap/bin', 'LS_COLORS': 'rs=0:di=01;34:ln=01;36:mh=00:pi=40;33:so=01;35:do=01;35:bd=40;33;01:cd=40;33;01:or=40;31;01:mi=00:su=37;41:sg=30;43:ca=30;41:tw=30;42:ow=34;42:st=37;44:ex=01;32:*.tar=01;31:*.tgz=01;31:*.arc=01;31:*.arj=01;31:*.taz=01;31:*.lha=01;31:*.lz4=01;31:*.lzh=01;31:*.lzma=01;31:*.tlz=01;31:*.txz=01;31:*.tzo=01;31:*.t7z=01;31:*.zip=01;31:*.z=01;31:*.dz=01;31:*.gz=01;31:*.lrz=01;31:*.lz=01;31:*.lzo=01;31:*.xz=01;31:*.zst=01;31:*.tzst=01;31:*.bz2=01;31:*.bz=01;31:*.tbz=01;31:*.tbz2=01;31:*.tz=01;31:*.deb=01;31:*.rpm=01;31:*.jar=01;31:*.war=01;31:*.ear=01;31:*.sar=01;31:*.rar=01;31:*.alz=01;31:*.ace=01;31:*.zoo=01;31:*.cpio=01;31:*.7z=01;31:*.rz=01;31:*.cab=01;31:*.wim=01;31:*.swm=01;31:*.dwm=01;31:*.esd=01;31:*.jpg=01;35:*.jpeg=01;35:*.mjpg=01;35:*.mjpeg=01;35:*.gif=01;35:*.bmp=01;35:*.pbm=01;35:*.pgm=01;35:*.ppm=01;35:*.tga=01;35:*.xbm=01;35:*.xpm=01;35:*.tif=01;35:*.tiff=01;35:*.png=01;35:*.svg=01;35:*.svgz=01;35:*.mng=01;35:*.pcx=01;35:*.mov=01;35:*.mpg=01;35:*.mpeg=01;35:*.m2v=01;35:*.mkv=01;35:*.webm=01;35:*.webp=01;35:*.ogm=01;35:*.mp4=01;35:*.m4v=01;35:*.mp4v=01;35:*.vob=01;35:*.qt=01;35:*.nuv=01;35:*.wmv=01;35:*.asf=01;35:*.rm=01;35:*.rmvb=01;35:*.flc=01;35:*.avi=01;35:*.fli=01;35:*.flv=01;35:*.gl=01;35:*.dl=01;35:*.xcf=01;35:*.xwd=01;35:*.yuv=01;35:*.cgm=01;35:*.emf=01;35:*.ogv=01;35:*.ogx=01;35:*.aac=00;36:*.au=00;36:*.flac=00;36:*.m4a=00;36:*.mid=00;36:*.midi=00;36:*.mka=00;36:*.mp3=00;36:*.mpc=00;36:*.ogg=00;36:*.ra=00;36:*.wav=00;36:*.oga=00;36:*.opus=00;36:*.spx=00;36:*.xspf=00;36:', 'TERM_PROGRAM': 'tmux', 'MLFLOW_EXPERIMENT': 'time_exp_v3_five_seed', 'SHELL': '/bin/bash', 'PWD': '/mnt/sw_exp_data/tsc', 'SSH_CONNECTION': '10.233.106.128 41191 10.233.116.228 22', 'TZ': 'Asia/Shanghai', 'TMUX_PANE': '%0', '_MLFLOW_TELEMETRY_SESSION_ID': '3c0ab1173f094af08fb0bd11460fb0bb', 'MLFLOW_TRACKING_USERNAME': 'sunwu', 'MLFLOW_TRACKING_PASSWORD': 'xxxxx', 'MLFLOW_TRACKING_URI': 'http://192.168.10.61:5000', 'MLFLOW_EXPERIMENT_ID': '32', 'KMP_DUPLICATE_LIB_OK': 'True', 'KMP_INIT_AT_FORK': 'FALSE', 'TORCHINDUCTOR_CACHE_DIR': '/tmp/torchinductor_root', 'TRAIN_START': '1779134543216645266', 'TRAIN_END': '1779134609969831681', 'TEST_START': '1779134609969894184', 'TEST_END': '1779134611469228904'} | CM5: 7 | CN5: [128, 128] | CO5: 0 | CP5: SelfRegulationSCP2 | CQ5: moving_avg | CR5: 5e0ec475124df73a8051fc0ef87242fe511915f156ae906e17e5ccb5ad333b8f | CS5: 7 | CT5: FALSE | CU5: MSE | CV5: TRUE | CW5: FALSE | CX5: 1 | CY5: 2 | CZ5: FALSE | DA5: FALSE | DB5: FALSE | DC5: cuda:0 | DD5: h | DE5: ./checkpoints/ | DF5: 0.5 | DG5: 10 | DH5: 0.3 | DI5: 1 | DJ5: 1 | DK5: gelu | DL5: FALSE | DM5: 32 | DN5: 1 | DO5: LOCAL | DP5: classification_SelfRegulationSCP2_PatchTST_UEA_ftM_sl1152_ll48_pl0_dm128_nh8_el3_dl1_df256_expand2_dc4_fc1_ebtimeF_dtTrue_Exp_05e0ec475124df73a8051fc0ef87242fe511915f156ae906e17e5ccb5ad333b8f | DQ5: run.py | DR5: sunwu | DS5: =_xlfn.XLOOKUP(CP5,datasetmap!B:B,datasetmap!A:A) -> SRS2 | DT5: =(N5-G5)/1000000000 -> 1.49933
A6: 81c0cefd498f47ada57611a2af61456c | B6: 32 | C6: FINISHED | D6: mlflow-artifacts:/32/81c0cefd498f47ada57611a2af61456c/artifacts | E6: 2026-05-18 20:01:58.139000+00:00 | F6: 2026-05-18 20:02:03.360000+00:00 | G6: 1.7791345e+18 | H6: 0.83127086 | I6: 0.80147673 | J6: 0.45789028 | K6: 0.83127086 | L6: 1.7791345e+18 | M6: 0.80546075 | N6: 1.7791345e+18 | O6: 1.7791345e+18 | P6: 24.613549 | Q6: 0.25 | R6: 6 | S6: 0,1,2,3 | T6: Exp | U6: FALSE | V6: 25 | W6: 0 | X6: 10 | Y6: 8 | Z6: FALSE | AA6: 4 | AB6: FALSE | AC6: FALSE | AD6: type1 | AE6: run.py --task_name classification --is_training 1 --root_path ./dataset/SelfRegulationSCP1/ --model_id SelfRegulationSCP1 --model PatchTST --data UEA --e_layers 3 --batch_size 32 --d_model 128 --d_ff 256 --top_k 3 --des Exp --itr 1 --learning_rate 0.001 --train_epochs 1000 --patience 10 --seed 2026 --id 2498077efd113788834027269e88238a63b4c4d9fec922d1b9073470310b3c50 | AF6: 1 | AG6: FALSE | AH6: FALSE | AI6: M | AJ6: 3 | AK6: FALSE | AL6: 2 | AM6: 0 | AN6: 0 | AO6: FALSE | AP6: 0.001 | AQ6: 256 | AR6: TRUE | AS6: 1 | AT6: 3 | AU6: 0.1 | AV6: 0.1 | AW6: FALSE | AX6: 32 | AY6: 2026 | AZ6: 1 | BA6: 16 | BB6: ./dataset/SelfRegulationSCP1/ | BC6: Monthly | BD6: 10 | BE6: FALSE | BF6: classification | BG6: 2498077efd113788834027269e88238a63b4c4d9fec922d1b9073470310b3c50 | BH6: 0 | BI6: OT | BJ6: 2 | BL6: FALSE | BM6: 0 | BN6: 0 | BO6: cuda | BP6: 128 | BQ6: ETTh1.csv | BR6: 2 | BS6: timeF | BT6: 0 | BU6: 96 | BV6: FALSE | BW6: 1000 | BX6: 0.3 | BY6: FALSE | BZ6: Namespace(task_name='classification', is_training=1, model_id='SelfRegulationSCP1', model='PatchTST', data='UEA', root_path='./dataset/SelfRegulationSCP1/', data_path='ETTh1.csv', features='M', target='OT', freq='h', checkpoints='./checkpoints/', seq_len=np.int64(896), label_len=48, pred_len=0, seasonal_patterns='Monthly', inverse=False, mask_rate=0.25, anomaly_ratio=0.25, expand=2, d_conv=4, tv_dt=0, tv_B=0, tv_C=0, use_D=0, top_k=3, num_kernels=6, enc_in=6, dec_in=7, c_out=7, d_model=128, n_heads=8, e_layers=3, d_layers=1, d_ff=256, moving_avg=25, factor=1, distil=True, dropout=0.1, embed='timeF', activation='gelu', channel_independence=1, decomp_method='moving_avg', use_norm=1, down_sampling_layers=0, down_sampling_window=1, down_sampling_method=None, seg_len=96, num_workers=10, itr=1, train_epochs=1000, batch_size=32, patience=10, learning_rate=0.001, des='Exp', loss='MSE', lradj='type1', use_amp=False, use_gpu=True, gpu=0, gpu_type='cuda', use_multi_gpu=False, devices='0,1,2,3', p_hidden_dims=[128, 128], p_hidden_layers=2, use_dtw=False, augmentation_ratio=0, jitter=False, scaling=False, permutation=False, randompermutation=False, magwarp=False, timewarp=False, windowslice=False, windowwarp=False, rotation=False, spawner=False, dtwwarp=False, shapedtwwarp=False, wdba=False, discdtw=False, discsdtw=False, extra_tag='', patch_len=16, node_dim=10, gcn_depth=2, gcn_dropout=0.3, propalpha=0.3, conv_channel=32, skip_channel=32, individual=False, alpha=0.1, top_p=0.5, seed=2026, pos=1, id='2498077efd113788834027269e88238a63b4c4d9fec922d1b9073470310b3c50', device=device(type='cuda', index=0), num_class=2) | CA6: PatchTST | CB6: classification_SelfRegulationSCP1_PatchTST_UEA_ftM_sl896_ll48_pl0_dm128_nh8_el3_dl1_df256_expand2_dc4_fc1_ebtimeF_dtTrue_Exp_02498077efd113788834027269e88238a63b4c4d9fec922d1b9073470310b3c50 | CC6: None | CD6: 896 | CE6: 32 | CF6: FALSE | CG6: UEA | CH6: 48 | CI6: 1 | CJ6: 0.25 | CK6: 7 | CL6: {'TMUX': '/tmp/tmux-0/default,1344,0', 'USER': 'root', 'SSH_CLIENT': '10.233.106.128 41191 22', 'SHLVL': '3', 'MOTD_SHOWN': 'pam', 'HOME': '/root', 'OLDPWD': '/root', 'TERM_PROGRAM_VERSION': '3.2a', 'SSH_TTY': '/dev/pts/1', 'LC_CTYPE': 'C.UTF-8', 'CUDA_VISIBLE_DEVICES': '0', 'LOGNAME': 'root', '_': '/mnt/sw_exp_data/miniconda3/envs/tsc1/bin/python', 'TERM': 'screen', 'PATH': '/usr/local/nodejs/bin:/usr/local/nodejs/bin:/usr/local/sbin:/usr/local/bin:/usr/sbin:/usr/bin:/sbin:/bin:/usr/games:/usr/local/games:/snap/bin', 'LS_COLORS': 'rs=0:di=01;34:ln=01;36:mh=00:pi=40;33:so=01;35:do=01;35:bd=40;33;01:cd=40;33;01:or=40;31;01:mi=00:su=37;41:sg=30;43:ca=30;41:tw=30;42:ow=34;42:st=37;44:ex=01;32:*.tar=01;31:*.tgz=01;31:*.arc=01;31:*.arj=01;31:*.taz=01;31:*.lha=01;31:*.lz4=01;31:*.lzh=01;31:*.lzma=01;31:*.tlz=01;31:*.txz=01;31:*.tzo=01;31:*.t7z=01;31:*.zip=01;31:*.z=01;31:*.dz=01;31:*.gz=01;31:*.lrz=01;31:*.lz=01;31:*.lzo=01;31:*.xz=01;31:*.zst=01;31:*.tzst=01;31:*.bz2=01;31:*.bz=01;31:*.tbz=01;31:*.tbz2=01;31:*.tz=01;31:*.deb=01;31:*.rpm=01;31:*.jar=01;31:*.war=01;31:*.ear=01;31:*.sar=01;31:*.rar=01;31:*.alz=01;31:*.ace=01;31:*.zoo=01;31:*.cpio=01;31:*.7z=01;31:*.rz=01;31:*.cab=01;31:*.wim=01;31:*.swm=01;31:*.dwm=01;31:*.esd=01;31:*.jpg=01;35:*.jpeg=01;35:*.mjpg=01;35:*.mjpeg=01;35:*.gif=01;35:*.bmp=01;35:*.pbm=01;35:*.pgm=01;35:*.ppm=01;35:*.tga=01;35:*.xbm=01;35:*.xpm=01;35:*.tif=01;35:*.tiff=01;35:*.png=01;35:*.svg=01;35:*.svgz=01;35:*.mng=01;35:*.pcx=01;35:*.mov=01;35:*.mpg=01;35:*.mpeg=01;35:*.m2v=01;35:*.mkv=01;35:*.webm=01;35:*.webp=01;35:*.ogm=01;35:*.mp4=01;35:*.m4v=01;35:*.mp4v=01;35:*.vob=01;35:*.qt=01;35:*.nuv=01;35:*.wmv=01;35:*.asf=01;35:*.rm=01;35:*.rmvb=01;35:*.flc=01;35:*.avi=01;35:*.fli=01;35:*.flv=01;35:*.gl=01;35:*.dl=01;35:*.xcf=01;35:*.xwd=01;35:*.yuv=01;35:*.cgm=01;35:*.emf=01;35:*.ogv=01;35:*.ogx=01;35:*.aac=00;36:*.au=00;36:*.flac=00;36:*.m4a=00;36:*.mid=00;36:*.midi=00;36:*.mka=00;36:*.mp3=00;36:*.mpc=00;36:*.ogg=00;36:*.ra=00;36:*.wav=00;36:*.oga=00;36:*.opus=00;36:*.spx=00;36:*.xspf=00;36:', 'TERM_PROGRAM': 'tmux', 'MLFLOW_EXPERIMENT': 'time_exp_v3_five_seed', 'SHELL': '/bin/bash', 'PWD': '/mnt/sw_exp_data/tsc', 'SSH_CONNECTION': '10.233.106.128 41191 10.233.116.228 22', 'TZ': 'Asia/Shanghai', 'TMUX_PANE': '%0', '_MLFLOW_TELEMETRY_SESSION_ID': '1ab79d82527246beb53d68718bcc672e', 'MLFLOW_TRACKING_USERNAME': 'sunwu', 'MLFLOW_TRACKING_PASSWORD': 'xxxxx', 'MLFLOW_TRACKING_URI': 'http://192.168.10.61:5000', 'MLFLOW_EXPERIMENT_ID': '32', 'KMP_DUPLICATE_LIB_OK': 'True', 'KMP_INIT_AT_FORK': 'FALSE', 'TORCHINDUCTOR_CACHE_DIR': '/tmp/torchinductor_root', 'TRAIN_START': '1779134489518182820', 'TRAIN_END': '1779134516801944118', 'TEST_START': '1779134516802010081', 'TEST_END': '1779134518083013488'} | CM6: 7 | CN6: [128, 128] | CO6: 0 | CP6: SelfRegulationSCP1 | CQ6: moving_avg | CR6: 2498077efd113788834027269e88238a63b4c4d9fec922d1b9073470310b3c50 | CS6: 6 | CT6: FALSE | CU6: MSE | CV6: TRUE | CW6: FALSE | CX6: 1 | CY6: 2 | CZ6: FALSE | DA6: FALSE | DB6: FALSE | DC6: cuda:0 | DD6: h | DE6: ./checkpoints/ | DF6: 0.5 | DG6: 10 | DH6: 0.3 | DI6: 1 | DJ6: 1 | DK6: gelu | DL6: FALSE | DM6: 32 | DN6: 1 | DO6: LOCAL | DP6: classification_SelfRegulationSCP1_PatchTST_UEA_ftM_sl896_ll48_pl0_dm128_nh8_el3_dl1_df256_expand2_dc4_fc1_ebtimeF_dtTrue_Exp_02498077efd113788834027269e88238a63b4c4d9fec922d1b9073470310b3c50 | DQ6: run.py | DR6: sunwu | DS6: =_xlfn.XLOOKUP(CP6,datasetmap!B:B,datasetmap!A:A) -> SRS1 | DT6: =(N6-G6)/1000000000 -> 1.2809999
A7: 2a8f98daca4e4c928df444bcbadd0c17 | B7: 32 | C7: FINISHED | D7: mlflow-artifacts:/32/2a8f98daca4e4c928df444bcbadd0c17/artifacts | E7: 2026-05-18 20:01:05.445000+00:00 | F7: 2026-05-18 20:01:09.918000+00:00 | G7: 1.7791345e+18 | H7: 0.9530611 | I7: 0.95163857 | J7: 0.43257826 | K7: 0.9530611 | L7: 1.7791345e+18 | M7: 0.95135135 | N7: 1.7791345e+18 | O7: 1.7791344e+18 | P7: 56.569047 | Q7: 0.25 | R7: 6 | S7: 0,1,2,3 | T7: Exp | U7: FALSE | V7: 25 | W7: 0 | X7: 10 | Y7: 8 | Z7: FALSE | AA7: 4 | AB7: FALSE | AC7: FALSE | AD7: type1 | AE7: run.py --task_name classification --is_training 1 --root_path ./dataset/JapaneseVowels/ --model_id JapaneseVowels --model PatchTST --data UEA --e_layers 3 --batch_size 32 --d_model 128 --d_ff 256 --top_k 3 --des Exp --itr 1 --learning_rate 0.001 --train_epochs 1000 --patience 10 --seed 2026 --id b86cf4d08ffc4ae89897de23e26f2a6ef252e8dedadf38f8e2188a512061fd35 | AF7: 1 | AG7: FALSE | AH7: FALSE | AI7: M | AJ7: 3 | AK7: FALSE | AL7: 9 | AM7: 0 | AN7: 0 | AO7: FALSE | AP7: 0.001 | AQ7: 256 | AR7: TRUE | AS7: 1 | AT7: 3 | AU7: 0.1 | AV7: 0.1 | AW7: FALSE | AX7: 32 | AY7: 2026 | AZ7: 1 | BA7: 16 | BB7: ./dataset/JapaneseVowels/ | BC7: Monthly | BD7: 10 | BE7: FALSE | BF7: classification | BG7: b86cf4d08ffc4ae89897de23e26f2a6ef252e8dedadf38f8e2188a512061fd35 | BH7: 0 | BI7: OT | BJ7: 2 | BL7: FALSE | BM7: 0 | BN7: 0 | BO7: cuda | BP7: 128 | BQ7: ETTh1.csv | BR7: 2 | BS7: timeF | BT7: 0 | BU7: 96 | BV7: FALSE | BW7: 1000 | BX7: 0.3 | BY7: FALSE | BZ7: Namespace(task_name='classification', is_training=1, model_id='JapaneseVowels', model='PatchTST', data='UEA', root_path='./dataset/JapaneseVowels/', data_path='ETTh1.csv', features='M', target='OT', freq='h', checkpoints='./checkpoints/', seq_len=29, label_len=48, pred_len=0, seasonal_patterns='Monthly', inverse=False, mask_rate=0.25, anomaly_ratio=0.25, expand=2, d_conv=4, tv_dt=0, tv_B=0, tv_C=0, use_D=0, top_k=3, num_kernels=6, enc_in=12, dec_in=7, c_out=7, d_model=128, n_heads=8, e_layers=3, d_layers=1, d_ff=256, moving_avg=25, factor=1, distil=True, dropout=0.1, embed='timeF', activation='gelu', channel_independence=1, decomp_method='moving_avg', use_norm=1, down_sampling_layers=0, down_sampling_window=1, down_sampling_method=None, seg_len=96, num_workers=10, itr=1, train_epochs=1000, batch_size=32, patience=10, learning_rate=0.001, des='Exp', loss='MSE', lradj='type1', use_amp=False, use_gpu=True, gpu=0, gpu_type='cuda', use_multi_gpu=False, devices='0,1,2,3', p_hidden_dims=[128, 128], p_hidden_layers=2, use_dtw=False, augmentation_ratio=0, jitter=False, scaling=False, permutation=False, randompermutation=False, magwarp=False, timewarp=False, windowslice=False, windowwarp=False, rotation=False, spawner=False, dtwwarp=False, shapedtwwarp=False, wdba=False, discdtw=False, discsdtw=False, extra_tag='', patch_len=16, node_dim=10, gcn_depth=2, gcn_dropout=0.3, propalpha=0.3, conv_channel=32, skip_channel=32, individual=False, alpha=0.1, top_p=0.5, seed=2026, pos=1, id='b86cf4d08ffc4ae89897de23e26f2a6ef252e8dedadf38f8e2188a512061fd35', device=device(type='cuda', index=0), num_class=9) | CA7: PatchTST | CB7: classification_JapaneseVowels_PatchTST_UEA_ftM_sl29_ll48_pl0_dm128_nh8_el3_dl1_df256_expand2_dc4_fc1_ebtimeF_dtTrue_Exp_0b86cf4d08ffc4ae89897de23e26f2a6ef252e8dedadf38f8e2188a512061fd35 | CC7: None | CD7: 29 | CE7: 32 | CF7: FALSE | CG7: UEA | CH7: 48 | CI7: 1 | CJ7: 0.25 | CK7: 7 | CL7: {'TMUX': '/tmp/tmux-0/default,1344,0', 'USER': 'root', 'SSH_CLIENT': '10.233.106.128 41191 22', 'SHLVL': '3', 'MOTD_SHOWN': 'pam', 'HOME': '/root', 'OLDPWD': '/root', 'TERM_PROGRAM_VERSION': '3.2a', 'SSH_TTY': '/dev/pts/1', 'LC_CTYPE': 'C.UTF-8', 'CUDA_VISIBLE_DEVICES': '0', 'LOGNAME': 'root', '_': '/mnt/sw_exp_data/miniconda3/envs/tsc1/bin/python', 'TERM': 'screen', 'PATH': '/usr/local/nodejs/bin:/usr/local/nodejs/bin:/usr/local/sbin:/usr/local/bin:/usr/sbin:/usr/bin:/sbin:/bin:/usr/games:/usr/local/games:/snap/bin', 'LS_COLORS': 'rs=0:di=01;34:ln=01;36:mh=00:pi=40;33:so=01;35:do=01;35:bd=40;33;01:cd=40;33;01:or=40;31;01:mi=00:su=37;41:sg=30;43:ca=30;41:tw=30;42:ow=34;42:st=37;44:ex=01;32:*.tar=01;31:*.tgz=01;31:*.arc=01;31:*.arj=01;31:*.taz=01;31:*.lha=01;31:*.lz4=01;31:*.lzh=01;31:*.lzma=01;31:*.tlz=01;31:*.txz=01;31:*.tzo=01;31:*.t7z=01;31:*.zip=01;31:*.z=01;31:*.dz=01;31:*.gz=01;31:*.lrz=01;31:*.lz=01;31:*.lzo=01;31:*.xz=01;31:*.zst=01;31:*.tzst=01;31:*.bz2=01;31:*.bz=01;31:*.tbz=01;31:*.tbz2=01;31:*.tz=01;31:*.deb=01;31:*.rpm=01;31:*.jar=01;31:*.war=01;31:*.ear=01;31:*.sar=01;31:*.rar=01;31:*.alz=01;31:*.ace=01;31:*.zoo=01;31:*.cpio=01;31:*.7z=01;31:*.rz=01;31:*.cab=01;31:*.wim=01;31:*.swm=01;31:*.dwm=01;31:*.esd=01;31:*.jpg=01;35:*.jpeg=01;35:*.mjpg=01;35:*.mjpeg=01;35:*.gif=01;35:*.bmp=01;35:*.pbm=01;35:*.pgm=01;35:*.ppm=01;35:*.tga=01;35:*.xbm=01;35:*.xpm=01;35:*.tif=01;35:*.tiff=01;35:*.png=01;35:*.svg=01;35:*.svgz=01;35:*.mng=01;35:*.pcx=01;35:*.mov=01;35:*.mpg=01;35:*.mpeg=01;35:*.m2v=01;35:*.mkv=01;35:*.webm=01;35:*.webp=01;35:*.ogm=01;35:*.mp4=01;35:*.m4v=01;35:*.mp4v=01;35:*.vob=01;35:*.qt=01;35:*.nuv=01;35:*.wmv=01;35:*.asf=01;35:*.rm=01;35:*.rmvb=01;35:*.flc=01;35:*.avi=01;35:*.fli=01;35:*.flv=01;35:*.gl=01;35:*.dl=01;35:*.xcf=01;35:*.xwd=01;35:*.yuv=01;35:*.cgm=01;35:*.emf=01;35:*.ogv=01;35:*.ogx=01;35:*.aac=00;36:*.au=00;36:*.flac=00;36:*.m4a=00;36:*.mid=00;36:*.midi=00;36:*.mka=00;36:*.mp3=00;36:*.mpc=00;36:*.ogg=00;36:*.ra=00;36:*.wav=00;36:*.oga=00;36:*.opus=00;36:*.spx=00;36:*.xspf=00;36:', 'TERM_PROGRAM': 'tmux', 'MLFLOW_EXPERIMENT': 'time_exp_v3_five_seed', 'SHELL': '/bin/bash', 'PWD': '/mnt/sw_exp_data/tsc', 'SSH_CONNECTION': '10.233.106.128 41191 10.233.116.228 22', 'TZ': 'Asia/Shanghai', 'TMUX_PANE': '%0', '_MLFLOW_TELEMETRY_SESSION_ID': '800d8f387732443d934280ad806ce85d', 'MLFLOW_TRACKING_USERNAME': 'sunwu', 'MLFLOW_TRACKING_PASSWORD': 'xxxxx', 'MLFLOW_TRACKING_URI': 'http://192.168.10.61:5000', 'MLFLOW_EXPERIMENT_ID': '32', 'KMP_DUPLICATE_LIB_OK': 'True', 'KMP_INIT_AT_FORK': 'FALSE', 'TORCHINDUCTOR_CACHE_DIR': '/tmp/torchinductor_root', 'TRAIN_START': '1779134405299549969', 'TRAIN_END': '1779134464278625376', 'TEST_START': '1779134464278721913', 'TEST_END': '1779134465387271213'} | CM7: 7 | CN7: [128, 128] | CO7: 0 | CP7: JapaneseVowels | CQ7: moving_avg | CR7: b86cf4d08ffc4ae89897de23e26f2a6ef252e8dedadf38f8e2188a512061fd35 | CS7: 12 | CT7: FALSE | CU7: MSE | CV7: TRUE | CW7: FALSE | CX7: 1 | CY7: 2 | CZ7: FALSE | DA7: FALSE | DB7: FALSE | DC7: cuda:0 | DD7: h | DE7: ./checkpoints/ | DF7: 0.5 | DG7: 10 | DH7: 0.3 | DI7: 1 | DJ7: 1 | DK7: gelu | DL7: FALSE | DM7: 32 | DN7: 1 | DO7: LOCAL | DP7: classification_JapaneseVowels_PatchTST_UEA_ftM_sl29_ll48_pl0_dm128_nh8_el3_dl1_df256_expand2_dc4_fc1_ebtimeF_dtTrue_Exp_0b86cf4d08ffc4ae89897de23e26f2a6ef252e8dedadf38f8e2188a512061fd35 | DQ7: run.py | DR7: sunwu | DS7: =_xlfn.XLOOKUP(CP7,datasetmap!B:B,datasetmap!A:A) -> JV | DT7: =(N7-G7)/1000000000 -> 1.1085499
A8: c8d3da638ffe42d788b9ccdd60dc0dd8 | B8: 32 | C8: FINISHED | D8: mlflow-artifacts:/32/c8d3da638ffe42d788b9ccdd60dc0dd8/artifacts | E8: 2026-05-18 19:59:43.038000+00:00 | F8: 2026-05-18 19:59:48.008000+00:00 | G8: 1.7791344e+18 | H8: 0.64803029 | I8: 0.65071575 | J8: 0.53677833 | K8: 0.64803029 | L8: 1.7791344e+18 | M8: 0.65365854 | N8: 1.7791344e+18 | O8: 1.7791343e+18 | P8: 38.226741 | Q8: 0.25 | R8: 6 | S8: 0,1,2,3 | T8: Exp | U8: FALSE | V8: 25 | W8: 0 | X8: 10 | Y8: 8 | Z8: FALSE | AA8: 4 | AB8: FALSE | AC8: FALSE | AD8: type1 | AE8: run.py --task_name classification --is_training 1 --root_path ./dataset/Heartbeat/ --model_id Heartbeat --model PatchTST --data UEA --e_layers 3 --batch_size 32 --d_model 128 --d_ff 256 --top_k 3 --des Exp --itr 1 --learning_rate 0.001 --train_epochs 1000 --patience 10 --seed 2026 --id 83c95b8971616fde171f39d9938ec9403e0335ec288e31413c6c4b0f79ae76dd | AF8: 1 | AG8: FALSE | AH8: FALSE | AI8: M | AJ8: 3 | AK8: FALSE | AL8: 2 | AM8: 0 | AN8: 0 | AO8: FALSE | AP8: 0.001 | AQ8: 256 | AR8: TRUE | AS8: 1 | AT8: 3 | AU8: 0.1 | AV8: 0.1 | AW8: FALSE | AX8: 32 | AY8: 2026 | AZ8: 1 | BA8: 16 | BB8: ./dataset/Heartbeat/ | BC8: Monthly | BD8: 10 | BE8: FALSE | BF8: classification | BG8: 83c95b8971616fde171f39d9938ec9403e0335ec288e31413c6c4b0f79ae76dd | BH8: 0 | BI8: OT | BJ8: 2 | BL8: FALSE | BM8: 0 | BN8: 0 | BO8: cuda | BP8: 128 | BQ8: ETTh1.csv | BR8: 2 | BS8: timeF | BT8: 0 | BU8: 96 | BV8: FALSE | BW8: 1000 | BX8: 0.3 | BY8: FALSE | BZ8: Namespace(task_name='classification', is_training=1, model_id='Heartbeat', model='PatchTST', data='UEA', root_path='./dataset/Heartbeat/', data_path='ETTh1.csv', features='M', target='OT', freq='h', checkpoints='./checkpoints/', seq_len=np.int64(405), label_len=48, pred_len=0, seasonal_patterns='Monthly', inverse=False, mask_rate=0.25, anomaly_ratio=0.25, expand=2, d_conv=4, tv_dt=0, tv_B=0, tv_C=0, use_D=0, top_k=3, num_kernels=6, enc_in=61, dec_in=7, c_out=7, d_model=128, n_heads=8, e_layers=3, d_layers=1, d_ff=256, moving_avg=25, factor=1, distil=True, dropout=0.1, embed='timeF', activation='gelu', channel_independence=1, decomp_method='moving_avg', use_norm=1, down_sampling_layers=0, down_sampling_window=1, down_sampling_method=None, seg_len=96, num_workers=10, itr=1, train_epochs=1000, batch_size=32, patience=10, learning_rate=0.001, des='Exp', loss='MSE', lradj='type1', use_amp=False, use_gpu=True, gpu=0, gpu_type='cuda', use_multi_gpu=False, devices='0,1,2,3', p_hidden_dims=[128, 128], p_hidden_layers=2, use_dtw=False, augmentation_ratio=0, jitter=False, scaling=False, permutation=False, randompermutation=False, magwarp=False, timewarp=False, windowslice=False, windowwarp=False, rotation=False, spawner=False, dtwwarp=False, shapedtwwarp=False, wdba=False, discdtw=False, discsdtw=False, extra_tag='', patch_len=16, node_dim=10, gcn_depth=2, gcn_dropout=0.3, propalpha=0.3, conv_channel=32, skip_channel=32, individual=False, alpha=0.1, top_p=0.5, seed=2026, pos=1, id='83c95b8971616fde171f39d9938ec9403e0335ec288e31413c6c4b0f79ae76dd', device=device(type='cuda', index=0), num_class=2) | CA8: PatchTST | CB8: classification_Heartbeat_PatchTST_UEA_ftM_sl405_ll48_pl0_dm128_nh8_el3_dl1_df256_expand2_dc4_fc1_ebtimeF_dtTrue_Exp_083c95b8971616fde171f39d9938ec9403e0335ec288e31413c6c4b0f79ae76dd | CC8: None | CD8: 405 | CE8: 32 | CF8: FALSE | CG8: UEA | CH8: 48 | CI8: 1 | CJ8: 0.25 | CK8: 7 | CL8: {'TMUX': '/tmp/tmux-0/default,1344,0', 'USER': 'root', 'SSH_CLIENT': '10.233.106.128 41191 22', 'SHLVL': '3', 'MOTD_SHOWN': 'pam', 'HOME': '/root', 'OLDPWD': '/root', 'TERM_PROGRAM_VERSION': '3.2a', 'SSH_TTY': '/dev/pts/1', 'LC_CTYPE': 'C.UTF-8', 'CUDA_VISIBLE_DEVICES': '0', 'LOGNAME': 'root', '_': '/mnt/sw_exp_data/miniconda3/envs/tsc1/bin/python', 'TERM': 'screen', 'PATH': '/usr/local/nodejs/bin:/usr/local/nodejs/bin:/usr/local/sbin:/usr/local/bin:/usr/sbin:/usr/bin:/sbin:/bin:/usr/games:/usr/local/games:/snap/bin', 'LS_COLORS': 'rs=0:di=01;34:ln=01;36:mh=00:pi=40;33:so=01;35:do=01;35:bd=40;33;01:cd=40;33;01:or=40;31;01:mi=00:su=37;41:sg=30;43:ca=30;41:tw=30;42:ow=34;42:st=37;44:ex=01;32:*.tar=01;31:*.tgz=01;31:*.arc=01;31:*.arj=01;31:*.taz=01;31:*.lha=01;31:*.lz4=01;31:*.lzh=01;31:*.lzma=01;31:*.tlz=01;31:*.txz=01;31:*.tzo=01;31:*.t7z=01;31:*.zip=01;31:*.z=01;31:*.dz=01;31:*.gz=01;31:*.lrz=01;31:*.lz=01;31:*.lzo=01;31:*.xz=01;31:*.zst=01;31:*.tzst=01;31:*.bz2=01;31:*.bz=01;31:*.tbz=01;31:*.tbz2=01;31:*.tz=01;31:*.deb=01;31:*.rpm=01;31:*.jar=01;31:*.war=01;31:*.ear=01;31:*.sar=01;31:*.rar=01;31:*.alz=01;31:*.ace=01;31:*.zoo=01;31:*.cpio=01;31:*.7z=01;31:*.rz=01;31:*.cab=01;31:*.wim=01;31:*.swm=01;31:*.dwm=01;31:*.esd=01;31:*.jpg=01;35:*.jpeg=01;35:*.mjpg=01;35:*.mjpeg=01;35:*.gif=01;35:*.bmp=01;35:*.pbm=01;35:*.pgm=01;35:*.ppm=01;35:*.tga=01;35:*.xbm=01;35:*.xpm=01;35:*.tif=01;35:*.tiff=01;35:*.png=01;35:*.svg=01;35:*.svgz=01;35:*.mng=01;35:*.pcx=01;35:*.mov=01;35:*.mpg=01;35:*.mpeg=01;35:*.m2v=01;35:*.mkv=01;35:*.webm=01;35:*.webp=01;35:*.ogm=01;35:*.mp4=01;35:*.m4v=01;35:*.mp4v=01;35:*.vob=01;35:*.qt=01;35:*.nuv=01;35:*.wmv=01;35:*.asf=01;35:*.rm=01;35:*.rmvb=01;35:*.flc=01;35:*.avi=01;35:*.fli=01;35:*.flv=01;35:*.gl=01;35:*.dl=01;35:*.xcf=01;35:*.xwd=01;35:*.yuv=01;35:*.cgm=01;35:*.emf=01;35:*.ogv=01;35:*.ogx=01;35:*.aac=00;36:*.au=00;36:*.flac=00;36:*.m4a=00;36:*.mid=00;36:*.midi=00;36:*.mka=00;36:*.mp3=00;36:*.mpc=00;36:*.ogg=00;36:*.ra=00;36:*.wav=00;36:*.oga=00;36:*.opus=00;36:*.spx=00;36:*.xspf=00;36:', 'TERM_PROGRAM': 'tmux', 'MLFLOW_EXPERIMENT': 'time_exp_v3_five_seed', 'SHELL': '/bin/bash', 'PWD': '/mnt/sw_exp_data/tsc', 'SSH_CONNECTION': '10.233.106.128 41191 10.233.116.228 22', 'TZ': 'Asia/Shanghai', 'TMUX_PANE': '%0', '_MLFLOW_TELEMETRY_SESSION_ID': 'db77e3aacce145be87ec8e4b59e37222', 'MLFLOW_TRACKING_USERNAME': 'sunwu', 'MLFLOW_TRACKING_PASSWORD': 'xxxxx', 'MLFLOW_TRACKING_URI': 'http://192.168.10.61:5000', 'MLFLOW_EXPERIMENT_ID': '32', 'KMP_DUPLICATE_LIB_OK': 'True', 'KMP_INIT_AT_FORK': 'FALSE', 'TORCHINDUCTOR_CACHE_DIR': '/tmp/torchinductor_root', 'TRAIN_START': '1779134330600422053', 'TRAIN_END': '1779134379092112749', 'TEST_START': '1779134379092224025', 'TEST_END': '1779134382968378624'} | CM8: 7 | CN8: [128, 128] | CO8: 0 | CP8: Heartbeat | CQ8: moving_avg | CR8: 83c95b8971616fde171f39d9938ec9403e0335ec288e31413c6c4b0f79ae76dd | CS8: 61 | CT8: FALSE | CU8: MSE | CV8: TRUE | CW8: FALSE | CX8: 1 | CY8: 2 | CZ8: FALSE | DA8: FALSE | DB8: FALSE | DC8: cuda:0 | DD8: h | DE8: ./checkpoints/ | DF8: 0.5 | DG8: 10 | DH8: 0.3 | DI8: 1 | DJ8: 1 | DK8: gelu | DL8: FALSE | DM8: 32 | DN8: 1 | DO8: LOCAL | DP8: classification_Heartbeat_PatchTST_UEA_ftM_sl405_ll48_pl0_dm128_nh8_el3_dl1_df256_expand2_dc4_fc1_ebtimeF_dtTrue_Exp_083c95b8971616fde171f39d9938ec9403e0335ec288e31413c6c4b0f79ae76dd | DQ8: run.py | DR8: sunwu | DS8: =_xlfn.XLOOKUP(CP8,datasetmap!B:B,datasetmap!A:A) -> HB | DT8: =(N8-G8)/1000000000 -> 3.87615
A9: 903ff783e2714fbe917d180ab42ce6c0 | B9: 32 | C9: FINISHED | D9: mlflow-artifacts:/32/903ff783e2714fbe917d180ab42ce6c0/artifacts | E9: 2026-05-18 19:58:03.847000+00:00 | F9: 2026-05-18 19:58:11.656000+00:00 | G9: 1.7791343e+18 | H9: 0.30441212 | I9: 0.25015319 | J9: 0.5226203 | K9: 0.30441212 | L9: 1.7791343e+18 | M9: 0.26470588 | N9: 1.7791343e+18 | O9: 1.7791342e+18 | P9: 48.925015 | Q9: 0.25 | R9: 6 | S9: 0,1,2,3 | T9: Exp | U9: FALSE | V9: 25 | W9: 0 | X9: 10 | Y9: 8 | Z9: FALSE | AA9: 4 | AB9: FALSE | AC9: FALSE | AD9: type1 | AE9: run.py --task_name classification --is_training 1 --root_path ./dataset/Handwriting/ --model_id Handwriting --model PatchTST --data UEA --e_layers 3 --batch_size 32 --d_model 128 --d_ff 256 --top_k 3 --des Exp --itr 1 --learning_rate 0.001 --train_epochs 1000 --patience 10 --seed 2026 --id b00ba4f2fd7f892250cdf379bfc4bc916c19a154bee665b33e0c7e05152f1e70 | AF9: 1 | AG9: FALSE | AH9: FALSE | AI9: M | AJ9: 3 | AK9: FALSE | AL9: 26 | AM9: 0 | AN9: 0 | AO9: FALSE | AP9: 0.001 | AQ9: 256 | AR9: TRUE | AS9: 1 | AT9: 3 | AU9: 0.1 | AV9: 0.1 | AW9: FALSE | AX9: 32 | AY9: 2026 | AZ9: 1 | BA9: 16 | BB9: ./dataset/Handwriting/ | BC9: Monthly | BD9: 10 | BE9: FALSE | BF9: classification | BG9: b00ba4f2fd7f892250cdf379bfc4bc916c19a154bee665b33e0c7e05152f1e70 | BH9: 0 | BI9: OT | BJ9: 2 | BL9: FALSE | BM9: 0 | BN9: 0 | BO9: cuda | BP9: 128 | BQ9: ETTh1.csv | BR9: 2 | BS9: timeF | BT9: 0 | BU9: 96 | BV9: FALSE | BW9: 1000 | BX9: 0.3 | BY9: FALSE | BZ9: Namespace(task_name='classification', is_training=1, model_id='Handwriting', model='PatchTST', data='UEA', root_path='./dataset/Handwriting/', data_path='ETTh1.csv', features='M', target='OT', freq='h', checkpoints='./checkpoints/', seq_len=np.int64(152), label_len=48, pred_len=0, seasonal_patterns='Monthly', inverse=False, mask_rate=0.25, anomaly_ratio=0.25, expand=2, d_conv=4, tv_dt=0, tv_B=0, tv_C=0, use_D=0, top_k=3, num_kernels=6, enc_in=3, dec_in=7, c_out=7, d_model=128, n_heads=8, e_layers=3, d_layers=1, d_ff=256, moving_avg=25, factor=1, distil=True, dropout=0.1, embed='timeF', activation='gelu', channel_independence=1, decomp_method='moving_avg', use_norm=1, down_sampling_layers=0, down_sampling_window=1, down_sampling_method=None, seg_len=96, num_workers=10, itr=1, train_epochs=1000, batch_size=32, patience=10, learning_rate=0.001, des='Exp', loss='MSE', lradj='type1', use_amp=False, use_gpu=True, gpu=0, gpu_type='cuda', use_multi_gpu=False, devices='0,1,2,3', p_hidden_dims=[128, 128], p_hidden_layers=2, use_dtw=False, augmentation_ratio=0, jitter=False, scaling=False, permutation=False, randompermutation=False, magwarp=False, timewarp=False, windowslice=False, windowwarp=False, rotation=False, spawner=False, dtwwarp=False, shapedtwwarp=False, wdba=False, discdtw=False, discsdtw=False, extra_tag='', patch_len=16, node_dim=10, gcn_depth=2, gcn_dropout=0.3, propalpha=0.3, conv_channel=32, skip_channel=32, individual=False, alpha=0.1, top_p=0.5, seed=2026, pos=1, id='b00ba4f2fd7f892250cdf379bfc4bc916c19a154bee665b33e0c7e05152f1e70', device=device(type='cuda', index=0), num_class=26) | CA9: PatchTST | CB9: classification_Handwriting_PatchTST_UEA_ftM_sl152_ll48_pl0_dm128_nh8_el3_dl1_df256_expand2_dc4_fc1_ebtimeF_dtTrue_Exp_0b00ba4f2fd7f892250cdf379bfc4bc916c19a154bee665b33e0c7e05152f1e70 | CC9: None | CD9: 152 | CE9: 32 | CF9: FALSE | CG9: UEA | CH9: 48 | CI9: 1 | CJ9: 0.25 | CK9: 7 | CL9: {'TMUX': '/tmp/tmux-0/default,1344,0', 'USER': 'root', 'SSH_CLIENT': '10.233.106.128 41191 22', 'SHLVL': '3', 'MOTD_SHOWN': 'pam', 'HOME': '/root', 'OLDPWD': '/root', 'TERM_PROGRAM_VERSION': '3.2a', 'SSH_TTY': '/dev/pts/1', 'LC_CTYPE': 'C.UTF-8', 'CUDA_VISIBLE_DEVICES': '0', 'LOGNAME': 'root', '_': '/mnt/sw_exp_data/miniconda3/envs/tsc1/bin/python', 'TERM': 'screen', 'PATH': '/usr/local/nodejs/bin:/usr/local/nodejs/bin:/usr/local/sbin:/usr/local/bin:/usr/sbin:/usr/bin:/sbin:/bin:/usr/games:/usr/local/games:/snap/bin', 'LS_COLORS': 'rs=0:di=01;34:ln=01;36:mh=00:pi=40;33:so=01;35:do=01;35:bd=40;33;01:cd=40;33;01:or=40;31;01:mi=00:su=37;41:sg=30;43:ca=30;41:tw=30;42:ow=34;42:st=37;44:ex=01;32:*.tar=01;31:*.tgz=01;31:*.arc=01;31:*.arj=01;31:*.taz=01;31:*.lha=01;31:*.lz4=01;31:*.lzh=01;31:*.lzma=01;31:*.tlz=01;31:*.txz=01;31:*.tzo=01;31:*.t7z=01;31:*.zip=01;31:*.z=01;31:*.dz=01;31:*.gz=01;31:*.lrz=01;31:*.lz=01;31:*.lzo=01;31:*.xz=01;31:*.zst=01;31:*.tzst=01;31:*.bz2=01;31:*.bz=01;31:*.tbz=01;31:*.tbz2=01;31:*.tz=01;31:*.deb=01;31:*.rpm=01;31:*.jar=01;31:*.war=01;31:*.ear=01;31:*.sar=01;31:*.rar=01;31:*.alz=01;31:*.ace=01;31:*.zoo=01;31:*.cpio=01;31:*.7z=01;31:*.rz=01;31:*.cab=01;31:*.wim=01;31:*.swm=01;31:*.dwm=01;31:*.esd=01;31:*.jpg=01;35:*.jpeg=01;35:*.mjpg=01;35:*.mjpeg=01;35:*.gif=01;35:*.bmp=01;35:*.pbm=01;35:*.pgm=01;35:*.ppm=01;35:*.tga=01;35:*.xbm=01;35:*.xpm=01;35:*.tif=01;35:*.tiff=01;35:*.png=01;35:*.svg=01;35:*.svgz=01;35:*.mng=01;35:*.pcx=01;35:*.mov=01;35:*.mpg=01;35:*.mpeg=01;35:*.m2v=01;35:*.mkv=01;35:*.webm=01;35:*.webp=01;35:*.ogm=01;35:*.mp4=01;35:*.m4v=01;35:*.mp4v=01;35:*.vob=01;35:*.qt=01;35:*.nuv=01;35:*.wmv=01;35:*.asf=01;35:*.rm=01;35:*.rmvb=01;35:*.flc=01;35:*.avi=01;35:*.fli=01;35:*.flv=01;35:*.gl=01;35:*.dl=01;35:*.xcf=01;35:*.xwd=01;35:*.yuv=01;35:*.cgm=01;35:*.emf=01;35:*.ogv=01;35:*.ogx=01;35:*.aac=00;36:*.au=00;36:*.flac=00;36:*.m4a=00;36:*.mid=00;36:*.midi=00;36:*.mka=00;36:*.mp3=00;36:*.mpc=00;36:*.ogg=00;36:*.ra=00;36:*.wav=00;36:*.oga=00;36:*.opus=00;36:*.spx=00;36:*.xspf=00;36:', 'TERM_PROGRAM': 'tmux', 'MLFLOW_EXPERIMENT': 'time_exp_v3_five_seed', 'SHELL': '/bin/bash', 'PWD': '/mnt/sw_exp_data/tsc', 'SSH_CONNECTION': '10.233.106.128 41191 10.233.116.228 22', 'TZ': 'Asia/Shanghai', 'TMUX_PANE': '%0', '_MLFLOW_TELEMETRY_SESSION_ID': 'f2c63f2437154be6bc9e843297eb7baf', 'MLFLOW_TRACKING_USERNAME': 'sunwu', 'MLFLOW_TRACKING_PASSWORD': 'xxxxx', 'MLFLOW_TRACKING_URI': 'http://192.168.10.61:5000', 'MLFLOW_EXPERIMENT_ID': '32', 'KMP_DUPLICATE_LIB_OK': 'True', 'KMP_INIT_AT_FORK': 'FALSE', 'TORCHINDUCTOR_CACHE_DIR': '/tmp/torchinductor_root', 'TRAIN_START': '1779134231385974531', 'TRAIN_END': '1779134282515841646', 'TEST_START': '1779134282515993522', 'TEST_END': '1779134283800329578'} | CM9: 7 | CN9: [128, 128] | CO9: 0 | CP9: Handwriting | CQ9: moving_avg | CR9: b00ba4f2fd7f892250cdf379bfc4bc916c19a154bee665b33e0c7e05152f1e70 | CS9: 3 | CT9: FALSE | CU9: MSE | CV9: TRUE | CW9: FALSE | CX9: 1 | CY9: 2 | CZ9: FALSE | DA9: FALSE | DB9: FALSE | DC9: cuda:0 | DD9: h | DE9: ./checkpoints/ | DF9: 0.5 | DG9: 10 | DH9: 0.3 | DI9: 1 | DJ9: 1 | DK9: gelu | DL9: FALSE | DM9: 32 | DN9: 1 | DO9: LOCAL | DP9: classification_Handwriting_PatchTST_UEA_ftM_sl152_ll48_pl0_dm128_nh8_el3_dl1_df256_expand2_dc4_fc1_ebtimeF_dtTrue_Exp_0b00ba4f2fd7f892250cdf379bfc4bc916c19a154bee665b33e0c7e05152f1e70 | DQ9: run.py | DR9: sunwu | DS9: =_xlfn.XLOOKUP(CP9,datasetmap!B:B,datasetmap!A:A) -> HW | DT9: =(N9-G9)/1000000000 -> 1.28433
