Workbook

Sheet Sheet1
A3: 平均值项:test_elapsed_seconds | B3: 列标签
A4: 行标签 | B4: EC | C4: FD | D4: HB | E4: HW | F4: JV | G4: PEMS-SF | H4: SAD | I4: SRS1 | J4: SRS2 | K4: UWG
A5: M2SFormerATPSelfRegulationSCP2 | B5: 0.45755787 | C5: 0.33624003 | D5: 0.27037487 | E5: 0.31895608 | F5: 0.29262712 | G5: 0.29789227 | H5: 0.5088737 | I5: 0.33832051 | J5: 0.31320943 | K5: 0.3016476

Sheet eval_time_ours
A1: Start Time | B1: Duration | C1: Run ID | D1: Name | E1: Source Type | F1: Source Name | G1: User | H1: Status | I1: HP__DROPOUT | J1: HP__D_MODEL | K1: HP__HIDDEN_DIM | L1: HP__SEQ_LEN | M1: __id | N1: activation | O1: alpha | P1: anomaly_ratio | Q1: args | R1: augmentation_ratio | S1: batch_size | T1: c_out | U1: channel_independence | V1: check_mlflow_exist | W1: checkpoints | X1: classification_report_metrics | Y1: conv_channel | Z1: d_conv | AA1: d_ff | AB1: d_layers | AC1: d_model | AD1: data | AE1: data_path | AF1: dec_in | AG1: decomp_method | AH1: des | AI1: device | AJ1: devices | AK1: discdtw | AL1: discsdtw | AM1: distil | AN1: down_sampling_layers | AO1: down_sampling_method | AP1: down_sampling_window | AQ1: dropout | AR1: dtwwarp | AS1: e_layers | AT1: embed | AU1: enc_in | AV1: envs | AW1: expand | AX1: extra_tag | AY1: factor | AZ1: features | BA1: freq | BB1: gcn_depth | BC1: gcn_dropout | BD1: gpu | BE1: gpu_type | BF1: id | BG1: individual | BH1: inverse | BI1: is_training | BJ1: itr | BK1: jitter | BL1: label_len | BM1: learning_rate | BN1: loss | BO1: lradj | BP1: magwarp | BQ1: mask_rate | BR1: model | BS1: model_id | BT1: moving_avg | BU1: n_heads | BV1: node_dim | BW1: num_class | BX1: num_kernels | BY1: num_workers | BZ1: p_hidden_dims | CA1: p_hidden_layers | CB1: patch_len | CC1: patience | CD1: permutation | CE1: pos | CF1: pred_len | CG1: propalpha | CH1: randompermutation | CI1: root_path | CJ1: rotation | CK1: run_cmd | CL1: scaling | CM1: seasonal_patterns | CN1: seed | CO1: seg_len | CP1: seq_len | CQ1: settings | CR1: shapedtwwarp | CS1: skip_channel | CT1: spawner | CU1: target | CV1: task_name | CW1: timewarp | CX1: top_k | CY1: top_p | CZ1: train_epochs | DA1: tv_B | DB1: tv_C | DC1: tv_dt | DD1: use_D | DE1: use_amp | DF1: use_dtw | DG1: use_gpu | DH1: use_multi_gpu | DI1: use_norm | DJ1: wdba | DK1: windowslice | DL1: windowwarp | DM1: accuracy | DN1: f1 | DO1: precision | DP1: recall | DQ1: test_elapsed_seconds | DR1: train_elapsed_seconds | DS1: dataset
A2: 46189.468 | B2: 3.5s | C2: 8af2c23a21044066af3347409e9cb32a | D2: silent-roo-281 | E2: LOCAL | F2: run.py | G2: sunwu | H2: FINISHED | I2: 0.2 | J2: 512 | K2: 256 | L2: 5000 | M2: d4148af2649958c554afac0d997666c083cd806ff6e119eedd44a6ea585ecb27 | N2: gelu | O2: 0.1 | P2: 0.25 | Q2: Namespace(task_name='classification', is_training=0, model_id='UWaveGestureLibrary', model='M2SFormerATPSelfRegulationSCP2', data='UEA', root_path='./dataset/UWaveGestureLibrary/', data_path='ETTh1.csv', features='M', target='OT', freq='h', checkpoints='00_final_model/ours', seq_len=np.int64(315), label_len=48, pred_len=0, seasonal_patterns='Monthly', inverse=False, mask_rate=0.25, anomaly_ratio=0.25, expand=2, d_conv=4, tv_dt=0, tv_B=0, tv_C=0, use_D=0, top_k=3, num_kernels=6, enc_in=3, dec_in=7, c_out=7, d_model=128, n_heads=8, e_layers=3, d_layers=1, d_ff=256, moving_avg=25, factor=1, distil=True, dropout=0.1, embed='timeF', activation='gelu', channel_independence=1, decomp_method='moving_avg', use_norm=1, down_sampling_layers=0, down_sampling_window=1, down_sampling_method=None, seg_len=96, num_workers=0, itr=1, train_epochs=1000, batch_size=256, patience=20, learning_rate=0.001, des='Exp', loss='MSE', lradj='type1', use_amp=False, use_gpu=True, gpu=0, gpu_type='cuda', use_multi_gpu=False, devices='0,1,2,3', p_hidden_dims=[128, 128], p_hidden_layers=2, use_dtw=False, augmentation_ratio=0, jitter=False, scaling=False, permutation=False, randompermutation=False, magwarp=False, timewarp=False, windowslice=False, windowwarp=False, rotation=False, spawner=False, dtwwarp=False, shapedtwwarp=False, wdba=False, discdtw=False, discsdtw=False, extra_tag='', patch_len=16, node_dim=10, gcn_depth=2, gcn_dropout=0.3, propalpha=0.3, conv_channel=32, skip_channel=32, individual=False, alpha=0.1, top_p=0.5, seed=42, pos=1, check_mlflow_exist=0, id='d4148af2649958c554afac0d997666c083cd806ff6e119eedd44a6ea585ecb27', device=device(type='cuda', index=0), num_class=8) | R2: 0 | S2: 256 | T2: 7 | U2: 1 | V2: 0 | W2: 00_final_model/ours | X2: precision recall f1-score support 0 0.97 0.88 0.92 40 1 1.00 1.00 1.00 40 2 0.97 0.90 0.94 40 3 0.93 0.70 0.80 40 4 0.73 0.93 0.81 40 5 0.87 0.97 0.92 40 6 0.98 1.00 0.99 40 7 1.00 1.00 1.00 40 accuracy 0.92 320 macro avg 0.93 0.92 0.92 320 weighted avg 0.93 0.92 0.92 320 | Y2: 32 | Z2: 4 | AA2: 256 | AB2: 1 | AC2: 128 | AD2: UEA | AE2: ETTh1.csv | AF2: 7 | AG2: moving_avg | AH2: Exp | AI2: cuda:0 | AJ2: 0,1,2,3 | AK2: FALSE | AL2: FALSE | AM2: TRUE | AN2: 0 | AO2: None | AP2: 1 | AQ2: 0.1 | AR2: FALSE | AS2: 3 | AT2: timeF | AU2: 3 | AV2: {'MLFLOW_EXPERIMENT': 'p1-tsc-our-eval-time-5times', 'HP__SEQ_LEN': '5000', 'HP__HIDDEN_DIM': '256', 'HP__DROPOUT': '0.2', 'HP__D_MODEL': '512', 'SHELL': '/bin/bash', 'TERM_PROGRAM_VERSION': '3.4', 'CONDA_MKL_INTERFACE_LAYER_BACKUP': '', 'CONDA_EXE': '/miniconda3/bin/conda', '_CE_M': '', 'TMUX': '/tmp/tmux-0/default,1082789,1', 'XML_CATALOG_FILES': 'file:///root/.local/share/mamba/envs/tsc/etc/xml/catalog file:///etc/xml/catalog', 'CF_TORCH_CUDA_ARCH_LIST_BACKUP': 'NOT_SET', 'PWD': '/remote-home/claude/tsc', 'LOGNAME': 'root', 'XDG_SESSION_TYPE': 'tty', 'CONDA_PREFIX': '/root/.local/share/mamba/envs/tsc', 'HOME': '/root', 'LANG': 'en_US.UTF-8', 'LS_COLORS': 'rs=0:di=01;34:ln=01;36:mh=00:pi=40;33:so=01;35:do=01;35:bd=40;33;01:cd=40;33;01:or=40;31;01:mi=00:su=37;41:sg=30;43:ca=00:tw=30;42:ow=34;42:st=37;44:ex=01;32:*.tar=01;31:*.tgz=01;31:*.arc=01;31:*.arj=01;31:*.taz=01;31:*.lha=01;31:*.lz4=01;31:*.lzh=01;31:*.lzma=01;31:*.tlz=01;31:*.txz=01;31:*.tzo=01;31:*.t7z=01;31:*.zip=01;31:*.z=01;31:*.dz=01;31:*.gz=01;31:*.lrz=01;31:*.lz=01;31:*.lzo=01;31:*.xz=01;31:*.zst=01;31:*.tzst=01;31:*.bz2=01;31:*.bz=01;31:*.tbz=01;31:*.tbz2=01;31:*.tz=01;31:*.deb=01;31:*.rpm=01;31:*.jar=01;31:*.war=01;31:*.ear=01;31:*.sar=01;31:*.rar=01;31:*.alz=01;31:*.ace=01;31:*.zoo=01;31:*.cpio=01;31:*.7z=01;31:*.rz=01;31:*.cab=01;31:*.wim=01;31:*.swm=01;31:*.dwm=01;31:*.esd=01;31:*.avif=01;35:*.jpg=01;35:*.jpeg=01;35:*.mjpg=01;35:*.mjpeg=01;35:*.gif=01;35:*.bmp=01;35:*.pbm=01;35:*.pgm=01;35:*.ppm=01;35:*.tga=01;35:*.xbm=01;35:*.xpm=01;35:*.tif=01;35:*.tiff=01;35:*.png=01;35:*.svg=01;35:*.svgz=01;35:*.mng=01;35:*.pcx=01;35:*.mov=01;35:*.mpg=01;35:*.mpeg=01;35:*.m2v=01;35:*.mkv=01;35:*.webm=01;35:*.webp=01;35:*.ogm=01;35:*.mp4=01;35:*.m4v=01;35:*.mp4v=01;35:*.vob=01;35:*.qt=01;35:*.nuv=01;35:*.wmv=01;35:*.asf=01;35:*.rm=01;35:*.rmvb=01;35:*.flc=01;35:*.avi=01;35:*.fli=01;35:*.flv=01;35:*.gl=01;35:*.dl=01;35:*.xcf=01;35:*.xwd=01;35:*.yuv=01;35:*.cgm=01;35:*.emf=01;35:*.ogv=01;35:*.ogx=01;35:*.aac=00;36:*.au=00;36:*.flac=00;36:*.m4a=00;36:*.mid=00;36:*.midi=00;36:*.mka=00;36:*.mp3=00;36:*.mpc=00;36:*.ogg=00;36:*.ra=00;36:*.wav=00;36:*.oga=00;36:*.opus=00;36:*.spx=00;36:*.xspf=00;36:*~=00;90:*#=00;90:*.bak=00;90:*.crdownload=00;90:*.dpkg-dist=00;90:*.dpkg-new=00;90:*.dpkg-old=00;90:*.dpkg-tmp=00;90:*.old=00;90:*.orig=00;90:*.part=00;90:*.rej=00;90:*.rpmnew=00;90:*.rpmorig=00;90:*.rpmsave=00;90:*.swp=00;90:*.tmp=00;90:*.ucf-dist=00;90:*.ucf-new=00;90:*.ucf-old=00;90:', 'CF_TORCH_CUDA_ARCH_LIST': '5.0;6.0;7.0;7.5;8.0;8.6;9.0;10.0;12.0+PTX', 'CONDA_PROMPT_MODIFIER': '(tsc) ', 'SSH_CONNECTION': '100.64.0.2 49956 100.64.0.17 22', 'LESSCLOSE': '/usr/bin/lesspipe %s %s', 'XDG_SESSION_CLASS': 'user', 'TERM': 'tmux-256color', '_CE_CONDA': '', 'LESSOPEN': '| /usr/bin/lesspipe %s', 'USER': 'root', 'TMUX_PANE': '%1', 'CONDA_SHLVL': '2', 'SHLVL': '3', 'XDG_SESSION_ID': '1105', 'CONDA_PYTHON_EXE': '/miniconda3/bin/python', 'XDG_RUNTIME_DIR': '/run/user/0', 'SSH_CLIENT': '100.64.0.2 65344 22', 'CONDA_DEFAULT_ENV': 'tsc', 'DEBUGINFOD_URLS': 'https://debuginfod.ubuntu.com ', 'XDG_DATA_DIRS': '/usr/share/gnome:/usr/local/share:/usr/share:/var/lib/snapd/desktop', 'PATH': '/root/.local/share/mamba/envs/tsc/bin:/root/bin/nodejs/bin:/root/.local/share/mamba/envs/tsc/bin:/miniconda3/condabin:/root/bin/nodejs/bin:/usr/local/sbin:/usr/local/bin:/usr/sbin:/usr/bin:/sbin:/bin:/usr/games:/usr/local/games:/snap/bin', 'DBUS_SESSION_BUS_ADDRESS': 'unix:path=/run/user/0/bus', 'SSH_TTY': '/dev/pts/0', 'CONDA_PREFIX_1': '/miniconda3', 'OLDPWD': '/root', 'TERM_PROGRAM': 'tmux', 'MKL_INTERFACE_LAYER': 'LP64,GNU', '_': '/root/.local/share/mamba/envs/tsc/bin/python', '_MLFLOW_TELEMETRY_SESSION_ID': '76de9343605444a2a0700cfb2b4af08d', 'KMP_DUPLICATE_LIB_OK': 'True', 'KMP_INIT_AT_FORK': 'FALSE', 'CUDA_VISIBLE_DEVICES': '0', 'MLFLOW_TRACKING_USERNAME': 'sunwu', 'MLFLOW_TRACKING_PASSWORD': 'xxxxx', 'MLFLOW_HTTP_REQUEST_TIMEOUT': '5', 'MLFLOW_TRACKING_URI': 'http://192.168.10.61:5000', 'MLFLOW_EXPERIMENT_ID': '55', 'TEST_START': '1781579627106509412', 'TEST_END': '1781579627567917270'} | AW2: 2 | AY2: 1 | AZ2: M | BA2: h | BB2: 2 | BC2: 0.3 | BD2: 0 | BE2: cuda | BF2: d4148af2649958c554afac0d997666c083cd806ff6e119eedd44a6ea585ecb27 | BG2: FALSE | BH2: FALSE | BI2: 0 | BJ2: 1 | BK2: FALSE | BL2: 48 | BM2: 0.001 | BN2: MSE | BO2: type1 | BP2: FALSE | BQ2: 0.25 | BR2: M2SFormerATPSelfRegulationSCP2 | BS2: UWaveGestureLibrary | BT2: 25 | BU2: 8 | BV2: 10 | BW2: 8 | BX2: 6 | BY2: 0 | BZ2: [128, 128] | CA2: 2 | CB2: 16 | CC2: 20 | CD2: FALSE | CE2: 1 | CF2: 0 | CG2: 0.3 | CH2: FALSE | CI2: ./dataset/UWaveGestureLibrary/ | CJ2: FALSE | CK2: run.py --task_name classification --is_training 0 --root_path ./dataset/UWaveGestureLibrary/ --model_id UWaveGestureLibrary --model M2SFormerATPSelfRegulationSCP2 --data UEA --e_layers 3 --batch_size 256 --d_model 128 --d_ff 256 --top_k 3 --des Exp --itr 1 --learning_rate 0.001 --train_epochs 1000 --patience 20 --seed 42 --id d4148af2649958c554afac0d997666c083cd806ff6e119eedd44a6ea585ecb27 --use_gpu --num_workers 0 --checkpoints 00_final_model/ours --id d4148af2649958c554afac0d997666c083cd806ff6e119eedd44a6ea585ecb27 --check_mlflow_exist 0 | CL2: FALSE | CM2: Monthly | CN2: 42 | CO2: 96 | CP2: 315 | CQ2: classification_UWaveGestureLibrary_M2SFormerATPSelfRegulationSCP2_UEA_ftM_sl315_ll48_pl0_dm128_nh8_el3_dl1_df256_expand2_dc4_fc1_ebtimeF_dtTrue_Exp_0d4148af2649958c554afac0d997666c083cd806ff6e119eedd44a6ea585ecb27 | CR2: FALSE | CS2: 32 | CT2: FALSE | CU2: OT | CV2: classification | CW2: FALSE | CX2: 3 | CY2: 0.5 | CZ2: 1000 | DA2: 0 | DB2: 0 | DC2: 0 | DD2: 0 | DE2: FALSE | DF2: FALSE | DG2: TRUE | DH2: FALSE | DI2: 1 | DJ2: FALSE | DK2: FALSE | DL2: FALSE | DM2: 0.93078689 | DN2: 0.92182572 | DO2: 0.93078689 | DP2: 0.921875 | DQ2: 0.30065894 | DR2: '-1 | DS2: =_xlfn.XLOOKUP(BS2,Sheet2!B:B,Sheet2!A:A) -> UWG
A3: 46189.468 | B3: 3.9s | C3: 01644fd2ef4a44e18df300b634aa15d4 | D3: hilarious-mule-485 | E3: LOCAL | F3: run.py | G3: sunwu | H3: FINISHED | I3: 0.2 | J3: 512 | K3: 256 | L3: 5000 | M3: d4148af2649958c554afac0d997666c083cd806ff6e119eedd44a6ea585ecb27 | N3: gelu | O3: 0.1 | P3: 0.25 | Q3: Namespace(task_name='classification', is_training=0, model_id='UWaveGestureLibrary', model='M2SFormerATPSelfRegulationSCP2', data='UEA', root_path='./dataset/UWaveGestureLibrary/', data_path='ETTh1.csv', features='M', target='OT', freq='h', checkpoints='00_final_model/ours', seq_len=np.int64(315), label_len=48, pred_len=0, seasonal_patterns='Monthly', inverse=False, mask_rate=0.25, anomaly_ratio=0.25, expand=2, d_conv=4, tv_dt=0, tv_B=0, tv_C=0, use_D=0, top_k=3, num_kernels=6, enc_in=3, dec_in=7, c_out=7, d_model=128, n_heads=8, e_layers=3, d_layers=1, d_ff=256, moving_avg=25, factor=1, distil=True, dropout=0.1, embed='timeF', activation='gelu', channel_independence=1, decomp_method='moving_avg', use_norm=1, down_sampling_layers=0, down_sampling_window=1, down_sampling_method=None, seg_len=96, num_workers=0, itr=1, train_epochs=1000, batch_size=256, patience=20, learning_rate=0.001, des='Exp', loss='MSE', lradj='type1', use_amp=False, use_gpu=True, gpu=0, gpu_type='cuda', use_multi_gpu=False, devices='0,1,2,3', p_hidden_dims=[128, 128], p_hidden_layers=2, use_dtw=False, augmentation_ratio=0, jitter=False, scaling=False, permutation=False, randompermutation=False, magwarp=False, timewarp=False, windowslice=False, windowwarp=False, rotation=False, spawner=False, dtwwarp=False, shapedtwwarp=False, wdba=False, discdtw=False, discsdtw=False, extra_tag='', patch_len=16, node_dim=10, gcn_depth=2, gcn_dropout=0.3, propalpha=0.3, conv_channel=32, skip_channel=32, individual=False, alpha=0.1, top_p=0.5, seed=42, pos=1, check_mlflow_exist=0, id='d4148af2649958c554afac0d997666c083cd806ff6e119eedd44a6ea585ecb27', device=device(type='cuda', index=0), num_class=8) | R3: 0 | S3: 256 | T3: 7 | U3: 1 | V3: 0 | W3: 00_final_model/ours | X3: precision recall f1-score support 0 0.97 0.88 0.92 40 1 1.00 1.00 1.00 40 2 0.97 0.90 0.94 40 3 0.93 0.70 0.80 40 4 0.73 0.93 0.81 40 5 0.87 0.97 0.92 40 6 0.98 1.00 0.99 40 7 1.00 1.00 1.00 40 accuracy 0.92 320 macro avg 0.93 0.92 0.92 320 weighted avg 0.93 0.92 0.92 320 | Y3: 32 | Z3: 4 | AA3: 256 | AB3: 1 | AC3: 128 | AD3: UEA | AE3: ETTh1.csv | AF3: 7 | AG3: moving_avg | AH3: Exp | AI3: cuda:0 | AJ3: 0,1,2,3 | AK3: FALSE | AL3: FALSE | AM3: TRUE | AN3: 0 | AO3: None | AP3: 1 | AQ3: 0.1 | AR3: FALSE | AS3: 3 | AT3: timeF | AU3: 3 | AV3: {'MLFLOW_EXPERIMENT': 'p1-tsc-our-eval-time-5times', 'HP__SEQ_LEN': '5000', 'HP__HIDDEN_DIM': '256', 'HP__DROPOUT': '0.2', 'HP__D_MODEL': '512', 'SHELL': '/bin/bash', 'TERM_PROGRAM_VERSION': '3.4', 'CONDA_MKL_INTERFACE_LAYER_BACKUP': '', 'CONDA_EXE': '/miniconda3/bin/conda', '_CE_M': '', 'TMUX': '/tmp/tmux-0/default,1082789,1', 'XML_CATALOG_FILES': 'file:///root/.local/share/mamba/envs/tsc/etc/xml/catalog file:///etc/xml/catalog', 'CF_TORCH_CUDA_ARCH_LIST_BACKUP': 'NOT_SET', 'PWD': '/remote-home/claude/tsc', 'LOGNAME': 'root', 'XDG_SESSION_TYPE': 'tty', 'CONDA_PREFIX': '/root/.local/share/mamba/envs/tsc', 'HOME': '/root', 'LANG': 'en_US.UTF-8', 'LS_COLORS': 'rs=0:di=01;34:ln=01;36:mh=00:pi=40;33:so=01;35:do=01;35:bd=40;33;01:cd=40;33;01:or=40;31;01:mi=00:su=37;41:sg=30;43:ca=00:tw=30;42:ow=34;42:st=37;44:ex=01;32:*.tar=01;31:*.tgz=01;31:*.arc=01;31:*.arj=01;31:*.taz=01;31:*.lha=01;31:*.lz4=01;31:*.lzh=01;31:*.lzma=01;31:*.tlz=01;31:*.txz=01;31:*.tzo=01;31:*.t7z=01;31:*.zip=01;31:*.z=01;31:*.dz=01;31:*.gz=01;31:*.lrz=01;31:*.lz=01;31:*.lzo=01;31:*.xz=01;31:*.zst=01;31:*.tzst=01;31:*.bz2=01;31:*.bz=01;31:*.tbz=01;31:*.tbz2=01;31:*.tz=01;31:*.deb=01;31:*.rpm=01;31:*.jar=01;31:*.war=01;31:*.ear=01;31:*.sar=01;31:*.rar=01;31:*.alz=01;31:*.ace=01;31:*.zoo=01;31:*.cpio=01;31:*.7z=01;31:*.rz=01;31:*.cab=01;31:*.wim=01;31:*.swm=01;31:*.dwm=01;31:*.esd=01;31:*.avif=01;35:*.jpg=01;35:*.jpeg=01;35:*.mjpg=01;35:*.mjpeg=01;35:*.gif=01;35:*.bmp=01;35:*.pbm=01;35:*.pgm=01;35:*.ppm=01;35:*.tga=01;35:*.xbm=01;35:*.xpm=01;35:*.tif=01;35:*.tiff=01;35:*.png=01;35:*.svg=01;35:*.svgz=01;35:*.mng=01;35:*.pcx=01;35:*.mov=01;35:*.mpg=01;35:*.mpeg=01;35:*.m2v=01;35:*.mkv=01;35:*.webm=01;35:*.webp=01;35:*.ogm=01;35:*.mp4=01;35:*.m4v=01;35:*.mp4v=01;35:*.vob=01;35:*.qt=01;35:*.nuv=01;35:*.wmv=01;35:*.asf=01;35:*.rm=01;35:*.rmvb=01;35:*.flc=01;35:*.avi=01;35:*.fli=01;35:*.flv=01;35:*.gl=01;35:*.dl=01;35:*.xcf=01;35:*.xwd=01;35:*.yuv=01;35:*.cgm=01;35:*.emf=01;35:*.ogv=01;35:*.ogx=01;35:*.aac=00;36:*.au=00;36:*.flac=00;36:*.m4a=00;36:*.mid=00;36:*.midi=00;36:*.mka=00;36:*.mp3=00;36:*.mpc=00;36:*.ogg=00;36:*.ra=00;36:*.wav=00;36:*.oga=00;36:*.opus=00;36:*.spx=00;36:*.xspf=00;36:*~=00;90:*#=00;90:*.bak=00;90:*.crdownload=00;90:*.dpkg-dist=00;90:*.dpkg-new=00;90:*.dpkg-old=00;90:*.dpkg-tmp=00;90:*.old=00;90:*.orig=00;90:*.part=00;90:*.rej=00;90:*.rpmnew=00;90:*.rpmorig=00;90:*.rpmsave=00;90:*.swp=00;90:*.tmp=00;90:*.ucf-dist=00;90:*.ucf-new=00;90:*.ucf-old=00;90:', 'CF_TORCH_CUDA_ARCH_LIST': '5.0;6.0;7.0;7.5;8.0;8.6;9.0;10.0;12.0+PTX', 'CONDA_PROMPT_MODIFIER': '(tsc) ', 'SSH_CONNECTION': '100.64.0.2 49956 100.64.0.17 22', 'LESSCLOSE': '/usr/bin/lesspipe %s %s', 'XDG_SESSION_CLASS': 'user', 'TERM': 'tmux-256color', '_CE_CONDA': '', 'LESSOPEN': '| /usr/bin/lesspipe %s', 'USER': 'root', 'TMUX_PANE': '%1', 'CONDA_SHLVL': '2', 'SHLVL': '3', 'XDG_SESSION_ID': '1105', 'CONDA_PYTHON_EXE': '/miniconda3/bin/python', 'XDG_RUNTIME_DIR': '/run/user/0', 'SSH_CLIENT': '100.64.0.2 65344 22', 'CONDA_DEFAULT_ENV': 'tsc', 'DEBUGINFOD_URLS': 'https://debuginfod.ubuntu.com ', 'XDG_DATA_DIRS': '/usr/share/gnome:/usr/local/share:/usr/share:/var/lib/snapd/desktop', 'PATH': '/root/.local/share/mamba/envs/tsc/bin:/root/bin/nodejs/bin:/root/.local/share/mamba/envs/tsc/bin:/miniconda3/condabin:/root/bin/nodejs/bin:/usr/local/sbin:/usr/local/bin:/usr/sbin:/usr/bin:/sbin:/bin:/usr/games:/usr/local/games:/snap/bin', 'DBUS_SESSION_BUS_ADDRESS': 'unix:path=/run/user/0/bus', 'SSH_TTY': '/dev/pts/0', 'CONDA_PREFIX_1': '/miniconda3', 'OLDPWD': '/root', 'TERM_PROGRAM': 'tmux', 'MKL_INTERFACE_LAYER': 'LP64,GNU', '_': '/root/.local/share/mamba/envs/tsc/bin/python', '_MLFLOW_TELEMETRY_SESSION_ID': '93271a5adab34e0183ef7678812faa40', 'KMP_DUPLICATE_LIB_OK': 'True', 'KMP_INIT_AT_FORK': 'FALSE', 'CUDA_VISIBLE_DEVICES': '0', 'MLFLOW_TRACKING_USERNAME': 'sunwu', 'MLFLOW_TRACKING_PASSWORD': 'xxxxx', 'MLFLOW_HTTP_REQUEST_TIMEOUT': '5', 'MLFLOW_TRACKING_URI': 'http://192.168.10.61:5000', 'MLFLOW_EXPERIMENT_ID': '55', 'TEST_START': '1781579617685071918', 'TEST_END': '1781579618145241741'} | AW3: 2 | AY3: 1 | AZ3: M | BA3: h | BB3: 2 | BC3: 0.3 | BD3: 0 | BE3: cuda | BF3: d4148af2649958c554afac0d997666c083cd806ff6e119eedd44a6ea585ecb27 | BG3: FALSE | BH3: FALSE | BI3: 0 | BJ3: 1 | BK3: FALSE | BL3: 48 | BM3: 0.001 | BN3: MSE | BO3: type1 | BP3: FALSE | BQ3: 0.25 | BR3: M2SFormerATPSelfRegulationSCP2 | BS3: UWaveGestureLibrary | BT3: 25 | BU3: 8 | BV3: 10 | BW3: 8 | BX3: 6 | BY3: 0 | BZ3: [128, 128] | CA3: 2 | CB3: 16 | CC3: 20 | CD3: FALSE | CE3: 1 | CF3: 0 | CG3: 0.3 | CH3: FALSE | CI3: ./dataset/UWaveGestureLibrary/ | CJ3: FALSE | CK3: run.py --task_name classification --is_training 0 --root_path ./dataset/UWaveGestureLibrary/ --model_id UWaveGestureLibrary --model M2SFormerATPSelfRegulationSCP2 --data UEA --e_layers 3 --batch_size 256 --d_model 128 --d_ff 256 --top_k 3 --des Exp --itr 1 --learning_rate 0.001 --train_epochs 1000 --patience 20 --seed 42 --id d4148af2649958c554afac0d997666c083cd806ff6e119eedd44a6ea585ecb27 --use_gpu --num_workers 0 --checkpoints 00_final_model/ours --id d4148af2649958c554afac0d997666c083cd806ff6e119eedd44a6ea585ecb27 --check_mlflow_exist 0 | CL3: FALSE | CM3: Monthly | CN3: 42 | CO3: 96 | CP3: 315 | CQ3: classification_UWaveGestureLibrary_M2SFormerATPSelfRegulationSCP2_UEA_ftM_sl315_ll48_pl0_dm128_nh8_el3_dl1_df256_expand2_dc4_fc1_ebtimeF_dtTrue_Exp_0d4148af2649958c554afac0d997666c083cd806ff6e119eedd44a6ea585ecb27 | CR3: FALSE | CS3: 32 | CT3: FALSE | CU3: OT | CV3: classification | CW3: FALSE | CX3: 3 | CY3: 0.5 | CZ3: 1000 | DA3: 0 | DB3: 0 | DC3: 0 | DD3: 0 | DE3: FALSE | DF3: FALSE | DG3: TRUE | DH3: FALSE | DI3: 1 | DJ3: FALSE | DK3: FALSE | DL3: FALSE | DM3: 0.93078689 | DN3: 0.92182572 | DO3: 0.93078689 | DP3: 0.921875 | DQ3: 0.30140373 | DR3: '-1 | DS3: =_xlfn.XLOOKUP(BS3,Sheet2!B:B,Sheet2!A:A) -> UWG
A4: 46189.468 | B4: 3.4s | C4: ead218204fb34cf6ba2121c54598e595 | D4: sincere-kite-287 | E4: LOCAL | F4: run.py | G4: sunwu | H4: FINISHED | I4: 0.2 | J4: 512 | K4: 256 | L4: 5000 | M4: d4148af2649958c554afac0d997666c083cd806ff6e119eedd44a6ea585ecb27 | N4: gelu | O4: 0.1 | P4: 0.25 | Q4: Namespace(task_name='classification', is_training=0, model_id='UWaveGestureLibrary', model='M2SFormerATPSelfRegulationSCP2', data='UEA', root_path='./dataset/UWaveGestureLibrary/', data_path='ETTh1.csv', features='M', target='OT', freq='h', checkpoints='00_final_model/ours', seq_len=np.int64(315), label_len=48, pred_len=0, seasonal_patterns='Monthly', inverse=False, mask_rate=0.25, anomaly_ratio=0.25, expand=2, d_conv=4, tv_dt=0, tv_B=0, tv_C=0, use_D=0, top_k=3, num_kernels=6, enc_in=3, dec_in=7, c_out=7, d_model=128, n_heads=8, e_layers=3, d_layers=1, d_ff=256, moving_avg=25, factor=1, distil=True, dropout=0.1, embed='timeF', activation='gelu', channel_independence=1, decomp_method='moving_avg', use_norm=1, down_sampling_layers=0, down_sampling_window=1, down_sampling_method=None, seg_len=96, num_workers=0, itr=1, train_epochs=1000, batch_size=256, patience=20, learning_rate=0.001, des='Exp', loss='MSE', lradj='type1', use_amp=False, use_gpu=True, gpu=0, gpu_type='cuda', use_multi_gpu=False, devices='0,1,2,3', p_hidden_dims=[128, 128], p_hidden_layers=2, use_dtw=False, augmentation_ratio=0, jitter=False, scaling=False, permutation=False, randompermutation=False, magwarp=False, timewarp=False, windowslice=False, windowwarp=False, rotation=False, spawner=False, dtwwarp=False, shapedtwwarp=False, wdba=False, discdtw=False, discsdtw=False, extra_tag='', patch_len=16, node_dim=10, gcn_depth=2, gcn_dropout=0.3, propalpha=0.3, conv_channel=32, skip_channel=32, individual=False, alpha=0.1, top_p=0.5, seed=42, pos=1, check_mlflow_exist=0, id='d4148af2649958c554afac0d997666c083cd806ff6e119eedd44a6ea585ecb27', device=device(type='cuda', index=0), num_class=8) | R4: 0 | S4: 256 | T4: 7 | U4: 1 | V4: 0 | W4: 00_final_model/ours | X4: precision recall f1-score support 0 0.97 0.88 0.92 40 1 1.00 1.00 1.00 40 2 0.97 0.90 0.94 40 3 0.93 0.70 0.80 40 4 0.73 0.93 0.81 40 5 0.87 0.97 0.92 40 6 0.98 1.00 0.99 40 7 1.00 1.00 1.00 40 accuracy 0.92 320 macro avg 0.93 0.92 0.92 320 weighted avg 0.93 0.92 0.92 320 | Y4: 32 | Z4: 4 | AA4: 256 | AB4: 1 | AC4: 128 | AD4: UEA | AE4: ETTh1.csv | AF4: 7 | AG4: moving_avg | AH4: Exp | AI4: cuda:0 | AJ4: 0,1,2,3 | AK4: FALSE | AL4: FALSE | AM4: TRUE | AN4: 0 | AO4: None | AP4: 1 | AQ4: 0.1 | AR4: FALSE | AS4: 3 | AT4: timeF | AU4: 3 | AV4: {'MLFLOW_EXPERIMENT': 'p1-tsc-our-eval-time-5times', 'HP__SEQ_LEN': '5000', 'HP__HIDDEN_DIM': '256', 'HP__DROPOUT': '0.2', 'HP__D_MODEL': '512', 'SHELL': '/bin/bash', 'TERM_PROGRAM_VERSION': '3.4', 'CONDA_MKL_INTERFACE_LAYER_BACKUP': '', 'CONDA_EXE': '/miniconda3/bin/conda', '_CE_M': '', 'TMUX': '/tmp/tmux-0/default,1082789,1', 'XML_CATALOG_FILES': 'file:///root/.local/share/mamba/envs/tsc/etc/xml/catalog file:///etc/xml/catalog', 'CF_TORCH_CUDA_ARCH_LIST_BACKUP': 'NOT_SET', 'PWD': '/remote-home/claude/tsc', 'LOGNAME': 'root', 'XDG_SESSION_TYPE': 'tty', 'CONDA_PREFIX': '/root/.local/share/mamba/envs/tsc', 'HOME': '/root', 'LANG': 'en_US.UTF-8', 'LS_COLORS': 'rs=0:di=01;34:ln=01;36:mh=00:pi=40;33:so=01;35:do=01;35:bd=40;33;01:cd=40;33;01:or=40;31;01:mi=00:su=37;41:sg=30;43:ca=00:tw=30;42:ow=34;42:st=37;44:ex=01;32:*.tar=01;31:*.tgz=01;31:*.arc=01;31:*.arj=01;31:*.taz=01;31:*.lha=01;31:*.lz4=01;31:*.lzh=01;31:*.lzma=01;31:*.tlz=01;31:*.txz=01;31:*.tzo=01;31:*.t7z=01;31:*.zip=01;31:*.z=01;31:*.dz=01;31:*.gz=01;31:*.lrz=01;31:*.lz=01;31:*.lzo=01;31:*.xz=01;31:*.zst=01;31:*.tzst=01;31:*.bz2=01;31:*.bz=01;31:*.tbz=01;31:*.tbz2=01;31:*.tz=01;31:*.deb=01;31:*.rpm=01;31:*.jar=01;31:*.war=01;31:*.ear=01;31:*.sar=01;31:*.rar=01;31:*.alz=01;31:*.ace=01;31:*.zoo=01;31:*.cpio=01;31:*.7z=01;31:*.rz=01;31:*.cab=01;31:*.wim=01;31:*.swm=01;31:*.dwm=01;31:*.esd=01;31:*.avif=01;35:*.jpg=01;35:*.jpeg=01;35:*.mjpg=01;35:*.mjpeg=01;35:*.gif=01;35:*.bmp=01;35:*.pbm=01;35:*.pgm=01;35:*.ppm=01;35:*.tga=01;35:*.xbm=01;35:*.xpm=01;35:*.tif=01;35:*.tiff=01;35:*.png=01;35:*.svg=01;35:*.svgz=01;35:*.mng=01;35:*.pcx=01;35:*.mov=01;35:*.mpg=01;35:*.mpeg=01;35:*.m2v=01;35:*.mkv=01;35:*.webm=01;35:*.webp=01;35:*.ogm=01;35:*.mp4=01;35:*.m4v=01;35:*.mp4v=01;35:*.vob=01;35:*.qt=01;35:*.nuv=01;35:*.wmv=01;35:*.asf=01;35:*.rm=01;35:*.rmvb=01;35:*.flc=01;35:*.avi=01;35:*.fli=01;35:*.flv=01;35:*.gl=01;35:*.dl=01;35:*.xcf=01;35:*.xwd=01;35:*.yuv=01;35:*.cgm=01;35:*.emf=01;35:*.ogv=01;35:*.ogx=01;35:*.aac=00;36:*.au=00;36:*.flac=00;36:*.m4a=00;36:*.mid=00;36:*.midi=00;36:*.mka=00;36:*.mp3=00;36:*.mpc=00;36:*.ogg=00;36:*.ra=00;36:*.wav=00;36:*.oga=00;36:*.opus=00;36:*.spx=00;36:*.xspf=00;36:*~=00;90:*#=00;90:*.bak=00;90:*.crdownload=00;90:*.dpkg-dist=00;90:*.dpkg-new=00;90:*.dpkg-old=00;90:*.dpkg-tmp=00;90:*.old=00;90:*.orig=00;90:*.part=00;90:*.rej=00;90:*.rpmnew=00;90:*.rpmorig=00;90:*.rpmsave=00;90:*.swp=00;90:*.tmp=00;90:*.ucf-dist=00;90:*.ucf-new=00;90:*.ucf-old=00;90:', 'CF_TORCH_CUDA_ARCH_LIST': '5.0;6.0;7.0;7.5;8.0;8.6;9.0;10.0;12.0+PTX', 'CONDA_PROMPT_MODIFIER': '(tsc) ', 'SSH_CONNECTION': '100.64.0.2 49956 100.64.0.17 22', 'LESSCLOSE': '/usr/bin/lesspipe %s %s', 'XDG_SESSION_CLASS': 'user', 'TERM': 'tmux-256color', '_CE_CONDA': '', 'LESSOPEN': '| /usr/bin/lesspipe %s', 'USER': 'root', 'TMUX_PANE': '%1', 'CONDA_SHLVL': '2', 'SHLVL': '3', 'XDG_SESSION_ID': '1105', 'CONDA_PYTHON_EXE': '/miniconda3/bin/python', 'XDG_RUNTIME_DIR': '/run/user/0', 'SSH_CLIENT': '100.64.0.2 65344 22', 'CONDA_DEFAULT_ENV': 'tsc', 'DEBUGINFOD_URLS': 'https://debuginfod.ubuntu.com ', 'XDG_DATA_DIRS': '/usr/share/gnome:/usr/local/share:/usr/share:/var/lib/snapd/desktop', 'PATH': '/root/.local/share/mamba/envs/tsc/bin:/root/bin/nodejs/bin:/root/.local/share/mamba/envs/tsc/bin:/miniconda3/condabin:/root/bin/nodejs/bin:/usr/local/sbin:/usr/local/bin:/usr/sbin:/usr/bin:/sbin:/bin:/usr/games:/usr/local/games:/snap/bin', 'DBUS_SESSION_BUS_ADDRESS': 'unix:path=/run/user/0/bus', 'SSH_TTY': '/dev/pts/0', 'CONDA_PREFIX_1': '/miniconda3', 'OLDPWD': '/root', 'TERM_PROGRAM': 'tmux', 'MKL_INTERFACE_LAYER': 'LP64,GNU', '_': '/root/.local/share/mamba/envs/tsc/bin/python', '_MLFLOW_TELEMETRY_SESSION_ID': '581ed91e63a8452c8dbfb47a3d5cb3c0', 'KMP_DUPLICATE_LIB_OK': 'True', 'KMP_INIT_AT_FORK': 'FALSE', 'CUDA_VISIBLE_DEVICES': '0', 'MLFLOW_TRACKING_USERNAME': 'sunwu', 'MLFLOW_TRACKING_PASSWORD': 'xxxxx', 'MLFLOW_HTTP_REQUEST_TIMEOUT': '5', 'MLFLOW_TRACKING_URI': 'http://192.168.10.61:5000', 'MLFLOW_EXPERIMENT_ID': '55', 'TEST_START': '1781579608875676007', 'TEST_END': '1781579609337423264'} | AW4: 2 | AY4: 1 | AZ4: M | BA4: h | BB4: 2 | BC4: 0.3 | BD4: 0 | BE4: cuda | BF4: d4148af2649958c554afac0d997666c083cd806ff6e119eedd44a6ea585ecb27 | BG4: FALSE | BH4: FALSE | BI4: 0 | BJ4: 1 | BK4: FALSE | BL4: 48 | BM4: 0.001 | BN4: MSE | BO4: type1 | BP4: FALSE | BQ4: 0.25 | BR4: M2SFormerATPSelfRegulationSCP2 | BS4: UWaveGestureLibrary | BT4: 25 | BU4: 8 | BV4: 10 | BW4: 8 | BX4: 6 | BY4: 0 | BZ4: [128, 128] | CA4: 2 | CB4: 16 | CC4: 20 | CD4: FALSE | CE4: 1 | CF4: 0 | CG4: 0.3 | CH4: FALSE | CI4: ./dataset/UWaveGestureLibrary/ | CJ4: FALSE | CK4: run.py --task_name classification --is_training 0 --root_path ./dataset/UWaveGestureLibrary/ --model_id UWaveGestureLibrary --model M2SFormerATPSelfRegulationSCP2 --data UEA --e_layers 3 --batch_size 256 --d_model 128 --d_ff 256 --top_k 3 --des Exp --itr 1 --learning_rate 0.001 --train_epochs 1000 --patience 20 --seed 42 --id d4148af2649958c554afac0d997666c083cd806ff6e119eedd44a6ea585ecb27 --use_gpu --num_workers 0 --checkpoints 00_final_model/ours --id d4148af2649958c554afac0d997666c083cd806ff6e119eedd44a6ea585ecb27 --check_mlflow_exist 0 | CL4: FALSE | CM4: Monthly | CN4: 42 | CO4: 96 | CP4: 315 | CQ4: classification_UWaveGestureLibrary_M2SFormerATPSelfRegulationSCP2_UEA_ftM_sl315_ll48_pl0_dm128_nh8_el3_dl1_df256_expand2_dc4_fc1_ebtimeF_dtTrue_Exp_0d4148af2649958c554afac0d997666c083cd806ff6e119eedd44a6ea585ecb27 | CR4: FALSE | CS4: 32 | CT4: FALSE | CU4: OT | CV4: classification | CW4: FALSE | CX4: 3 | CY4: 0.5 | CZ4: 1000 | DA4: 0 | DB4: 0 | DC4: 0 | DD4: 0 | DE4: FALSE | DF4: FALSE | DG4: TRUE | DH4: FALSE | DI4: 1 | DJ4: FALSE | DK4: FALSE | DL4: FALSE | DM4: 0.93078689 | DN4: 0.92182572 | DO4: 0.93078689 | DP4: 0.921875 | DQ4: 0.30369306 | DR4: '-1 | DS4: =_xlfn.XLOOKUP(BS4,Sheet2!B:B,Sheet2!A:A) -> UWG
A5: 46189.468 | B5: 3.7s | C5: c9f557fae3834d3bb488ca365013f678 | D5: adventurous-seal-924 | E5: LOCAL | F5: run.py | G5: sunwu | H5: FINISHED | I5: 0.2 | J5: 512 | K5: 256 | L5: 5000 | M5: d4148af2649958c554afac0d997666c083cd806ff6e119eedd44a6ea585ecb27 | N5: gelu | O5: 0.1 | P5: 0.25 | Q5: Namespace(task_name='classification', is_training=0, model_id='UWaveGestureLibrary', model='M2SFormerATPSelfRegulationSCP2', data='UEA', root_path='./dataset/UWaveGestureLibrary/', data_path='ETTh1.csv', features='M', target='OT', freq='h', checkpoints='00_final_model/ours', seq_len=np.int64(315), label_len=48, pred_len=0, seasonal_patterns='Monthly', inverse=False, mask_rate=0.25, anomaly_ratio=0.25, expand=2, d_conv=4, tv_dt=0, tv_B=0, tv_C=0, use_D=0, top_k=3, num_kernels=6, enc_in=3, dec_in=7, c_out=7, d_model=128, n_heads=8, e_layers=3, d_layers=1, d_ff=256, moving_avg=25, factor=1, distil=True, dropout=0.1, embed='timeF', activation='gelu', channel_independence=1, decomp_method='moving_avg', use_norm=1, down_sampling_layers=0, down_sampling_window=1, down_sampling_method=None, seg_len=96, num_workers=0, itr=1, train_epochs=1000, batch_size=256, patience=20, learning_rate=0.001, des='Exp', loss='MSE', lradj='type1', use_amp=False, use_gpu=True, gpu=0, gpu_type='cuda', use_multi_gpu=False, devices='0,1,2,3', p_hidden_dims=[128, 128], p_hidden_layers=2, use_dtw=False, augmentation_ratio=0, jitter=False, scaling=False, permutation=False, randompermutation=False, magwarp=False, timewarp=False, windowslice=False, windowwarp=False, rotation=False, spawner=False, dtwwarp=False, shapedtwwarp=False, wdba=False, discdtw=False, discsdtw=False, extra_tag='', patch_len=16, node_dim=10, gcn_depth=2, gcn_dropout=0.3, propalpha=0.3, conv_channel=32, skip_channel=32, individual=False, alpha=0.1, top_p=0.5, seed=42, pos=1, check_mlflow_exist=0, id='d4148af2649958c554afac0d997666c083cd806ff6e119eedd44a6ea585ecb27', device=device(type='cuda', index=0), num_class=8) | R5: 0 | S5: 256 | T5: 7 | U5: 1 | V5: 0 | W5: 00_final_model/ours | X5: precision recall f1-score support 0 0.97 0.88 0.92 40 1 1.00 1.00 1.00 40 2 0.97 0.90 0.94 40 3 0.93 0.70 0.80 40 4 0.73 0.93 0.81 40 5 0.87 0.97 0.92 40 6 0.98 1.00 0.99 40 7 1.00 1.00 1.00 40 accuracy 0.92 320 macro avg 0.93 0.92 0.92 320 weighted avg 0.93 0.92 0.92 320 | Y5: 32 | Z5: 4 | AA5: 256 | AB5: 1 | AC5: 128 | AD5: UEA | AE5: ETTh1.csv | AF5: 7 | AG5: moving_avg | AH5: Exp | AI5: cuda:0 | AJ5: 0,1,2,3 | AK5: FALSE | AL5: FALSE | AM5: TRUE | AN5: 0 | AO5: None | AP5: 1 | AQ5: 0.1 | AR5: FALSE | AS5: 3 | AT5: timeF | AU5: 3 | AV5: {'MLFLOW_EXPERIMENT': 'p1-tsc-our-eval-time-5times', 'HP__SEQ_LEN': '5000', 'HP__HIDDEN_DIM': '256', 'HP__DROPOUT': '0.2', 'HP__D_MODEL': '512', 'SHELL': '/bin/bash', 'TERM_PROGRAM_VERSION': '3.4', 'CONDA_MKL_INTERFACE_LAYER_BACKUP': '', 'CONDA_EXE': '/miniconda3/bin/conda', '_CE_M': '', 'TMUX': '/tmp/tmux-0/default,1082789,1', 'XML_CATALOG_FILES': 'file:///root/.local/share/mamba/envs/tsc/etc/xml/catalog file:///etc/xml/catalog', 'CF_TORCH_CUDA_ARCH_LIST_BACKUP': 'NOT_SET', 'PWD': '/remote-home/claude/tsc', 'LOGNAME': 'root', 'XDG_SESSION_TYPE': 'tty', 'CONDA_PREFIX': '/root/.local/share/mamba/envs/tsc', 'HOME': '/root', 'LANG': 'en_US.UTF-8', 'LS_COLORS': 'rs=0:di=01;34:ln=01;36:mh=00:pi=40;33:so=01;35:do=01;35:bd=40;33;01:cd=40;33;01:or=40;31;01:mi=00:su=37;41:sg=30;43:ca=00:tw=30;42:ow=34;42:st=37;44:ex=01;32:*.tar=01;31:*.tgz=01;31:*.arc=01;31:*.arj=01;31:*.taz=01;31:*.lha=01;31:*.lz4=01;31:*.lzh=01;31:*.lzma=01;31:*.tlz=01;31:*.txz=01;31:*.tzo=01;31:*.t7z=01;31:*.zip=01;31:*.z=01;31:*.dz=01;31:*.gz=01;31:*.lrz=01;31:*.lz=01;31:*.lzo=01;31:*.xz=01;31:*.zst=01;31:*.tzst=01;31:*.bz2=01;31:*.bz=01;31:*.tbz=01;31:*.tbz2=01;31:*.tz=01;31:*.deb=01;31:*.rpm=01;31:*.jar=01;31:*.war=01;31:*.ear=01;31:*.sar=01;31:*.rar=01;31:*.alz=01;31:*.ace=01;31:*.zoo=01;31:*.cpio=01;31:*.7z=01;31:*.rz=01;31:*.cab=01;31:*.wim=01;31:*.swm=01;31:*.dwm=01;31:*.esd=01;31:*.avif=01;35:*.jpg=01;35:*.jpeg=01;35:*.mjpg=01;35:*.mjpeg=01;35:*.gif=01;35:*.bmp=01;35:*.pbm=01;35:*.pgm=01;35:*.ppm=01;35:*.tga=01;35:*.xbm=01;35:*.xpm=01;35:*.tif=01;35:*.tiff=01;35:*.png=01;35:*.svg=01;35:*.svgz=01;35:*.mng=01;35:*.pcx=01;35:*.mov=01;35:*.mpg=01;35:*.mpeg=01;35:*.m2v=01;35:*.mkv=01;35:*.webm=01;35:*.webp=01;35:*.ogm=01;35:*.mp4=01;35:*.m4v=01;35:*.mp4v=01;35:*.vob=01;35:*.qt=01;35:*.nuv=01;35:*.wmv=01;35:*.asf=01;35:*.rm=01;35:*.rmvb=01;35:*.flc=01;35:*.avi=01;35:*.fli=01;35:*.flv=01;35:*.gl=01;35:*.dl=01;35:*.xcf=01;35:*.xwd=01;35:*.yuv=01;35:*.cgm=01;35:*.emf=01;35:*.ogv=01;35:*.ogx=01;35:*.aac=00;36:*.au=00;36:*.flac=00;36:*.m4a=00;36:*.mid=00;36:*.midi=00;36:*.mka=00;36:*.mp3=00;36:*.mpc=00;36:*.ogg=00;36:*.ra=00;36:*.wav=00;36:*.oga=00;36:*.opus=00;36:*.spx=00;36:*.xspf=00;36:*~=00;90:*#=00;90:*.bak=00;90:*.crdownload=00;90:*.dpkg-dist=00;90:*.dpkg-new=00;90:*.dpkg-old=00;90:*.dpkg-tmp=00;90:*.old=00;90:*.orig=00;90:*.part=00;90:*.rej=00;90:*.rpmnew=00;90:*.rpmorig=00;90:*.rpmsave=00;90:*.swp=00;90:*.tmp=00;90:*.ucf-dist=00;90:*.ucf-new=00;90:*.ucf-old=00;90:', 'CF_TORCH_CUDA_ARCH_LIST': '5.0;6.0;7.0;7.5;8.0;8.6;9.0;10.0;12.0+PTX', 'CONDA_PROMPT_MODIFIER': '(tsc) ', 'SSH_CONNECTION': '100.64.0.2 49956 100.64.0.17 22', 'LESSCLOSE': '/usr/bin/lesspipe %s %s', 'XDG_SESSION_CLASS': 'user', 'TERM': 'tmux-256color', '_CE_CONDA': '', 'LESSOPEN': '| /usr/bin/lesspipe %s', 'USER': 'root', 'TMUX_PANE': '%1', 'CONDA_SHLVL': '2', 'SHLVL': '3', 'XDG_SESSION_ID': '1105', 'CONDA_PYTHON_EXE': '/miniconda3/bin/python', 'XDG_RUNTIME_DIR': '/run/user/0', 'SSH_CLIENT': '100.64.0.2 65344 22', 'CONDA_DEFAULT_ENV': 'tsc', 'DEBUGINFOD_URLS': 'https://debuginfod.ubuntu.com ', 'XDG_DATA_DIRS': '/usr/share/gnome:/usr/local/share:/usr/share:/var/lib/snapd/desktop', 'PATH': '/root/.local/share/mamba/envs/tsc/bin:/root/bin/nodejs/bin:/root/.local/share/mamba/envs/tsc/bin:/miniconda3/condabin:/root/bin/nodejs/bin:/usr/local/sbin:/usr/local/bin:/usr/sbin:/usr/bin:/sbin:/bin:/usr/games:/usr/local/games:/snap/bin', 'DBUS_SESSION_BUS_ADDRESS': 'unix:path=/run/user/0/bus', 'SSH_TTY': '/dev/pts/0', 'CONDA_PREFIX_1': '/miniconda3', 'OLDPWD': '/root', 'TERM_PROGRAM': 'tmux', 'MKL_INTERFACE_LAYER': 'LP64,GNU', '_': '/root/.local/share/mamba/envs/tsc/bin/python', '_MLFLOW_TELEMETRY_SESSION_ID': 'd0094fb0cffc48ef873adc1171743749', 'KMP_DUPLICATE_LIB_OK': 'True', 'KMP_INIT_AT_FORK': 'FALSE', 'CUDA_VISIBLE_DEVICES': '0', 'MLFLOW_TRACKING_USERNAME': 'sunwu', 'MLFLOW_TRACKING_PASSWORD': 'xxxxx', 'MLFLOW_HTTP_REQUEST_TIMEOUT': '5', 'MLFLOW_TRACKING_URI': 'http://192.168.10.61:5000', 'MLFLOW_EXPERIMENT_ID': '55', 'TEST_START': '1781579599455215360', 'TEST_END': '1781579599914118723'} | AW5: 2 | AY5: 1 | AZ5: M | BA5: h | BB5: 2 | BC5: 0.3 | BD5: 0 | BE5: cuda | BF5: d4148af2649958c554afac0d997666c083cd806ff6e119eedd44a6ea585ecb27 | BG5: FALSE | BH5: FALSE | BI5: 0 | BJ5: 1 | BK5: FALSE | BL5: 48 | BM5: 0.001 | BN5: MSE | BO5: type1 | BP5: FALSE | BQ5: 0.25 | BR5: M2SFormerATPSelfRegulationSCP2 | BS5: UWaveGestureLibrary | BT5: 25 | BU5: 8 | BV5: 10 | BW5: 8 | BX5: 6 | BY5: 0 | BZ5: [128, 128] | CA5: 2 | CB5: 16 | CC5: 20 | CD5: FALSE | CE5: 1 | CF5: 0 | CG5: 0.3 | CH5: FALSE | CI5: ./dataset/UWaveGestureLibrary/ | CJ5: FALSE | CK5: run.py --task_name classification --is_training 0 --root_path ./dataset/UWaveGestureLibrary/ --model_id UWaveGestureLibrary --model M2SFormerATPSelfRegulationSCP2 --data UEA --e_layers 3 --batch_size 256 --d_model 128 --d_ff 256 --top_k 3 --des Exp --itr 1 --learning_rate 0.001 --train_epochs 1000 --patience 20 --seed 42 --id d4148af2649958c554afac0d997666c083cd806ff6e119eedd44a6ea585ecb27 --use_gpu --num_workers 0 --checkpoints 00_final_model/ours --id d4148af2649958c554afac0d997666c083cd806ff6e119eedd44a6ea585ecb27 --check_mlflow_exist 0 | CL5: FALSE | CM5: Monthly | CN5: 42 | CO5: 96 | CP5: 315 | CQ5: classification_UWaveGestureLibrary_M2SFormerATPSelfRegulationSCP2_UEA_ftM_sl315_ll48_pl0_dm128_nh8_el3_dl1_df256_expand2_dc4_fc1_ebtimeF_dtTrue_Exp_0d4148af2649958c554afac0d997666c083cd806ff6e119eedd44a6ea585ecb27 | CR5: FALSE | CS5: 32 | CT5: FALSE | CU5: OT | CV5: classification | CW5: FALSE | CX5: 3 | CY5: 0.5 | CZ5: 1000 | DA5: 0 | DB5: 0 | DC5: 0 | DD5: 0 | DE5: FALSE | DF5: FALSE | DG5: TRUE | DH5: FALSE | DI5: 1 | DJ5: FALSE | DK5: FALSE | DL5: FALSE | DM5: 0.93078689 | DN5: 0.92182572 | DO5: 0.93078689 | DP5: 0.921875 | DQ5: 0.30050738 | DR5: '-1 | DS5: =_xlfn.XLOOKUP(BS5,Sheet2!B:B,Sheet2!A:A) -> UWG
A6: 46189.467 | B6: 3.2s | C6: c65c62a34e9c4367ba566b6bd1570863 | D6: spiffy-squirrel-884 | E6: LOCAL | F6: run.py | G6: sunwu | H6: FINISHED | I6: 0.2 | J6: 512 | K6: 256 | L6: 5000 | M6: d4148af2649958c554afac0d997666c083cd806ff6e119eedd44a6ea585ecb27 | N6: gelu | O6: 0.1 | P6: 0.25 | Q6: Namespace(task_name='classification', is_training=0, model_id='UWaveGestureLibrary', model='M2SFormerATPSelfRegulationSCP2', data='UEA', root_path='./dataset/UWaveGestureLibrary/', data_path='ETTh1.csv', features='M', target='OT', freq='h', checkpoints='00_final_model/ours', seq_len=np.int64(315), label_len=48, pred_len=0, seasonal_patterns='Monthly', inverse=False, mask_rate=0.25, anomaly_ratio=0.25, expand=2, d_conv=4, tv_dt=0, tv_B=0, tv_C=0, use_D=0, top_k=3, num_kernels=6, enc_in=3, dec_in=7, c_out=7, d_model=128, n_heads=8, e_layers=3, d_layers=1, d_ff=256, moving_avg=25, factor=1, distil=True, dropout=0.1, embed='timeF', activation='gelu', channel_independence=1, decomp_method='moving_avg', use_norm=1, down_sampling_layers=0, down_sampling_window=1, down_sampling_method=None, seg_len=96, num_workers=0, itr=1, train_epochs=1000, batch_size=256, patience=20, learning_rate=0.001, des='Exp', loss='MSE', lradj='type1', use_amp=False, use_gpu=True, gpu=0, gpu_type='cuda', use_multi_gpu=False, devices='0,1,2,3', p_hidden_dims=[128, 128], p_hidden_layers=2, use_dtw=False, augmentation_ratio=0, jitter=False, scaling=False, permutation=False, randompermutation=False, magwarp=False, timewarp=False, windowslice=False, windowwarp=False, rotation=False, spawner=False, dtwwarp=False, shapedtwwarp=False, wdba=False, discdtw=False, discsdtw=False, extra_tag='', patch_len=16, node_dim=10, gcn_depth=2, gcn_dropout=0.3, propalpha=0.3, conv_channel=32, skip_channel=32, individual=False, alpha=0.1, top_p=0.5, seed=42, pos=1, check_mlflow_exist=0, id='d4148af2649958c554afac0d997666c083cd806ff6e119eedd44a6ea585ecb27', device=device(type='cuda', index=0), num_class=8) | R6: 0 | S6: 256 | T6: 7 | U6: 1 | V6: 0 | W6: 00_final_model/ours | X6: precision recall f1-score support 0 0.97 0.88 0.92 40 1 1.00 1.00 1.00 40 2 0.97 0.90 0.94 40 3 0.93 0.70 0.80 40 4 0.73 0.93 0.81 40 5 0.87 0.97 0.92 40 6 0.98 1.00 0.99 40 7 1.00 1.00 1.00 40 accuracy 0.92 320 macro avg 0.93 0.92 0.92 320 weighted avg 0.93 0.92 0.92 320 | Y6: 32 | Z6: 4 | AA6: 256 | AB6: 1 | AC6: 128 | AD6: UEA | AE6: ETTh1.csv | AF6: 7 | AG6: moving_avg | AH6: Exp | AI6: cuda:0 | AJ6: 0,1,2,3 | AK6: FALSE | AL6: FALSE | AM6: TRUE | AN6: 0 | AO6: None | AP6: 1 | AQ6: 0.1 | AR6: FALSE | AS6: 3 | AT6: timeF | AU6: 3 | AV6: {'MLFLOW_EXPERIMENT': 'p1-tsc-our-eval-time-5times', 'HP__SEQ_LEN': '5000', 'HP__HIDDEN_DIM': '256', 'HP__DROPOUT': '0.2', 'HP__D_MODEL': '512', 'SHELL': '/bin/bash', 'TERM_PROGRAM_VERSION': '3.4', 'CONDA_MKL_INTERFACE_LAYER_BACKUP': '', 'CONDA_EXE': '/miniconda3/bin/conda', '_CE_M': '', 'TMUX': '/tmp/tmux-0/default,1082789,1', 'XML_CATALOG_FILES': 'file:///root/.local/share/mamba/envs/tsc/etc/xml/catalog file:///etc/xml/catalog', 'CF_TORCH_CUDA_ARCH_LIST_BACKUP': 'NOT_SET', 'PWD': '/remote-home/claude/tsc', 'LOGNAME': 'root', 'XDG_SESSION_TYPE': 'tty', 'CONDA_PREFIX': '/root/.local/share/mamba/envs/tsc', 'HOME': '/root', 'LANG': 'en_US.UTF-8', 'LS_COLORS': 'rs=0:di=01;34:ln=01;36:mh=00:pi=40;33:so=01;35:do=01;35:bd=40;33;01:cd=40;33;01:or=40;31;01:mi=00:su=37;41:sg=30;43:ca=00:tw=30;42:ow=34;42:st=37;44:ex=01;32:*.tar=01;31:*.tgz=01;31:*.arc=01;31:*.arj=01;31:*.taz=01;31:*.lha=01;31:*.lz4=01;31:*.lzh=01;31:*.lzma=01;31:*.tlz=01;31:*.txz=01;31:*.tzo=01;31:*.t7z=01;31:*.zip=01;31:*.z=01;31:*.dz=01;31:*.gz=01;31:*.lrz=01;31:*.lz=01;31:*.lzo=01;31:*.xz=01;31:*.zst=01;31:*.tzst=01;31:*.bz2=01;31:*.bz=01;31:*.tbz=01;31:*.tbz2=01;31:*.tz=01;31:*.deb=01;31:*.rpm=01;31:*.jar=01;31:*.war=01;31:*.ear=01;31:*.sar=01;31:*.rar=01;31:*.alz=01;31:*.ace=01;31:*.zoo=01;31:*.cpio=01;31:*.7z=01;31:*.rz=01;31:*.cab=01;31:*.wim=01;31:*.swm=01;31:*.dwm=01;31:*.esd=01;31:*.avif=01;35:*.jpg=01;35:*.jpeg=01;35:*.mjpg=01;35:*.mjpeg=01;35:*.gif=01;35:*.bmp=01;35:*.pbm=01;35:*.pgm=01;35:*.ppm=01;35:*.tga=01;35:*.xbm=01;35:*.xpm=01;35:*.tif=01;35:*.tiff=01;35:*.png=01;35:*.svg=01;35:*.svgz=01;35:*.mng=01;35:*.pcx=01;35:*.mov=01;35:*.mpg=01;35:*.mpeg=01;35:*.m2v=01;35:*.mkv=01;35:*.webm=01;35:*.webp=01;35:*.ogm=01;35:*.mp4=01;35:*.m4v=01;35:*.mp4v=01;35:*.vob=01;35:*.qt=01;35:*.nuv=01;35:*.wmv=01;35:*.asf=01;35:*.rm=01;35:*.rmvb=01;35:*.flc=01;35:*.avi=01;35:*.fli=01;35:*.flv=01;35:*.gl=01;35:*.dl=01;35:*.xcf=01;35:*.xwd=01;35:*.yuv=01;35:*.cgm=01;35:*.emf=01;35:*.ogv=01;35:*.ogx=01;35:*.aac=00;36:*.au=00;36:*.flac=00;36:*.m4a=00;36:*.mid=00;36:*.midi=00;36:*.mka=00;36:*.mp3=00;36:*.mpc=00;36:*.ogg=00;36:*.ra=00;36:*.wav=00;36:*.oga=00;36:*.opus=00;36:*.spx=00;36:*.xspf=00;36:*~=00;90:*#=00;90:*.bak=00;90:*.crdownload=00;90:*.dpkg-dist=00;90:*.dpkg-new=00;90:*.dpkg-old=00;90:*.dpkg-tmp=00;90:*.old=00;90:*.orig=00;90:*.part=00;90:*.rej=00;90:*.rpmnew=00;90:*.rpmorig=00;90:*.rpmsave=00;90:*.swp=00;90:*.tmp=00;90:*.ucf-dist=00;90:*.ucf-new=00;90:*.ucf-old=00;90:', 'CF_TORCH_CUDA_ARCH_LIST': '5.0;6.0;7.0;7.5;8.0;8.6;9.0;10.0;12.0+PTX', 'CONDA_PROMPT_MODIFIER': '(tsc) ', 'SSH_CONNECTION': '100.64.0.2 49956 100.64.0.17 22', 'LESSCLOSE': '/usr/bin/lesspipe %s %s', 'XDG_SESSION_CLASS': 'user', 'TERM': 'tmux-256color', '_CE_CONDA': '', 'LESSOPEN': '| /usr/bin/lesspipe %s', 'USER': 'root', 'TMUX_PANE': '%1', 'CONDA_SHLVL': '2', 'SHLVL': '3', 'XDG_SESSION_ID': '1105', 'CONDA_PYTHON_EXE': '/miniconda3/bin/python', 'XDG_RUNTIME_DIR': '/run/user/0', 'SSH_CLIENT': '100.64.0.2 65344 22', 'CONDA_DEFAULT_ENV': 'tsc', 'DEBUGINFOD_URLS': 'https://debuginfod.ubuntu.com ', 'XDG_DATA_DIRS': '/usr/share/gnome:/usr/local/share:/usr/share:/var/lib/snapd/desktop', 'PATH': '/root/.local/share/mamba/envs/tsc/bin:/root/bin/nodejs/bin:/root/.local/share/mamba/envs/tsc/bin:/miniconda3/condabin:/root/bin/nodejs/bin:/usr/local/sbin:/usr/local/bin:/usr/sbin:/usr/bin:/sbin:/bin:/usr/games:/usr/local/games:/snap/bin', 'DBUS_SESSION_BUS_ADDRESS': 'unix:path=/run/user/0/bus', 'SSH_TTY': '/dev/pts/0', 'CONDA_PREFIX_1': '/miniconda3', 'OLDPWD': '/root', 'TERM_PROGRAM': 'tmux', 'MKL_INTERFACE_LAYER': 'LP64,GNU', '_': '/root/.local/share/mamba/envs/tsc/bin/python', '_MLFLOW_TELEMETRY_SESSION_ID': 'f83c0e1869eb42c69aa4cdec3eb67d58', 'KMP_DUPLICATE_LIB_OK': 'True', 'KMP_INIT_AT_FORK': 'FALSE', 'CUDA_VISIBLE_DEVICES': '0', 'MLFLOW_TRACKING_USERNAME': 'sunwu', 'MLFLOW_TRACKING_PASSWORD': 'xxxxx', 'MLFLOW_HTTP_REQUEST_TIMEOUT': '5', 'MLFLOW_TRACKING_URI': 'http://192.168.10.61:5000', 'MLFLOW_EXPERIMENT_ID': '55', 'TEST_START': '1781579590647333490', 'TEST_END': '1781579591109450650'} | AW6: 2 | AY6: 1 | AZ6: M | BA6: h | BB6: 2 | BC6: 0.3 | BD6: 0 | BE6: cuda | BF6: d4148af2649958c554afac0d997666c083cd806ff6e119eedd44a6ea585ecb27 | BG6: FALSE | BH6: FALSE | BI6: 0 | BJ6: 1 | BK6: FALSE | BL6: 48 | BM6: 0.001 | BN6: MSE | BO6: type1 | BP6: FALSE | BQ6: 0.25 | BR6: M2SFormerATPSelfRegulationSCP2 | BS6: UWaveGestureLibrary | BT6: 25 | BU6: 8 | BV6: 10 | BW6: 8 | BX6: 6 | BY6: 0 | BZ6: [128, 128] | CA6: 2 | CB6: 16 | CC6: 20 | CD6: FALSE | CE6: 1 | CF6: 0 | CG6: 0.3 | CH6: FALSE | CI6: ./dataset/UWaveGestureLibrary/ | CJ6: FALSE | CK6: run.py --task_name classification --is_training 0 --root_path ./dataset/UWaveGestureLibrary/ --model_id UWaveGestureLibrary --model M2SFormerATPSelfRegulationSCP2 --data UEA --e_layers 3 --batch_size 256 --d_model 128 --d_ff 256 --top_k 3 --des Exp --itr 1 --learning_rate 0.001 --train_epochs 1000 --patience 20 --seed 42 --id d4148af2649958c554afac0d997666c083cd806ff6e119eedd44a6ea585ecb27 --use_gpu --num_workers 0 --checkpoints 00_final_model/ours --id d4148af2649958c554afac0d997666c083cd806ff6e119eedd44a6ea585ecb27 --check_mlflow_exist 0 | CL6: FALSE | CM6: Monthly | CN6: 42 | CO6: 96 | CP6: 315 | CQ6: classification_UWaveGestureLibrary_M2SFormerATPSelfRegulationSCP2_UEA_ftM_sl315_ll48_pl0_dm128_nh8_el3_dl1_df256_expand2_dc4_fc1_ebtimeF_dtTrue_Exp_0d4148af2649958c554afac0d997666c083cd806ff6e119eedd44a6ea585ecb27 | CR6: FALSE | CS6: 32 | CT6: FALSE | CU6: OT | CV6: classification | CW6: FALSE | CX6: 3 | CY6: 0.5 | CZ6: 1000 | DA6: 0 | DB6: 0 | DC6: 0 | DD6: 0 | DE6: FALSE | DF6: FALSE | DG6: TRUE | DH6: FALSE | DI6: 1 | DJ6: FALSE | DK6: FALSE | DL6: FALSE | DM6: 0.93078689 | DN6: 0.92182572 | DO6: 0.93078689 | DP6: 0.921875 | DQ6: 0.30197492 | DR6: '-1 | DS6: =_xlfn.XLOOKUP(BS6,Sheet2!B:B,Sheet2!A:A) -> UWG
A7: 46189.467 | B7: 3.2s | C7: 50ef8aa2536247edb040831a97473183 | D7: capable-mole-719 | E7: LOCAL | F7: run.py | G7: sunwu | H7: FINISHED | I7: 0.2 | J7: 1024 | K7: 1024 | L7: 5000 | M7: 7d72a1313879f87941ae4738e54758a878ab9c551e1667615a5bc63d82cc5ce6 | N7: gelu | O7: 0.1 | P7: 0.25 | Q7: Namespace(task_name='classification', is_training=0, model_id='SpokenArabicDigits', model='M2SFormerATPSelfRegulationSCP2', data='UEA', root_path='./dataset/SpokenArabicDigits/', data_path='ETTh1.csv', features='M', target='OT', freq='h', checkpoints='00_final_model/ours', seq_len=93, label_len=48, pred_len=0, seasonal_patterns='Monthly', inverse=False, mask_rate=0.25, anomaly_ratio=0.25, expand=2, d_conv=4, tv_dt=0, tv_B=0, tv_C=0, use_D=0, top_k=3, num_kernels=6, enc_in=13, dec_in=7, c_out=7, d_model=128, n_heads=8, e_layers=3, d_layers=1, d_ff=256, moving_avg=25, factor=1, distil=True, dropout=0.1, embed='timeF', activation='gelu', channel_independence=1, decomp_method='moving_avg', use_norm=1, down_sampling_layers=0, down_sampling_window=1, down_sampling_method=None, seg_len=96, num_workers=0, itr=1, train_epochs=1000, batch_size=256, patience=20, learning_rate=0.001, des='Exp', loss='MSE', lradj='type1', use_amp=False, use_gpu=True, gpu=0, gpu_type='cuda', use_multi_gpu=False, devices='0,1,2,3', p_hidden_dims=[128, 128], p_hidden_layers=2, use_dtw=False, augmentation_ratio=0, jitter=False, scaling=False, permutation=False, randompermutation=False, magwarp=False, timewarp=False, windowslice=False, windowwarp=False, rotation=False, spawner=False, dtwwarp=False, shapedtwwarp=False, wdba=False, discdtw=False, discsdtw=False, extra_tag='', patch_len=16, node_dim=10, gcn_depth=2, gcn_dropout=0.3, propalpha=0.3, conv_channel=32, skip_channel=32, individual=False, alpha=0.1, top_p=0.5, seed=42, pos=1, check_mlflow_exist=0, id='7d72a1313879f87941ae4738e54758a878ab9c551e1667615a5bc63d82cc5ce6', device=device(type='cuda', index=0), num_class=10) | R7: 0 | S7: 256 | T7: 7 | U7: 1 | V7: 0 | W7: 00_final_model/ours | X7: precision recall f1-score support 0 1.00 0.99 1.00 220 1 0.99 1.00 0.99 219 2 1.00 1.00 1.00 220 3 1.00 1.00 1.00 220 4 1.00 1.00 1.00 220 5 1.00 1.00 1.00 220 6 1.00 1.00 1.00 220 7 1.00 1.00 1.00 220 8 1.00 1.00 1.00 220 9 1.00 1.00 1.00 220 accuracy 1.00 2199 macro avg 1.00 1.00 1.00 2199 weighted avg 1.00 1.00 1.00 2199 | Y7: 32 | Z7: 4 | AA7: 256 | AB7: 1 | AC7: 128 | AD7: UEA | AE7: ETTh1.csv | AF7: 7 | AG7: moving_avg | AH7: Exp | AI7: cuda:0 | AJ7: 0,1,2,3 | AK7: FALSE | AL7: FALSE | AM7: TRUE | AN7: 0 | AO7: None | AP7: 1 | AQ7: 0.1 | AR7: FALSE | AS7: 3 | AT7: timeF | AU7: 13 | AV7: {'MLFLOW_EXPERIMENT': 'p1-tsc-our-eval-time-5times', 'HP__SEQ_LEN': '5000', 'HP__HIDDEN_DIM': '1024', 'HP__DROPOUT': '0.2', 'HP__D_MODEL': '1024', 'SHELL': '/bin/bash', 'TERM_PROGRAM_VERSION': '3.4', 'CONDA_MKL_INTERFACE_LAYER_BACKUP': '', 'CONDA_EXE': '/miniconda3/bin/conda', '_CE_M': '', 'TMUX': '/tmp/tmux-0/default,1082789,1', 'XML_CATALOG_FILES': 'file:///root/.local/share/mamba/envs/tsc/etc/xml/catalog file:///etc/xml/catalog', 'CF_TORCH_CUDA_ARCH_LIST_BACKUP': 'NOT_SET', 'PWD': '/remote-home/claude/tsc', 'LOGNAME': 'root', 'XDG_SESSION_TYPE': 'tty', 'CONDA_PREFIX': '/root/.local/share/mamba/envs/tsc', 'HOME': '/root', 'LANG': 'en_US.UTF-8', 'LS_COLORS': 'rs=0:di=01;34:ln=01;36:mh=00:pi=40;33:so=01;35:do=01;35:bd=40;33;01:cd=40;33;01:or=40;31;01:mi=00:su=37;41:sg=30;43:ca=00:tw=30;42:ow=34;42:st=37;44:ex=01;32:*.tar=01;31:*.tgz=01;31:*.arc=01;31:*.arj=01;31:*.taz=01;31:*.lha=01;31:*.lz4=01;31:*.lzh=01;31:*.lzma=01;31:*.tlz=01;31:*.txz=01;31:*.tzo=01;31:*.t7z=01;31:*.zip=01;31:*.z=01;31:*.dz=01;31:*.gz=01;31:*.lrz=01;31:*.lz=01;31:*.lzo=01;31:*.xz=01;31:*.zst=01;31:*.tzst=01;31:*.bz2=01;31:*.bz=01;31:*.tbz=01;31:*.tbz2=01;31:*.tz=01;31:*.deb=01;31:*.rpm=01;31:*.jar=01;31:*.war=01;31:*.ear=01;31:*.sar=01;31:*.rar=01;31:*.alz=01;31:*.ace=01;31:*.zoo=01;31:*.cpio=01;31:*.7z=01;31:*.rz=01;31:*.cab=01;31:*.wim=01;31:*.swm=01;31:*.dwm=01;31:*.esd=01;31:*.avif=01;35:*.jpg=01;35:*.jpeg=01;35:*.mjpg=01;35:*.mjpeg=01;35:*.gif=01;35:*.bmp=01;35:*.pbm=01;35:*.pgm=01;35:*.ppm=01;35:*.tga=01;35:*.xbm=01;35:*.xpm=01;35:*.tif=01;35:*.tiff=01;35:*.png=01;35:*.svg=01;35:*.svgz=01;35:*.mng=01;35:*.pcx=01;35:*.mov=01;35:*.mpg=01;35:*.mpeg=01;35:*.m2v=01;35:*.mkv=01;35:*.webm=01;35:*.webp=01;35:*.ogm=01;35:*.mp4=01;35:*.m4v=01;35:*.mp4v=01;35:*.vob=01;35:*.qt=01;35:*.nuv=01;35:*.wmv=01;35:*.asf=01;35:*.rm=01;35:*.rmvb=01;35:*.flc=01;35:*.avi=01;35:*.fli=01;35:*.flv=01;35:*.gl=01;35:*.dl=01;35:*.xcf=01;35:*.xwd=01;35:*.yuv=01;35:*.cgm=01;35:*.emf=01;35:*.ogv=01;35:*.ogx=01;35:*.aac=00;36:*.au=00;36:*.flac=00;36:*.m4a=00;36:*.mid=00;36:*.midi=00;36:*.mka=00;36:*.mp3=00;36:*.mpc=00;36:*.ogg=00;36:*.ra=00;36:*.wav=00;36:*.oga=00;36:*.opus=00;36:*.spx=00;36:*.xspf=00;36:*~=00;90:*#=00;90:*.bak=00;90:*.crdownload=00;90:*.dpkg-dist=00;90:*.dpkg-new=00;90:*.dpkg-old=00;90:*.dpkg-tmp=00;90:*.old=00;90:*.orig=00;90:*.part=00;90:*.rej=00;90:*.rpmnew=00;90:*.rpmorig=00;90:*.rpmsave=00;90:*.swp=00;90:*.tmp=00;90:*.ucf-dist=00;90:*.ucf-new=00;90:*.ucf-old=00;90:', 'CF_TORCH_CUDA_ARCH_LIST': '5.0;6.0;7.0;7.5;8.0;8.6;9.0;10.0;12.0+PTX', 'CONDA_PROMPT_MODIFIER': '(tsc) ', 'SSH_CONNECTION': '100.64.0.2 49956 100.64.0.17 22', 'LESSCLOSE': '/usr/bin/lesspipe %s %s', 'XDG_SESSION_CLASS': 'user', 'TERM': 'tmux-256color', '_CE_CONDA': '', 'LESSOPEN': '| /usr/bin/lesspipe %s', 'USER': 'root', 'TMUX_PANE': '%1', 'CONDA_SHLVL': '2', 'SHLVL': '3', 'XDG_SESSION_ID': '1105', 'CONDA_PYTHON_EXE': '/miniconda3/bin/python', 'XDG_RUNTIME_DIR': '/run/user/0', 'SSH_CLIENT': '100.64.0.2 65344 22', 'CONDA_DEFAULT_ENV': 'tsc', 'DEBUGINFOD_URLS': 'https://debuginfod.ubuntu.com ', 'XDG_DATA_DIRS': '/usr/share/gnome:/usr/local/share:/usr/share:/var/lib/snapd/desktop', 'PATH': '/root/.local/share/mamba/envs/tsc/bin:/root/bin/nodejs/bin:/root/.local/share/mamba/envs/tsc/bin:/miniconda3/condabin:/root/bin/nodejs/bin:/usr/local/sbin:/usr/local/bin:/usr/sbin:/usr/bin:/sbin:/bin:/usr/games:/usr/local/games:/snap/bin', 'DBUS_SESSION_BUS_ADDRESS': 'unix:path=/run/user/0/bus', 'SSH_TTY': '/dev/pts/0', 'CONDA_PREFIX_1': '/miniconda3', 'OLDPWD': '/root', 'TERM_PROGRAM': 'tmux', 'MKL_INTERFACE_LAYER': 'LP64,GNU', '_': '/root/.local/share/mamba/envs/tsc/bin/python', '_MLFLOW_TELEMETRY_SESSION_ID': 'b3c3214e5afb462f8f0c86ee38dce9b2', 'KMP_DUPLICATE_LIB_OK': 'True', 'KMP_INIT_AT_FORK': 'FALSE', 'CUDA_VISIBLE_DEVICES': '0', 'MLFLOW_TRACKING_USERNAME': 'sunwu', 'MLFLOW_TRACKING_PASSWORD': 'xxxxx', 'MLFLOW_HTTP_REQUEST_TIMEOUT': '5', 'MLFLOW_TRACKING_URI': 'http://192.168.10.61:5000', 'MLFLOW_EXPERIMENT_ID': '55', 'TEST_START': '1781579579840699289', 'TEST_END': '1781579582448704860'} | AW7: 2 | AY7: 1 | AZ7: M | BA7: h | BB7: 2 | BC7: 0.3 | BD7: 0 | BE7: cuda | BF7: 7d72a1313879f87941ae4738e54758a878ab9c551e1667615a5bc63d82cc5ce6 | BG7: FALSE | BH7: FALSE | BI7: 0 | BJ7: 1 | BK7: FALSE | BL7: 48 | BM7: 0.001 | BN7: MSE | BO7: type1 | BP7: FALSE | BQ7: 0.25 | BR7: M2SFormerATPSelfRegulationSCP2 | BS7: SpokenArabicDigits | BT7: 25 | BU7: 8 | BV7: 10 | BW7: 10 | BX7: 6 | BY7: 0 | BZ7: [128, 128] | CA7: 2 | CB7: 16 | CC7: 20 | CD7: FALSE | CE7: 1 | CF7: 0 | CG7: 0.3 | CH7: FALSE | CI7: ./dataset/SpokenArabicDigits/ | CJ7: FALSE | CK7: run.py --task_name classification --is_training 0 --root_path ./dataset/SpokenArabicDigits/ --model_id SpokenArabicDigits --model M2SFormerATPSelfRegulationSCP2 --data UEA --e_layers 3 --batch_size 256 --d_model 128 --d_ff 256 --top_k 3 --des Exp --itr 1 --learning_rate 0.001 --train_epochs 1000 --patience 20 --seed 42 --id 7d72a1313879f87941ae4738e54758a878ab9c551e1667615a5bc63d82cc5ce6 --use_gpu --num_workers 0 --checkpoints 00_final_model/ours --id 7d72a1313879f87941ae4738e54758a878ab9c551e1667615a5bc63d82cc5ce6 --check_mlflow_exist 0 | CL7: FALSE | CM7: Monthly | CN7: 42 | CO7: 96 | CP7: 93 | CQ7: classification_SpokenArabicDigits_M2SFormerATPSelfRegulationSCP2_UEA_ftM_sl93_ll48_pl0_dm128_nh8_el3_dl1_df256_expand2_dc4_fc1_ebtimeF_dtTrue_Exp_07d72a1313879f87941ae4738e54758a878ab9c551e1667615a5bc63d82cc5ce6 | CR7: FALSE | CS7: 32 | CT7: FALSE | CU7: OT | CV7: classification | CW7: FALSE | CX7: 3 | CY7: 0.5 | CZ7: 1000 | DA7: 0 | DB7: 0 | DC7: 0 | DD7: 0 | DE7: FALSE | DF7: FALSE | DG7: TRUE | DH7: FALSE | DI7: 1 | DJ7: FALSE | DK7: FALSE | DL7: FALSE | DM7: 0.99820148 | DN7: 0.99818303 | DO7: 0.99820148 | DP7: 0.99818099 | DQ7: 0.49769968 | DR7: '-1 | DS7: =_xlfn.XLOOKUP(BS7,Sheet2!B:B,Sheet2!A:A) -> SAD
