Workbook

Sheet F1
B3: 列标签
A4: 行标签 | B4: EC | C4: FD | D4: HB | E4: HW | F4: JV | G4: PEMS-SF | H4: SAD | I4: SRS1 | J4: SRS2 | K4: UWG
A5: 平均值项:metrics.f1
A6: M2SFormerATPSelfRegulationSCP2 | B6: 0.30624059 | C6: 0.68185145 | D6: 0.78178693 | E6: 0.39570973 | F6: 0.98279972 | G6: 0.83624226 | H6: 0.9964559 | I6: 0.92416518 | J6: 0.58177143 | K6: 0.91932572
A7: 平均值项:metrics.precision
A8: M2SFormerATPSelfRegulationSCP2 | B8: 0.34898906 | C8: 0.6846934 | D8: 0.78397342 | E8: 0.41415165 | F8: 0.98324036 | G8: 0.84841241 | H8: 0.99648985 | I8: 0.92555414 | J8: 0.58459707 | K8: 0.92828689
A9: 平均值项:metrics.recall
A10: M2SFormerATPSelfRegulationSCP2 | B10: 0.31787072 | C10: 0.68269012 | D10: 0.79512195 | E10: 0.41835294 | F10: 0.9827027 | G10: 0.83583815 | H10: 0.99645293 | I10: 0.92423208 | J10: 0.58333333 | K10: 0.919375

Sheet time_exp_v5_our_training_time_f
B1: run_id | C1: experiment_id | D1: status | E1: artifact_uri | F1: start_time | G1: end_time | H1: metrics.test_start | I1: metrics.accuracy | J1: metrics.f1 | K1: metrics.test_elapsed_seconds | L1: metrics.precision | M1: metrics.train_end | N1: metrics.recall | O1: metrics.test_end | P1: metrics.train_start | Q1: metrics.train_elapsed_seconds | R1: params.mask_rate | S1: params.num_kernels | T1: params.devices | U1: params.des | V1: params.permutation | W1: params.moving_avg | X1: params.pred_len | Y1: params.num_workers | Z1: params.n_heads | AA1: params.wdba | AB1: params.d_conv | AC1: params.use_amp | AD1: params.inverse | AE1: params.lradj | AF1: params.run_cmd | AG1: params.down_sampling_window | AH1: params.spawner | AI1: params.use_dtw | AJ1: params.features | AK1: params.e_layers | AL1: params.individual | AM1: params.num_class | AN1: params.tv_B | AO1: params.augmentation_ratio | AP1: params.discdtw | AQ1: params.learning_rate | AR1: params.d_ff | AS1: params.use_gpu | AT1: params.use_norm | AU1: params.top_k | AV1: params.alpha | AW1: params.dropout | AX1: params.scaling | AY1: params.conv_channel | AZ1: params.seed | BA1: params.is_training | BB1: params.patch_len | BC1: params.root_path | BD1: params.seasonal_patterns | BE1: params.patience | BF1: params.discsdtw | BG1: params.task_name | BH1: params.__id | BI1: params.use_D | BJ1: params.target | BK1: params.gcn_depth | BL1: params.extra_tag | BM1: params.use_multi_gpu | BN1: params.down_sampling_layers | BO1: params.tv_dt | BP1: params.gpu_type | BQ1: params.d_model | BR1: params.data_path | BS1: params.expand | BT1: params.embed | BU1: params.tv_C | BV1: params.seg_len | BW1: params.windowwarp | BX1: params.train_epochs | BY1: params.gcn_dropout | BZ1: params.timewarp | CA1: params.args | CB1: params.model | CC1: params.settings | CD1: params.down_sampling_method | CE1: params.seq_len | CF1: params.batch_size | CG1: params.shapedtwwarp | CH1: params.data | CI1: params.label_len | CJ1: params.d_layers | CK1: params.anomaly_ratio | CL1: params.dec_in | CM1: params.envs | CN1: params.c_out | CO1: params.p_hidden_dims | CP1: params.gpu | CQ1: params.model_id | CR1: params.decomp_method | CS1: params.id | CT1: params.enc_in | CU1: params.randompermutation | CV1: params.loss | CW1: params.distil | CX1: params.jitter | CY1: params.channel_independence | CZ1: params.p_hidden_layers | DA1: params.windowslice | DB1: params.magwarp | DC1: params.rotation | DD1: params.device | DE1: params.freq | DF1: params.checkpoints | DG1: params.top_p | DH1: params.node_dim | DI1: params.propalpha | DJ1: params.pos | DK1: params.itr | DL1: params.activation | DM1: params.dtwwarp | DN1: params.skip_channel | DO1: params.factor | DP1: tags.mlflow.source.type | DQ1: tags.mlflow.runName | DR1: tags.mlflow.source.name | DS1: tags.mlflow.user | DT1: dataset
A2: 0 | B2: 893f1f5f86994d429ae4aec29c68ed20 | C2: 37 | D2: FINISHED | E2: mlflow-artifacts:/37/893f1f5f86994d429ae4aec29c68ed20/artifacts | F2: 2026-05-20 01:02:37.388000+00:00 | G2: 2026-05-20 01:02:41.638000+00:00 | H2: 1.779238956442048e+18 | I2: 0.9276618934213985 | J2: 0.91870072 | K2: 0.55857769 | L2: 0.92766189 | M2: 1.779238956441986e+18 | N2: 0.91875 | O2: 1.7792389573386632e+18 | P2: 1.7792386616276795e+18 | Q2: 291.74645 | R2: 0.25 | S2: 6 | T2: 0,1,2,3 | U2: Exp | V2: FALSE | W2: 25 | X2: 0 | Y2: 10 | Z2: 8 | AA2: FALSE | AB2: 4 | AC2: FALSE | AD2: FALSE | AE2: type1 | AF2: run.py --task_name classification --is_training 1 --root_path ./dataset/UWaveGestureLibrary/ --model_id UWaveGestureLibrary --model M2SFormerATPSelfRegulationSCP2 --data UEA --e_layers 3 --batch_size 256 --d_model 128 --d_ff 256 --top_k 3 --des Exp --itr 1 --learning_rate 0.001 --train_epochs 1000 --patience 20 --seed 42 --id 5fc281e15c7af61420e745f87e5d200c8ae72e17269c60b809c65969d58db1ba_5 | AG2: 1 | AH2: FALSE | AI2: FALSE | AJ2: M | AK2: 3 | AL2: FALSE | AM2: 8 | AN2: 0 | AO2: 0 | AP2: FALSE | AQ2: 0.001 | AR2: 256 | AS2: TRUE | AT2: 1 | AU2: 3 | AV2: 0.1 | AW2: 0.1 | AX2: FALSE | AY2: 32 | AZ2: 42 | BA2: 1 | BB2: 16 | BC2: ./dataset/UWaveGestureLibrary/ | BD2: Monthly | BE2: 20 | BF2: FALSE | BG2: classification | BH2: 5fc281e15c7af61420e745f87e5d200c8ae72e17269c60b809c65969d58db1ba_5 | BI2: 0 | BJ2: OT | BK2: 2 | BM2: FALSE | BN2: 0 | BO2: 0 | BP2: cuda | BQ2: 128 | BR2: ETTh1.csv | BS2: 2 | BT2: timeF | BU2: 0 | BV2: 96 | BW2: FALSE | BX2: 1000 | BY2: 0.3 | BZ2: FALSE | CA2: Namespace(task_name='classification', is_training=1, model_id='UWaveGestureLibrary', model='M2SFormerATPSelfRegulationSCP2', data='UEA', root_path='./dataset/UWaveGestureLibrary/', data_path='ETTh1.csv', features='M', target='OT', freq='h', checkpoints='./checkpoints/', seq_len=np.int64(315), label_len=48, pred_len=0, seasonal_patterns='Monthly', inverse=False, mask_rate=0.25, anomaly_ratio=0.25, expand=2, d_conv=4, tv_dt=0, tv_B=0, tv_C=0, use_D=0, top_k=3, num_kernels=6, enc_in=3, dec_in=7, c_out=7, d_model=128, n_heads=8, e_layers=3, d_layers=1, d_ff=256, moving_avg=25, factor=1, distil=True, dropout=0.1, embed='timeF', activation='gelu', channel_independence=1, decomp_method='moving_avg', use_norm=1, down_sampling_layers=0, down_sampling_window=1, down_sampling_method=None, seg_len=96, num_workers=10, itr=1, train_epochs=1000, batch_size=256, patience=20, learning_rate=0.001, des='Exp', loss='MSE', lradj='type1', use_amp=False, use_gpu=True, gpu=0, gpu_type='cuda', use_multi_gpu=False, devices='0,1,2,3', p_hidden_dims=[128, 128], p_hidden_layers=2, use_dtw=False, augmentation_ratio=0, jitter=False, scaling=False, permutation=False, randompermutation=False, magwarp=False, timewarp=False, windowslice=False, windowwarp=False, rotation=False, spawner=False, dtwwarp=False, shapedtwwarp=False, wdba=False, discdtw=False, discsdtw=False, extra_tag='', patch_len=16, node_dim=10, gcn_depth=2, gcn_dropout=0.3, propalpha=0.3, conv_channel=32, skip_channel=32, individual=False, alpha=0.1, top_p=0.5, seed=42, pos=1, id='5fc281e15c7af61420e745f87e5d200c8ae72e17269c60b809c65969d58db1ba_5', device=device(type='cuda', index=0), num_class=8) | CB2: M2SFormerATPSelfRegulationSCP2 | CC2: classification_UWaveGestureLibrary_M2SFormerATPSelfRegulationSCP2_UEA_ftM_sl315_ll48_pl0_dm128_nh8_el3_dl1_df256_expand2_dc4_fc1_ebtimeF_dtTrue_Exp_05fc281e15c7af61420e745f87e5d200c8ae72e17269c60b809c65969d58db1ba_5 | CD2: None | CE2: 315 | CF2: 256 | CG2: FALSE | CH2: UEA | CI2: 48 | CJ2: 1 | CK2: 0.25 | CL2: 7 | CM2: {'TMUX': '/tmp/tmux-0/default,1344,0', 'USER': 'root', 'SSH_CLIENT': '10.233.106.128 41191 22', 'SHLVL': '2', 'MOTD_SHOWN': 'pam', 'HOME': '/root', 'OLDPWD': '/root', 'TERM_PROGRAM_VERSION': '3.2a', 'SSH_TTY': '/dev/pts/1', 'LC_CTYPE': 'C.UTF-8', 'HP__HIDDEN_DIM': '256', 'CUDA_VISIBLE_DEVICES': '0', 'LOGNAME': 'root', '_': '/mnt/sw_exp_data/miniconda3/envs/tsc1/bin/python', 'HP__SEQ_LEN': '5000', 'TERM': 'screen', 'PATH': '/usr/local/nodejs/bin:/usr/local/nodejs/bin:/usr/local/sbin:/usr/local/bin:/usr/sbin:/usr/bin:/sbin:/bin:/usr/games:/usr/local/games:/snap/bin', 'HP__DROPOUT': '0.2', 'LS_COLORS': 'rs=0:di=01;34:ln=01;36:mh=00:pi=40;33:so=01;35:do=01;35:bd=40;33;01:cd=40;33;01:or=40;31;01:mi=00:su=37;41:sg=30;43:ca=30;41:tw=30;42:ow=34;42:st=37;44:ex=01;32:*.tar=01;31:*.tgz=01;31:*.arc=01;31:*.arj=01;31:*.taz=01;31:*.lha=01;31:*.lz4=01;31:*.lzh=01;31:*.lzma=01;31:*.tlz=01;31:*.txz=01;31:*.tzo=01;31:*.t7z=01;31:*.zip=01;31:*.z=01;31:*.dz=01;31:*.gz=01;31:*.lrz=01;31:*.lz=01;31:*.lzo=01;31:*.xz=01;31:*.zst=01;31:*.tzst=01;31:*.bz2=01;31:*.bz=01;31:*.tbz=01;31:*.tbz2=01;31:*.tz=01;31:*.deb=01;31:*.rpm=01;31:*.jar=01;31:*.war=01;31:*.ear=01;31:*.sar=01;31:*.rar=01;31:*.alz=01;31:*.ace=01;31:*.zoo=01;31:*.cpio=01;31:*.7z=01;31:*.rz=01;31:*.cab=01;31:*.wim=01;31:*.swm=01;31:*.dwm=01;31:*.esd=01;31:*.jpg=01;35:*.jpeg=01;35:*.mjpg=01;35:*.mjpeg=01;35:*.gif=01;35:*.bmp=01;35:*.pbm=01;35:*.pgm=01;35:*.ppm=01;35:*.tga=01;35:*.xbm=01;35:*.xpm=01;35:*.tif=01;35:*.tiff=01;35:*.png=01;35:*.svg=01;35:*.svgz=01;35:*.mng=01;35:*.pcx=01;35:*.mov=01;35:*.mpg=01;35:*.mpeg=01;35:*.m2v=01;35:*.mkv=01;35:*.webm=01;35:*.webp=01;35:*.ogm=01;35:*.mp4=01;35:*.m4v=01;35:*.mp4v=01;35:*.vob=01;35:*.qt=01;35:*.nuv=01;35:*.wmv=01;35:*.asf=01;35:*.rm=01;35:*.rmvb=01;35:*.flc=01;35:*.avi=01;35:*.fli=01;35:*.flv=01;35:*.gl=01;35:*.dl=01;35:*.xcf=01;35:*.xwd=01;35:*.yuv=01;35:*.cgm=01;35:*.emf=01;35:*.ogv=01;35:*.ogx=01;35:*.aac=00;36:*.au=00;36:*.flac=00;36:*.m4a=00;36:*.mid=00;36:*.midi=00;36:*.mka=00;36:*.mp3=00;36:*.mpc=00;36:*.ogg=00;36:*.ra=00;36:*.wav=00;36:*.oga=00;36:*.opus=00;36:*.spx=00;36:*.xspf=00;36:', 'TERM_PROGRAM': 'tmux', 'MLFLOW_EXPERIMENT': 'time_exp_v5_our_training_time_five_repeated', 'SHELL': '/bin/bash', 'PWD': '/mnt/sw_exp_data/tsc', 'SSH_CONNECTION': '10.233.106.128 41191 10.233.116.228 22', 'TZ': 'Asia/Shanghai', 'TMUX_PANE': '%0', 'HP__NUM_CONV_STAGES': '4', 'HP__D_MODEL': '512', '_MLFLOW_TELEMETRY_SESSION_ID': '01060030641e4c8490704a1caa207add', 'MLFLOW_TRACKING_USERNAME': 'sunwu', 'MLFLOW_TRACKING_PASSWORD': 'xxxxx', 'MLFLOW_TRACKING_URI': 'http://192.168.10.61:5000', 'MLFLOW_EXPERIMENT_ID': '37', 'KMP_DUPLICATE_LIB_OK': 'True', 'KMP_INIT_AT_FORK': 'FALSE', 'TRAIN_START': '1779238661627679537', 'TORCHINDUCTOR_CACHE_DIR': '/tmp/torchinductor_root', 'TRAIN_END': '1779238956441986017', 'TEST_START': '1779238956442047949', 'TEST_END': '1779238957338663290'} | CN2: 7 | CO2: [128, 128] | CP2: 0 | CQ2: UWaveGestureLibrary | CR2: moving_avg | CS2: 5fc281e15c7af61420e745f87e5d200c8ae72e17269c60b809c65969d58db1ba_5 | CT2: 3 | CU2: FALSE | CV2: MSE | CW2: TRUE | CX2: FALSE | CY2: 1 | CZ2: 2 | DA2: FALSE | DB2: FALSE | DC2: FALSE | DD2: cuda:0 | DE2: h | DF2: ./checkpoints/ | DG2: 0.5 | DH2: 10 | DI2: 0.3 | DJ2: 1 | DK2: 1 | DL2: gelu | DM2: FALSE | DN2: 32 | DO2: 1 | DP2: LOCAL | DQ2: classification_UWaveGestureLibrary_M2SFormerATPSelfRegulationSCP2_UEA_ftM_sl315_ll48_pl0_dm128_nh8_el3_dl1_df256_expand2_dc4_fc1_ebtimeF_dtTrue_Exp_05fc281e15c7af61420e745f87e5d200c8ae72e17269c60b809c65969d58db1ba_5 | DR2: run.py | DS2: sunwu | DT2: =_xlfn.XLOOKUP(CQ2,dataset!B:B,dataset!A:A) -> UWG
A3: 1 | B3: f1c5b39cc4e74fb0bc413c7839859b3e | C3: 37 | D3: FINISHED | E3: mlflow-artifacts:/37/f1c5b39cc4e74fb0bc413c7839859b3e/artifacts | F3: 2026-05-20 01:00:36.058000+00:00 | G3: 2026-05-20 01:00:39.296000+00:00 | H3: 1.779238834754558e+18 | I3: 0.9276618934213985 | J3: 0.91870072 | K3: 0.71774162 | L3: 0.92766189 | M3: 1.7792388347545057e+18 | N3: 0.91875 | O3: 1.7792388360185956e+18 | P3: 1.7792383859474511e+18 | Q3: 445.85831 | R3: 0.25 | S3: 6 | T3: 0,1,2,3 | U3: Exp | V3: FALSE | W3: 25 | X3: 0 | Y3: 10 | Z3: 8 | AA3: FALSE | AB3: 4 | AC3: FALSE | AD3: FALSE | AE3: type1 | AF3: run.py --task_name classification --is_training 1 --root_path ./dataset/UWaveGestureLibrary/ --model_id UWaveGestureLibrary --model M2SFormerATPSelfRegulationSCP2 --data UEA --e_layers 3 --batch_size 256 --d_model 128 --d_ff 256 --top_k 3 --des Exp --itr 1 --learning_rate 0.001 --train_epochs 1000 --patience 20 --seed 42 --id 5fc281e15c7af61420e745f87e5d200c8ae72e17269c60b809c65969d58db1ba_4 | AG3: 1 | AH3: FALSE | AI3: FALSE | AJ3: M | AK3: 3 | AL3: FALSE | AM3: 8 | AN3: 0 | AO3: 0 | AP3: FALSE | AQ3: 0.001 | AR3: 256 | AS3: TRUE | AT3: 1 | AU3: 3 | AV3: 0.1 | AW3: 0.1 | AX3: FALSE | AY3: 32 | AZ3: 42 | BA3: 1 | BB3: 16 | BC3: ./dataset/UWaveGestureLibrary/ | BD3: Monthly | BE3: 20 | BF3: FALSE | BG3: classification | BH3: 5fc281e15c7af61420e745f87e5d200c8ae72e17269c60b809c65969d58db1ba_4 | BI3: 0 | BJ3: OT | BK3: 2 | BM3: FALSE | BN3: 0 | BO3: 0 | BP3: cuda | BQ3: 128 | BR3: ETTh1.csv | BS3: 2 | BT3: timeF | BU3: 0 | BV3: 96 | BW3: FALSE | BX3: 1000 | BY3: 0.3 | BZ3: FALSE | CA3: Namespace(task_name='classification', is_training=1, model_id='UWaveGestureLibrary', model='M2SFormerATPSelfRegulationSCP2', data='UEA', root_path='./dataset/UWaveGestureLibrary/', data_path='ETTh1.csv', features='M', target='OT', freq='h', checkpoints='./checkpoints/', seq_len=np.int64(315), label_len=48, pred_len=0, seasonal_patterns='Monthly', inverse=False, mask_rate=0.25, anomaly_ratio=0.25, expand=2, d_conv=4, tv_dt=0, tv_B=0, tv_C=0, use_D=0, top_k=3, num_kernels=6, enc_in=3, dec_in=7, c_out=7, d_model=128, n_heads=8, e_layers=3, d_layers=1, d_ff=256, moving_avg=25, factor=1, distil=True, dropout=0.1, embed='timeF', activation='gelu', channel_independence=1, decomp_method='moving_avg', use_norm=1, down_sampling_layers=0, down_sampling_window=1, down_sampling_method=None, seg_len=96, num_workers=10, itr=1, train_epochs=1000, batch_size=256, patience=20, learning_rate=0.001, des='Exp', loss='MSE', lradj='type1', use_amp=False, use_gpu=True, gpu=0, gpu_type='cuda', use_multi_gpu=False, devices='0,1,2,3', p_hidden_dims=[128, 128], p_hidden_layers=2, use_dtw=False, augmentation_ratio=0, jitter=False, scaling=False, permutation=False, randompermutation=False, magwarp=False, timewarp=False, windowslice=False, windowwarp=False, rotation=False, spawner=False, dtwwarp=False, shapedtwwarp=False, wdba=False, discdtw=False, discsdtw=False, extra_tag='', patch_len=16, node_dim=10, gcn_depth=2, gcn_dropout=0.3, propalpha=0.3, conv_channel=32, skip_channel=32, individual=False, alpha=0.1, top_p=0.5, seed=42, pos=1, id='5fc281e15c7af61420e745f87e5d200c8ae72e17269c60b809c65969d58db1ba_4', device=device(type='cuda', index=0), num_class=8) | CB3: M2SFormerATPSelfRegulationSCP2 | CC3: classification_UWaveGestureLibrary_M2SFormerATPSelfRegulationSCP2_UEA_ftM_sl315_ll48_pl0_dm128_nh8_el3_dl1_df256_expand2_dc4_fc1_ebtimeF_dtTrue_Exp_05fc281e15c7af61420e745f87e5d200c8ae72e17269c60b809c65969d58db1ba_4 | CD3: None | CE3: 315 | CF3: 256 | CG3: FALSE | CH3: UEA | CI3: 48 | CJ3: 1 | CK3: 0.25 | CL3: 7 | CM3: {'TMUX': '/tmp/tmux-0/default,1344,0', 'USER': 'root', 'SSH_CLIENT': '10.233.106.128 41191 22', 'SHLVL': '2', 'MOTD_SHOWN': 'pam', 'HOME': '/root', 'OLDPWD': '/root', 'TERM_PROGRAM_VERSION': '3.2a', 'SSH_TTY': '/dev/pts/1', 'LC_CTYPE': 'C.UTF-8', 'HP__HIDDEN_DIM': '256', 'CUDA_VISIBLE_DEVICES': '0', 'LOGNAME': 'root', '_': '/mnt/sw_exp_data/miniconda3/envs/tsc1/bin/python', 'HP__SEQ_LEN': '5000', 'TERM': 'screen', 'PATH': '/usr/local/nodejs/bin:/usr/local/nodejs/bin:/usr/local/sbin:/usr/local/bin:/usr/sbin:/usr/bin:/sbin:/bin:/usr/games:/usr/local/games:/snap/bin', 'HP__DROPOUT': '0.2', 'LS_COLORS': 'rs=0:di=01;34:ln=01;36:mh=00:pi=40;33:so=01;35:do=01;35:bd=40;33;01:cd=40;33;01:or=40;31;01:mi=00:su=37;41:sg=30;43:ca=30;41:tw=30;42:ow=34;42:st=37;44:ex=01;32:*.tar=01;31:*.tgz=01;31:*.arc=01;31:*.arj=01;31:*.taz=01;31:*.lha=01;31:*.lz4=01;31:*.lzh=01;31:*.lzma=01;31:*.tlz=01;31:*.txz=01;31:*.tzo=01;31:*.t7z=01;31:*.zip=01;31:*.z=01;31:*.dz=01;31:*.gz=01;31:*.lrz=01;31:*.lz=01;31:*.lzo=01;31:*.xz=01;31:*.zst=01;31:*.tzst=01;31:*.bz2=01;31:*.bz=01;31:*.tbz=01;31:*.tbz2=01;31:*.tz=01;31:*.deb=01;31:*.rpm=01;31:*.jar=01;31:*.war=01;31:*.ear=01;31:*.sar=01;31:*.rar=01;31:*.alz=01;31:*.ace=01;31:*.zoo=01;31:*.cpio=01;31:*.7z=01;31:*.rz=01;31:*.cab=01;31:*.wim=01;31:*.swm=01;31:*.dwm=01;31:*.esd=01;31:*.jpg=01;35:*.jpeg=01;35:*.mjpg=01;35:*.mjpeg=01;35:*.gif=01;35:*.bmp=01;35:*.pbm=01;35:*.pgm=01;35:*.ppm=01;35:*.tga=01;35:*.xbm=01;35:*.xpm=01;35:*.tif=01;35:*.tiff=01;35:*.png=01;35:*.svg=01;35:*.svgz=01;35:*.mng=01;35:*.pcx=01;35:*.mov=01;35:*.mpg=01;35:*.mpeg=01;35:*.m2v=01;35:*.mkv=01;35:*.webm=01;35:*.webp=01;35:*.ogm=01;35:*.mp4=01;35:*.m4v=01;35:*.mp4v=01;35:*.vob=01;35:*.qt=01;35:*.nuv=01;35:*.wmv=01;35:*.asf=01;35:*.rm=01;35:*.rmvb=01;35:*.flc=01;35:*.avi=01;35:*.fli=01;35:*.flv=01;35:*.gl=01;35:*.dl=01;35:*.xcf=01;35:*.xwd=01;35:*.yuv=01;35:*.cgm=01;35:*.emf=01;35:*.ogv=01;35:*.ogx=01;35:*.aac=00;36:*.au=00;36:*.flac=00;36:*.m4a=00;36:*.mid=00;36:*.midi=00;36:*.mka=00;36:*.mp3=00;36:*.mpc=00;36:*.ogg=00;36:*.ra=00;36:*.wav=00;36:*.oga=00;36:*.opus=00;36:*.spx=00;36:*.xspf=00;36:', 'TERM_PROGRAM': 'tmux', 'MLFLOW_EXPERIMENT': 'time_exp_v5_our_training_time_five_repeated', 'SHELL': '/bin/bash', 'PWD': '/mnt/sw_exp_data/tsc', 'SSH_CONNECTION': '10.233.106.128 41191 10.233.116.228 22', 'TZ': 'Asia/Shanghai', 'TMUX_PANE': '%0', 'HP__NUM_CONV_STAGES': '4', 'HP__D_MODEL': '512', '_MLFLOW_TELEMETRY_SESSION_ID': 'b37cac03bd9b47dfa55e62651ce73db3', 'MLFLOW_TRACKING_USERNAME': 'sunwu', 'MLFLOW_TRACKING_PASSWORD': 'xxxxx', 'MLFLOW_TRACKING_URI': 'http://192.168.10.61:5000', 'MLFLOW_EXPERIMENT_ID': '37', 'KMP_DUPLICATE_LIB_OK': 'True', 'KMP_INIT_AT_FORK': 'FALSE', 'TRAIN_START': '1779238385947451101', 'TORCHINDUCTOR_CACHE_DIR': '/tmp/torchinductor_root', 'TRAIN_END': '1779238834754505846', 'TEST_START': '1779238834754557971', 'TEST_END': '1779238836018595507'} | CN3: 7 | CO3: [128, 128] | CP3: 0 | CQ3: UWaveGestureLibrary | CR3: moving_avg | CS3: 5fc281e15c7af61420e745f87e5d200c8ae72e17269c60b809c65969d58db1ba_4 | CT3: 3 | CU3: FALSE | CV3: MSE | CW3: TRUE | CX3: FALSE | CY3: 1 | CZ3: 2 | DA3: FALSE | DB3: FALSE | DC3: FALSE | DD3: cuda:0 | DE3: h | DF3: ./checkpoints/ | DG3: 0.5 | DH3: 10 | DI3: 0.3 | DJ3: 1 | DK3: 1 | DL3: gelu | DM3: FALSE | DN3: 32 | DO3: 1 | DP3: LOCAL | DQ3: classification_UWaveGestureLibrary_M2SFormerATPSelfRegulationSCP2_UEA_ftM_sl315_ll48_pl0_dm128_nh8_el3_dl1_df256_expand2_dc4_fc1_ebtimeF_dtTrue_Exp_05fc281e15c7af61420e745f87e5d200c8ae72e17269c60b809c65969d58db1ba_4 | DR3: run.py | DS3: sunwu | DT3: =_xlfn.XLOOKUP(CQ3,dataset!B:B,dataset!A:A) -> UWG
A4: 2 | B4: a0f8cb45a9d44dbf8165271f24b09804 | C4: 37 | D4: FINISHED | E4: mlflow-artifacts:/37/a0f8cb45a9d44dbf8165271f24b09804/artifacts | F4: 2026-05-20 00:57:23.455000+00:00 | G4: 2026-05-20 00:57:26.987000+00:00 | H4: 1.7792386419632735e+18 | I4: 0.9276618934213985 | J4: 0.91870072 | K4: 0.83650184 | L4: 0.92766189 | M4: 1.7792386419632236e+18 | N4: 0.91875 | O4: 1.779238643383978e+18 | P4: 1.7792383681020073e+18 | Q4: 272.22169 | R4: 0.25 | S4: 6 | T4: 0,1,2,3 | U4: Exp | V4: FALSE | W4: 25 | X4: 0 | Y4: 10 | Z4: 8 | AA4: FALSE | AB4: 4 | AC4: FALSE | AD4: FALSE | AE4: type1 | AF4: run.py --task_name classification --is_training 1 --root_path ./dataset/UWaveGestureLibrary/ --model_id UWaveGestureLibrary --model M2SFormerATPSelfRegulationSCP2 --data UEA --e_layers 3 --batch_size 256 --d_model 128 --d_ff 256 --top_k 3 --des Exp --itr 1 --learning_rate 0.001 --train_epochs 1000 --patience 20 --seed 42 --id 5fc281e15c7af61420e745f87e5d200c8ae72e17269c60b809c65969d58db1ba_3 | AG4: 1 | AH4: FALSE | AI4: FALSE | AJ4: M | AK4: 3 | AL4: FALSE | AM4: 8 | AN4: 0 | AO4: 0 | AP4: FALSE | AQ4: 0.001 | AR4: 256 | AS4: TRUE | AT4: 1 | AU4: 3 | AV4: 0.1 | AW4: 0.1 | AX4: FALSE | AY4: 32 | AZ4: 42 | BA4: 1 | BB4: 16 | BC4: ./dataset/UWaveGestureLibrary/ | BD4: Monthly | BE4: 20 | BF4: FALSE | BG4: classification | BH4: 5fc281e15c7af61420e745f87e5d200c8ae72e17269c60b809c65969d58db1ba_3 | BI4: 0 | BJ4: OT | BK4: 2 | BM4: FALSE | BN4: 0 | BO4: 0 | BP4: cuda | BQ4: 128 | BR4: ETTh1.csv | BS4: 2 | BT4: timeF | BU4: 0 | BV4: 96 | BW4: FALSE | BX4: 1000 | BY4: 0.3 | BZ4: FALSE | CA4: Namespace(task_name='classification', is_training=1, model_id='UWaveGestureLibrary', model='M2SFormerATPSelfRegulationSCP2', data='UEA', root_path='./dataset/UWaveGestureLibrary/', data_path='ETTh1.csv', features='M', target='OT', freq='h', checkpoints='./checkpoints/', seq_len=np.int64(315), label_len=48, pred_len=0, seasonal_patterns='Monthly', inverse=False, mask_rate=0.25, anomaly_ratio=0.25, expand=2, d_conv=4, tv_dt=0, tv_B=0, tv_C=0, use_D=0, top_k=3, num_kernels=6, enc_in=3, dec_in=7, c_out=7, d_model=128, n_heads=8, e_layers=3, d_layers=1, d_ff=256, moving_avg=25, factor=1, distil=True, dropout=0.1, embed='timeF', activation='gelu', channel_independence=1, decomp_method='moving_avg', use_norm=1, down_sampling_layers=0, down_sampling_window=1, down_sampling_method=None, seg_len=96, num_workers=10, itr=1, train_epochs=1000, batch_size=256, patience=20, learning_rate=0.001, des='Exp', loss='MSE', lradj='type1', use_amp=False, use_gpu=True, gpu=0, gpu_type='cuda', use_multi_gpu=False, devices='0,1,2,3', p_hidden_dims=[128, 128], p_hidden_layers=2, use_dtw=False, augmentation_ratio=0, jitter=False, scaling=False, permutation=False, randompermutation=False, magwarp=False, timewarp=False, windowslice=False, windowwarp=False, rotation=False, spawner=False, dtwwarp=False, shapedtwwarp=False, wdba=False, discdtw=False, discsdtw=False, extra_tag='', patch_len=16, node_dim=10, gcn_depth=2, gcn_dropout=0.3, propalpha=0.3, conv_channel=32, skip_channel=32, individual=False, alpha=0.1, top_p=0.5, seed=42, pos=1, id='5fc281e15c7af61420e745f87e5d200c8ae72e17269c60b809c65969d58db1ba_3', device=device(type='cuda', index=0), num_class=8) | CB4: M2SFormerATPSelfRegulationSCP2 | CC4: classification_UWaveGestureLibrary_M2SFormerATPSelfRegulationSCP2_UEA_ftM_sl315_ll48_pl0_dm128_nh8_el3_dl1_df256_expand2_dc4_fc1_ebtimeF_dtTrue_Exp_05fc281e15c7af61420e745f87e5d200c8ae72e17269c60b809c65969d58db1ba_3 | CD4: None | CE4: 315 | CF4: 256 | CG4: FALSE | CH4: UEA | CI4: 48 | CJ4: 1 | CK4: 0.25 | CL4: 7 | CM4: {'TMUX': '/tmp/tmux-0/default,1344,0', 'USER': 'root', 'SSH_CLIENT': '10.233.106.128 41191 22', 'SHLVL': '2', 'MOTD_SHOWN': 'pam', 'HOME': '/root', 'OLDPWD': '/root', 'TERM_PROGRAM_VERSION': '3.2a', 'SSH_TTY': '/dev/pts/1', 'LC_CTYPE': 'C.UTF-8', 'HP__HIDDEN_DIM': '256', 'CUDA_VISIBLE_DEVICES': '0', 'LOGNAME': 'root', '_': '/mnt/sw_exp_data/miniconda3/envs/tsc1/bin/python', 'HP__SEQ_LEN': '5000', 'TERM': 'screen', 'PATH': '/usr/local/nodejs/bin:/usr/local/nodejs/bin:/usr/local/sbin:/usr/local/bin:/usr/sbin:/usr/bin:/sbin:/bin:/usr/games:/usr/local/games:/snap/bin', 'HP__DROPOUT': '0.2', 'LS_COLORS': 'rs=0:di=01;34:ln=01;36:mh=00:pi=40;33:so=01;35:do=01;35:bd=40;33;01:cd=40;33;01:or=40;31;01:mi=00:su=37;41:sg=30;43:ca=30;41:tw=30;42:ow=34;42:st=37;44:ex=01;32:*.tar=01;31:*.tgz=01;31:*.arc=01;31:*.arj=01;31:*.taz=01;31:*.lha=01;31:*.lz4=01;31:*.lzh=01;31:*.lzma=01;31:*.tlz=01;31:*.txz=01;31:*.tzo=01;31:*.t7z=01;31:*.zip=01;31:*.z=01;31:*.dz=01;31:*.gz=01;31:*.lrz=01;31:*.lz=01;31:*.lzo=01;31:*.xz=01;31:*.zst=01;31:*.tzst=01;31:*.bz2=01;31:*.bz=01;31:*.tbz=01;31:*.tbz2=01;31:*.tz=01;31:*.deb=01;31:*.rpm=01;31:*.jar=01;31:*.war=01;31:*.ear=01;31:*.sar=01;31:*.rar=01;31:*.alz=01;31:*.ace=01;31:*.zoo=01;31:*.cpio=01;31:*.7z=01;31:*.rz=01;31:*.cab=01;31:*.wim=01;31:*.swm=01;31:*.dwm=01;31:*.esd=01;31:*.jpg=01;35:*.jpeg=01;35:*.mjpg=01;35:*.mjpeg=01;35:*.gif=01;35:*.bmp=01;35:*.pbm=01;35:*.pgm=01;35:*.ppm=01;35:*.tga=01;35:*.xbm=01;35:*.xpm=01;35:*.tif=01;35:*.tiff=01;35:*.png=01;35:*.svg=01;35:*.svgz=01;35:*.mng=01;35:*.pcx=01;35:*.mov=01;35:*.mpg=01;35:*.mpeg=01;35:*.m2v=01;35:*.mkv=01;35:*.webm=01;35:*.webp=01;35:*.ogm=01;35:*.mp4=01;35:*.m4v=01;35:*.mp4v=01;35:*.vob=01;35:*.qt=01;35:*.nuv=01;35:*.wmv=01;35:*.asf=01;35:*.rm=01;35:*.rmvb=01;35:*.flc=01;35:*.avi=01;35:*.fli=01;35:*.flv=01;35:*.gl=01;35:*.dl=01;35:*.xcf=01;35:*.xwd=01;35:*.yuv=01;35:*.cgm=01;35:*.emf=01;35:*.ogv=01;35:*.ogx=01;35:*.aac=00;36:*.au=00;36:*.flac=00;36:*.m4a=00;36:*.mid=00;36:*.midi=00;36:*.mka=00;36:*.mp3=00;36:*.mpc=00;36:*.ogg=00;36:*.ra=00;36:*.wav=00;36:*.oga=00;36:*.opus=00;36:*.spx=00;36:*.xspf=00;36:', 'TERM_PROGRAM': 'tmux', 'MLFLOW_EXPERIMENT': 'time_exp_v5_our_training_time_five_repeated', 'SHELL': '/bin/bash', 'PWD': '/mnt/sw_exp_data/tsc', 'SSH_CONNECTION': '10.233.106.128 41191 10.233.116.228 22', 'TZ': 'Asia/Shanghai', 'TMUX_PANE': '%0', 'HP__NUM_CONV_STAGES': '4', 'HP__D_MODEL': '512', '_MLFLOW_TELEMETRY_SESSION_ID': '37e7b02a4f894050ab0cfb43c2a8da07', 'MLFLOW_TRACKING_USERNAME': 'sunwu', 'MLFLOW_TRACKING_PASSWORD': 'xxxxx', 'MLFLOW_TRACKING_URI': 'http://192.168.10.61:5000', 'MLFLOW_EXPERIMENT_ID': '37', 'KMP_DUPLICATE_LIB_OK': 'True', 'KMP_INIT_AT_FORK': 'FALSE', 'TRAIN_START': '1779238368102007359', 'TORCHINDUCTOR_CACHE_DIR': '/tmp/torchinductor_root', 'TRAIN_END': '1779238641963223626', 'TEST_START': '1779238641963273367', 'TEST_END': '1779238643383978051'} | CN4: 7 | CO4: [128, 128] | CP4: 0 | CQ4: UWaveGestureLibrary | CR4: moving_avg | CS4: 5fc281e15c7af61420e745f87e5d200c8ae72e17269c60b809c65969d58db1ba_3 | CT4: 3 | CU4: FALSE | CV4: MSE | CW4: TRUE | CX4: FALSE | CY4: 1 | CZ4: 2 | DA4: FALSE | DB4: FALSE | DC4: FALSE | DD4: cuda:0 | DE4: h | DF4: ./checkpoints/ | DG4: 0.5 | DH4: 10 | DI4: 0.3 | DJ4: 1 | DK4: 1 | DL4: gelu | DM4: FALSE | DN4: 32 | DO4: 1 | DP4: LOCAL | DQ4: classification_UWaveGestureLibrary_M2SFormerATPSelfRegulationSCP2_UEA_ftM_sl315_ll48_pl0_dm128_nh8_el3_dl1_df256_expand2_dc4_fc1_ebtimeF_dtTrue_Exp_05fc281e15c7af61420e745f87e5d200c8ae72e17269c60b809c65969d58db1ba_3 | DR4: run.py | DS4: sunwu | DT4: =_xlfn.XLOOKUP(CQ4,dataset!B:B,dataset!A:A) -> UWG
A5: 3 | B5: 331862f46e824ffe95942b5728959b6e | C5: 37 | D5: FINISHED | E5: mlflow-artifacts:/37/331862f46e824ffe95942b5728959b6e/artifacts | F5: 2026-05-20 00:52:48.249000+00:00 | G5: 2026-05-20 00:52:51.379000+00:00 | H5: 1.7792383670688584e+18 | I5: 0.9307868934213985 | J5: 0.92182572 | K5: 0.54335493 | L5: 0.93078689 | M5: 1.7792383670687985e+18 | N5: 0.921875 | O5: 1.7792383681928788e+18 | P5: 1.7792380502331978e+18 | Q5: 313.7185 | R5: 0.25 | S5: 6 | T5: 0,1,2,3 | U5: Exp | V5: FALSE | W5: 25 | X5: 0 | Y5: 10 | Z5: 8 | AA5: FALSE | AB5: 4 | AC5: FALSE | AD5: FALSE | AE5: type1 | AF5: run.py --task_name classification --is_training 1 --root_path ./dataset/UWaveGestureLibrary/ --model_id UWaveGestureLibrary --model M2SFormerATPSelfRegulationSCP2 --data UEA --e_layers 3 --batch_size 256 --d_model 128 --d_ff 256 --top_k 3 --des Exp --itr 1 --learning_rate 0.001 --train_epochs 1000 --patience 20 --seed 42 --id 5fc281e15c7af61420e745f87e5d200c8ae72e17269c60b809c65969d58db1ba_2 | AG5: 1 | AH5: FALSE | AI5: FALSE | AJ5: M | AK5: 3 | AL5: FALSE | AM5: 8 | AN5: 0 | AO5: 0 | AP5: FALSE | AQ5: 0.001 | AR5: 256 | AS5: TRUE | AT5: 1 | AU5: 3 | AV5: 0.1 | AW5: 0.1 | AX5: FALSE | AY5: 32 | AZ5: 42 | BA5: 1 | BB5: 16 | BC5: ./dataset/UWaveGestureLibrary/ | BD5: Monthly | BE5: 20 | BF5: FALSE | BG5: classification | BH5: 5fc281e15c7af61420e745f87e5d200c8ae72e17269c60b809c65969d58db1ba_2 | BI5: 0 | BJ5: OT | BK5: 2 | BM5: FALSE | BN5: 0 | BO5: 0 | BP5: cuda | BQ5: 128 | BR5: ETTh1.csv | BS5: 2 | BT5: timeF | BU5: 0 | BV5: 96 | BW5: FALSE | BX5: 1000 | BY5: 0.3 | BZ5: FALSE | CA5: Namespace(task_name='classification', is_training=1, model_id='UWaveGestureLibrary', model='M2SFormerATPSelfRegulationSCP2', data='UEA', root_path='./dataset/UWaveGestureLibrary/', data_path='ETTh1.csv', features='M', target='OT', freq='h', checkpoints='./checkpoints/', seq_len=np.int64(315), label_len=48, pred_len=0, seasonal_patterns='Monthly', inverse=False, mask_rate=0.25, anomaly_ratio=0.25, expand=2, d_conv=4, tv_dt=0, tv_B=0, tv_C=0, use_D=0, top_k=3, num_kernels=6, enc_in=3, dec_in=7, c_out=7, d_model=128, n_heads=8, e_layers=3, d_layers=1, d_ff=256, moving_avg=25, factor=1, distil=True, dropout=0.1, embed='timeF', activation='gelu', channel_independence=1, decomp_method='moving_avg', use_norm=1, down_sampling_layers=0, down_sampling_window=1, down_sampling_method=None, seg_len=96, num_workers=10, itr=1, train_epochs=1000, batch_size=256, patience=20, learning_rate=0.001, des='Exp', loss='MSE', lradj='type1', use_amp=False, use_gpu=True, gpu=0, gpu_type='cuda', use_multi_gpu=False, devices='0,1,2,3', p_hidden_dims=[128, 128], p_hidden_layers=2, use_dtw=False, augmentation_ratio=0, jitter=False, scaling=False, permutation=False, randompermutation=False, magwarp=False, timewarp=False, windowslice=False, windowwarp=False, rotation=False, spawner=False, dtwwarp=False, shapedtwwarp=False, wdba=False, discdtw=False, discsdtw=False, extra_tag='', patch_len=16, node_dim=10, gcn_depth=2, gcn_dropout=0.3, propalpha=0.3, conv_channel=32, skip_channel=32, individual=False, alpha=0.1, top_p=0.5, seed=42, pos=1, id='5fc281e15c7af61420e745f87e5d200c8ae72e17269c60b809c65969d58db1ba_2', device=device(type='cuda', index=0), num_class=8) | CB5: M2SFormerATPSelfRegulationSCP2 | CC5: classification_UWaveGestureLibrary_M2SFormerATPSelfRegulationSCP2_UEA_ftM_sl315_ll48_pl0_dm128_nh8_el3_dl1_df256_expand2_dc4_fc1_ebtimeF_dtTrue_Exp_05fc281e15c7af61420e745f87e5d200c8ae72e17269c60b809c65969d58db1ba_2 | CD5: None | CE5: 315 | CF5: 256 | CG5: FALSE | CH5: UEA | CI5: 48 | CJ5: 1 | CK5: 0.25 | CL5: 7 | CM5: {'TMUX': '/tmp/tmux-0/default,1344,0', 'USER': 'root', 'SSH_CLIENT': '10.233.106.128 41191 22', 'SHLVL': '2', 'MOTD_SHOWN': 'pam', 'HOME': '/root', 'OLDPWD': '/root', 'TERM_PROGRAM_VERSION': '3.2a', 'SSH_TTY': '/dev/pts/1', 'LC_CTYPE': 'C.UTF-8', 'HP__HIDDEN_DIM': '256', 'CUDA_VISIBLE_DEVICES': '0', 'LOGNAME': 'root', '_': '/mnt/sw_exp_data/miniconda3/envs/tsc1/bin/python', 'HP__SEQ_LEN': '5000', 'TERM': 'screen', 'PATH': '/usr/local/nodejs/bin:/usr/local/nodejs/bin:/usr/local/sbin:/usr/local/bin:/usr/sbin:/usr/bin:/sbin:/bin:/usr/games:/usr/local/games:/snap/bin', 'HP__DROPOUT': '0.2', 'LS_COLORS': 'rs=0:di=01;34:ln=01;36:mh=00:pi=40;33:so=01;35:do=01;35:bd=40;33;01:cd=40;33;01:or=40;31;01:mi=00:su=37;41:sg=30;43:ca=30;41:tw=30;42:ow=34;42:st=37;44:ex=01;32:*.tar=01;31:*.tgz=01;31:*.arc=01;31:*.arj=01;31:*.taz=01;31:*.lha=01;31:*.lz4=01;31:*.lzh=01;31:*.lzma=01;31:*.tlz=01;31:*.txz=01;31:*.tzo=01;31:*.t7z=01;31:*.zip=01;31:*.z=01;31:*.dz=01;31:*.gz=01;31:*.lrz=01;31:*.lz=01;31:*.lzo=01;31:*.xz=01;31:*.zst=01;31:*.tzst=01;31:*.bz2=01;31:*.bz=01;31:*.tbz=01;31:*.tbz2=01;31:*.tz=01;31:*.deb=01;31:*.rpm=01;31:*.jar=01;31:*.war=01;31:*.ear=01;31:*.sar=01;31:*.rar=01;31:*.alz=01;31:*.ace=01;31:*.zoo=01;31:*.cpio=01;31:*.7z=01;31:*.rz=01;31:*.cab=01;31:*.wim=01;31:*.swm=01;31:*.dwm=01;31:*.esd=01;31:*.jpg=01;35:*.jpeg=01;35:*.mjpg=01;35:*.mjpeg=01;35:*.gif=01;35:*.bmp=01;35:*.pbm=01;35:*.pgm=01;35:*.ppm=01;35:*.tga=01;35:*.xbm=01;35:*.xpm=01;35:*.tif=01;35:*.tiff=01;35:*.png=01;35:*.svg=01;35:*.svgz=01;35:*.mng=01;35:*.pcx=01;35:*.mov=01;35:*.mpg=01;35:*.mpeg=01;35:*.m2v=01;35:*.mkv=01;35:*.webm=01;35:*.webp=01;35:*.ogm=01;35:*.mp4=01;35:*.m4v=01;35:*.mp4v=01;35:*.vob=01;35:*.qt=01;35:*.nuv=01;35:*.wmv=01;35:*.asf=01;35:*.rm=01;35:*.rmvb=01;35:*.flc=01;35:*.avi=01;35:*.fli=01;35:*.flv=01;35:*.gl=01;35:*.dl=01;35:*.xcf=01;35:*.xwd=01;35:*.yuv=01;35:*.cgm=01;35:*.emf=01;35:*.ogv=01;35:*.ogx=01;35:*.aac=00;36:*.au=00;36:*.flac=00;36:*.m4a=00;36:*.mid=00;36:*.midi=00;36:*.mka=00;36:*.mp3=00;36:*.mpc=00;36:*.ogg=00;36:*.ra=00;36:*.wav=00;36:*.oga=00;36:*.opus=00;36:*.spx=00;36:*.xspf=00;36:', 'TERM_PROGRAM': 'tmux', 'MLFLOW_EXPERIMENT': 'time_exp_v5_our_training_time_five_repeated', 'SHELL': '/bin/bash', 'PWD': '/mnt/sw_exp_data/tsc', 'SSH_CONNECTION': '10.233.106.128 41191 10.233.116.228 22', 'TZ': 'Asia/Shanghai', 'TMUX_PANE': '%0', 'HP__NUM_CONV_STAGES': '4', 'HP__D_MODEL': '512', '_MLFLOW_TELEMETRY_SESSION_ID': '58eddc522b574c879a22b8e978d03408', 'MLFLOW_TRACKING_USERNAME': 'sunwu', 'MLFLOW_TRACKING_PASSWORD': 'xxxxx', 'MLFLOW_TRACKING_URI': 'http://192.168.10.61:5000', 'MLFLOW_EXPERIMENT_ID': '37', 'KMP_DUPLICATE_LIB_OK': 'True', 'KMP_INIT_AT_FORK': 'FALSE', 'TRAIN_START': '1779238050233197861', 'TORCHINDUCTOR_CACHE_DIR': '/tmp/torchinductor_root', 'TRAIN_END': '1779238367068798356', 'TEST_START': '1779238367068858480', 'TEST_END': '1779238368192878787'} | CN5: 7 | CO5: [128, 128] | CP5: 0 | CQ5: UWaveGestureLibrary | CR5: moving_avg | CS5: 5fc281e15c7af61420e745f87e5d200c8ae72e17269c60b809c65969d58db1ba_2 | CT5: 3 | CU5: FALSE | CV5: MSE | CW5: TRUE | CX5: FALSE | CY5: 1 | CZ5: 2 | DA5: FALSE | DB5: FALSE | DC5: FALSE | DD5: cuda:0 | DE5: h | DF5: ./checkpoints/ | DG5: 0.5 | DH5: 10 | DI5: 0.3 | DJ5: 1 | DK5: 1 | DL5: gelu | DM5: FALSE | DN5: 32 | DO5: 1 | DP5: LOCAL | DQ5: classification_UWaveGestureLibrary_M2SFormerATPSelfRegulationSCP2_UEA_ftM_sl315_ll48_pl0_dm128_nh8_el3_dl1_df256_expand2_dc4_fc1_ebtimeF_dtTrue_Exp_05fc281e15c7af61420e745f87e5d200c8ae72e17269c60b809c65969d58db1ba_2 | DR5: run.py | DS5: sunwu | DT5: =_xlfn.XLOOKUP(CQ5,dataset!B:B,dataset!A:A) -> UWG
A6: 4 | B6: d807520a538a413c8b8f22c0ab75635c | C6: 37 | D6: FINISHED | E6: mlflow-artifacts:/37/d807520a538a413c8b8f22c0ab75635c/artifacts | F6: 2026-05-20 00:52:29.434000+00:00 | G6: 2026-05-20 00:52:33.227000+00:00 | H6: 1.7792383481293181e+18 | I6: 0.9276618934213985 | J6: 0.91870072 | K6: 0.73269523 | L6: 0.92766189 | M6: 1.7792383481292529e+18 | N6: 0.91875 | O6: 1.779238349221786e+18 | P6: 1.779238022856927e+18 | Q6: 322.9334 | R6: 0.25 | S6: 6 | T6: 0,1,2,3 | U6: Exp | V6: FALSE | W6: 25 | X6: 0 | Y6: 10 | Z6: 8 | AA6: FALSE | AB6: 4 | AC6: FALSE | AD6: FALSE | AE6: type1 | AF6: run.py --task_name classification --is_training 1 --root_path ./dataset/UWaveGestureLibrary/ --model_id UWaveGestureLibrary --model M2SFormerATPSelfRegulationSCP2 --data UEA --e_layers 3 --batch_size 256 --d_model 128 --d_ff 256 --top_k 3 --des Exp --itr 1 --learning_rate 0.001 --train_epochs 1000 --patience 20 --seed 42 --id 5fc281e15c7af61420e745f87e5d200c8ae72e17269c60b809c65969d58db1ba_1 | AG6: 1 | AH6: FALSE | AI6: FALSE | AJ6: M | AK6: 3 | AL6: FALSE | AM6: 8 | AN6: 0 | AO6: 0 | AP6: FALSE | AQ6: 0.001 | AR6: 256 | AS6: TRUE | AT6: 1 | AU6: 3 | AV6: 0.1 | AW6: 0.1 | AX6: FALSE | AY6: 32 | AZ6: 42 | BA6: 1 | BB6: 16 | BC6: ./dataset/UWaveGestureLibrary/ | BD6: Monthly | BE6: 20 | BF6: FALSE | BG6: classification | BH6: 5fc281e15c7af61420e745f87e5d200c8ae72e17269c60b809c65969d58db1ba_1 | BI6: 0 | BJ6: OT | BK6: 2 | BM6: FALSE | BN6: 0 | BO6: 0 | BP6: cuda | BQ6: 128 | BR6: ETTh1.csv | BS6: 2 | BT6: timeF | BU6: 0 | BV6: 96 | BW6: FALSE | BX6: 1000 | BY6: 0.3 | BZ6: FALSE | CA6: Namespace(task_name='classification', is_training=1, model_id='UWaveGestureLibrary', model='M2SFormerATPSelfRegulationSCP2', data='UEA', root_path='./dataset/UWaveGestureLibrary/', data_path='ETTh1.csv', features='M', target='OT', freq='h', checkpoints='./checkpoints/', seq_len=np.int64(315), label_len=48, pred_len=0, seasonal_patterns='Monthly', inverse=False, mask_rate=0.25, anomaly_ratio=0.25, expand=2, d_conv=4, tv_dt=0, tv_B=0, tv_C=0, use_D=0, top_k=3, num_kernels=6, enc_in=3, dec_in=7, c_out=7, d_model=128, n_heads=8, e_layers=3, d_layers=1, d_ff=256, moving_avg=25, factor=1, distil=True, dropout=0.1, embed='timeF', activation='gelu', channel_independence=1, decomp_method='moving_avg', use_norm=1, down_sampling_layers=0, down_sampling_window=1, down_sampling_method=None, seg_len=96, num_workers=10, itr=1, train_epochs=1000, batch_size=256, patience=20, learning_rate=0.001, des='Exp', loss='MSE', lradj='type1', use_amp=False, use_gpu=True, gpu=0, gpu_type='cuda', use_multi_gpu=False, devices='0,1,2,3', p_hidden_dims=[128, 128], p_hidden_layers=2, use_dtw=False, augmentation_ratio=0, jitter=False, scaling=False, permutation=False, randompermutation=False, magwarp=False, timewarp=False, windowslice=False, windowwarp=False, rotation=False, spawner=False, dtwwarp=False, shapedtwwarp=False, wdba=False, discdtw=False, discsdtw=False, extra_tag='', patch_len=16, node_dim=10, gcn_depth=2, gcn_dropout=0.3, propalpha=0.3, conv_channel=32, skip_channel=32, individual=False, alpha=0.1, top_p=0.5, seed=42, pos=1, id='5fc281e15c7af61420e745f87e5d200c8ae72e17269c60b809c65969d58db1ba_1', device=device(type='cuda', index=0), num_class=8) | CB6: M2SFormerATPSelfRegulationSCP2 | CC6: classification_UWaveGestureLibrary_M2SFormerATPSelfRegulationSCP2_UEA_ftM_sl315_ll48_pl0_dm128_nh8_el3_dl1_df256_expand2_dc4_fc1_ebtimeF_dtTrue_Exp_05fc281e15c7af61420e745f87e5d200c8ae72e17269c60b809c65969d58db1ba_1 | CD6: None | CE6: 315 | CF6: 256 | CG6: FALSE | CH6: UEA | CI6: 48 | CJ6: 1 | CK6: 0.25 | CL6: 7 | CM6: {'TMUX': '/tmp/tmux-0/default,1344,0', 'USER': 'root', 'SSH_CLIENT': '10.233.106.128 41191 22', 'SHLVL': '2', 'MOTD_SHOWN': 'pam', 'HOME': '/root', 'OLDPWD': '/root', 'TERM_PROGRAM_VERSION': '3.2a', 'SSH_TTY': '/dev/pts/1', 'LC_CTYPE': 'C.UTF-8', 'HP__HIDDEN_DIM': '256', 'CUDA_VISIBLE_DEVICES': '0', 'LOGNAME': 'root', '_': '/mnt/sw_exp_data/miniconda3/envs/tsc1/bin/python', 'HP__SEQ_LEN': '5000', 'TERM': 'screen', 'PATH': '/usr/local/nodejs/bin:/usr/local/nodejs/bin:/usr/local/sbin:/usr/local/bin:/usr/sbin:/usr/bin:/sbin:/bin:/usr/games:/usr/local/games:/snap/bin', 'HP__DROPOUT': '0.2', 'LS_COLORS': 'rs=0:di=01;34:ln=01;36:mh=00:pi=40;33:so=01;35:do=01;35:bd=40;33;01:cd=40;33;01:or=40;31;01:mi=00:su=37;41:sg=30;43:ca=30;41:tw=30;42:ow=34;42:st=37;44:ex=01;32:*.tar=01;31:*.tgz=01;31:*.arc=01;31:*.arj=01;31:*.taz=01;31:*.lha=01;31:*.lz4=01;31:*.lzh=01;31:*.lzma=01;31:*.tlz=01;31:*.txz=01;31:*.tzo=01;31:*.t7z=01;31:*.zip=01;31:*.z=01;31:*.dz=01;31:*.gz=01;31:*.lrz=01;31:*.lz=01;31:*.lzo=01;31:*.xz=01;31:*.zst=01;31:*.tzst=01;31:*.bz2=01;31:*.bz=01;31:*.tbz=01;31:*.tbz2=01;31:*.tz=01;31:*.deb=01;31:*.rpm=01;31:*.jar=01;31:*.war=01;31:*.ear=01;31:*.sar=01;31:*.rar=01;31:*.alz=01;31:*.ace=01;31:*.zoo=01;31:*.cpio=01;31:*.7z=01;31:*.rz=01;31:*.cab=01;31:*.wim=01;31:*.swm=01;31:*.dwm=01;31:*.esd=01;31:*.jpg=01;35:*.jpeg=01;35:*.mjpg=01;35:*.mjpeg=01;35:*.gif=01;35:*.bmp=01;35:*.pbm=01;35:*.pgm=01;35:*.ppm=01;35:*.tga=01;35:*.xbm=01;35:*.xpm=01;35:*.tif=01;35:*.tiff=01;35:*.png=01;35:*.svg=01;35:*.svgz=01;35:*.mng=01;35:*.pcx=01;35:*.mov=01;35:*.mpg=01;35:*.mpeg=01;35:*.m2v=01;35:*.mkv=01;35:*.webm=01;35:*.webp=01;35:*.ogm=01;35:*.mp4=01;35:*.m4v=01;35:*.mp4v=01;35:*.vob=01;35:*.qt=01;35:*.nuv=01;35:*.wmv=01;35:*.asf=01;35:*.rm=01;35:*.rmvb=01;35:*.flc=01;35:*.avi=01;35:*.fli=01;35:*.flv=01;35:*.gl=01;35:*.dl=01;35:*.xcf=01;35:*.xwd=01;35:*.yuv=01;35:*.cgm=01;35:*.emf=01;35:*.ogv=01;35:*.ogx=01;35:*.aac=00;36:*.au=00;36:*.flac=00;36:*.m4a=00;36:*.mid=00;36:*.midi=00;36:*.mka=00;36:*.mp3=00;36:*.mpc=00;36:*.ogg=00;36:*.ra=00;36:*.wav=00;36:*.oga=00;36:*.opus=00;36:*.spx=00;36:*.xspf=00;36:', 'TERM_PROGRAM': 'tmux', 'MLFLOW_EXPERIMENT': 'time_exp_v5_our_training_time_five_repeated', 'SHELL': '/bin/bash', 'PWD': '/mnt/sw_exp_data/tsc', 'SSH_CONNECTION': '10.233.106.128 41191 10.233.116.228 22', 'TZ': 'Asia/Shanghai', 'TMUX_PANE': '%0', 'HP__NUM_CONV_STAGES': '4', 'HP__D_MODEL': '512', '_MLFLOW_TELEMETRY_SESSION_ID': 'b2d6edd3c70e46ca877709896d039bc4', 'MLFLOW_TRACKING_USERNAME': 'sunwu', 'MLFLOW_TRACKING_PASSWORD': 'xxxxx', 'MLFLOW_TRACKING_URI': 'http://192.168.10.61:5000', 'MLFLOW_EXPERIMENT_ID': '37', 'KMP_DUPLICATE_LIB_OK': 'True', 'KMP_INIT_AT_FORK': 'FALSE', 'TRAIN_START': '1779238022856927007', 'TORCHINDUCTOR_CACHE_DIR': '/tmp/torchinductor_root', 'TRAIN_END': '1779238348129252948', 'TEST_START': '1779238348129318106', 'TEST_END': '1779238349221786013'} | CN6: 7 | CO6: [128, 128] | CP6: 0 | CQ6: UWaveGestureLibrary | CR6: moving_avg | CS6: 5fc281e15c7af61420e745f87e5d200c8ae72e17269c60b809c65969d58db1ba_1 | CT6: 3 | CU6: FALSE | CV6: MSE | CW6: TRUE | CX6: FALSE | CY6: 1 | CZ6: 2 | DA6: FALSE | DB6: FALSE | DC6: FALSE | DD6: cuda:0 | DE6: h | DF6: ./checkpoints/ | DG6: 0.5 | DH6: 10 | DI6: 0.3 | DJ6: 1 | DK6: 1 | DL6: gelu | DM6: FALSE | DN6: 32 | DO6: 1 | DP6: LOCAL | DQ6: classification_UWaveGestureLibrary_M2SFormerATPSelfRegulationSCP2_UEA_ftM_sl315_ll48_pl0_dm128_nh8_el3_dl1_df256_expand2_dc4_fc1_ebtimeF_dtTrue_Exp_05fc281e15c7af61420e745f87e5d200c8ae72e17269c60b809c65969d58db1ba_1 | DR6: run.py | DS6: sunwu | DT6: =_xlfn.XLOOKUP(CQ6,dataset!B:B,dataset!A:A) -> UWG
A7: 5 | B7: c710b4c249534463a53a134d98c255ae | C7: 37 | D7: FINISHED | E7: mlflow-artifacts:/37/c710b4c249534463a53a134d98c255ae/artifacts | F7: 2026-05-20 00:47:11.314000+00:00 | G7: 2026-05-20 00:47:14.495000+00:00 | H7: 1.779238023807779e+18 | I7: 0.9968492171766387 | J7: 0.99681973 | K7: 0.8299034 | L7: 0.99684922 | M7: 1.779238023807719e+18 | N7: 0.99681673 | O7: 1.7792380311135977e+18 | P7: 1.7792378882770757e+18 | Q7: 108.69927 | R7: 0.25 | S7: 6 | T7: 0,1,2,3 | U7: Exp | V7: FALSE | W7: 25 | X7: 0 | Y7: 10 | Z7: 8 | AA7: FALSE | AB7: 4 | AC7: FALSE | AD7: FALSE | AE7: type1 | AF7: run.py --task_name classification --is_training 1 --root_path ./dataset/SpokenArabicDigits/ --model_id SpokenArabicDigits --model M2SFormerATPSelfRegulationSCP2 --data UEA --e_layers 3 --batch_size 256 --d_model 128 --d_ff 256 --top_k 3 --des Exp --itr 1 --learning_rate 0.001 --train_epochs 1000 --patience 20 --seed 42 --id bb5dc45f9c54bcc3d000a01a3a4f6f5af0910c1d929934bcb09ac76be69d1a37_5 | AG7: 1 | AH7: FALSE | AI7: FALSE | AJ7: M | AK7: 3 | AL7: FALSE | AM7: 10 | AN7: 0 | AO7: 0 | AP7: FALSE | AQ7: 0.001 | AR7: 256 | AS7: TRUE | AT7: 1 | AU7: 3 | AV7: 0.1 | AW7: 0.1 | AX7: FALSE | AY7: 32 | AZ7: 42 | BA7: 1 | BB7: 16 | BC7: ./dataset/SpokenArabicDigits/ | BD7: Monthly | BE7: 20 | BF7: FALSE | BG7: classification | BH7: bb5dc45f9c54bcc3d000a01a3a4f6f5af0910c1d929934bcb09ac76be69d1a37_5 | BI7: 0 | BJ7: OT | BK7: 2 | BM7: FALSE | BN7: 0 | BO7: 0 | BP7: cuda | BQ7: 128 | BR7: ETTh1.csv | BS7: 2 | BT7: timeF | BU7: 0 | BV7: 96 | BW7: FALSE | BX7: 1000 | BY7: 0.3 | BZ7: FALSE | CA7: Namespace(task_name='classification', is_training=1, model_id='SpokenArabicDigits', model='M2SFormerATPSelfRegulationSCP2', data='UEA', root_path='./dataset/SpokenArabicDigits/', data_path='ETTh1.csv', features='M', target='OT', freq='h', checkpoints='./checkpoints/', seq_len=93, label_len=48, pred_len=0, seasonal_patterns='Monthly', inverse=False, mask_rate=0.25, anomaly_ratio=0.25, expand=2, d_conv=4, tv_dt=0, tv_B=0, tv_C=0, use_D=0, top_k=3, num_kernels=6, enc_in=13, dec_in=7, c_out=7, d_model=128, n_heads=8, e_layers=3, d_layers=1, d_ff=256, moving_avg=25, factor=1, distil=True, dropout=0.1, embed='timeF', activation='gelu', channel_independence=1, decomp_method='moving_avg', use_norm=1, down_sampling_layers=0, down_sampling_window=1, down_sampling_method=None, seg_len=96, num_workers=10, itr=1, train_epochs=1000, batch_size=256, patience=20, learning_rate=0.001, des='Exp', loss='MSE', lradj='type1', use_amp=False, use_gpu=True, gpu=0, gpu_type='cuda', use_multi_gpu=False, devices='0,1,2,3', p_hidden_dims=[128, 128], p_hidden_layers=2, use_dtw=False, augmentation_ratio=0, jitter=False, scaling=False, permutation=False, randompermutation=False, magwarp=False, timewarp=False, windowslice=False, windowwarp=False, rotation=False, spawner=False, dtwwarp=False, shapedtwwarp=False, wdba=False, discdtw=False, discsdtw=False, extra_tag='', patch_len=16, node_dim=10, gcn_depth=2, gcn_dropout=0.3, propalpha=0.3, conv_channel=32, skip_channel=32, individual=False, alpha=0.1, top_p=0.5, seed=42, pos=1, id='bb5dc45f9c54bcc3d000a01a3a4f6f5af0910c1d929934bcb09ac76be69d1a37_5', device=device(type='cuda', index=0), num_class=10) | CB7: M2SFormerATPSelfRegulationSCP2 | CC7: classification_SpokenArabicDigits_M2SFormerATPSelfRegulationSCP2_UEA_ftM_sl93_ll48_pl0_dm128_nh8_el3_dl1_df256_expand2_dc4_fc1_ebtimeF_dtTrue_Exp_0bb5dc45f9c54bcc3d000a01a3a4f6f5af0910c1d929934bcb09ac76be69d1a37_5 | CD7: None | CE7: 93 | CF7: 256 | CG7: FALSE | CH7: UEA | CI7: 48 | CJ7: 1 | CK7: 0.25 | CL7: 7 | CM7: {'TMUX': '/tmp/tmux-0/default,1344,0', 'USER': 'root', 'SSH_CLIENT': '10.233.106.128 41191 22', 'SHLVL': '2', 'MOTD_SHOWN': 'pam', 'HOME': '/root', 'OLDPWD': '/root', 'TERM_PROGRAM_VERSION': '3.2a', 'SSH_TTY': '/dev/pts/1', 'LC_CTYPE': 'C.UTF-8', 'HP__HIDDEN_DIM': '512', 'CUDA_VISIBLE_DEVICES': '0', 'LOGNAME': 'root', '_': '/mnt/sw_exp_data/miniconda3/envs/tsc1/bin/python', 'HP__SEQ_LEN': '5000', 'TERM': 'screen', 'PATH': '/usr/local/nodejs/bin:/usr/local/nodejs/bin:/usr/local/sbin:/usr/local/bin:/usr/sbin:/usr/bin:/sbin:/bin:/usr/games:/usr/local/games:/snap/bin', 'HP__DROPOUT': '0.2', 'LS_COLORS': 'rs=0:di=01;34:ln=01;36:mh=00:pi=40;33:so=01;35:do=01;35:bd=40;33;01:cd=40;33;01:or=40;31;01:mi=00:su=37;41:sg=30;43:ca=30;41:tw=30;42:ow=34;42:st=37;44:ex=01;32:*.tar=01;31:*.tgz=01;31:*.arc=01;31:*.arj=01;31:*.taz=01;31:*.lha=01;31:*.lz4=01;31:*.lzh=01;31:*.lzma=01;31:*.tlz=01;31:*.txz=01;31:*.tzo=01;31:*.t7z=01;31:*.zip=01;31:*.z=01;31:*.dz=01;31:*.gz=01;31:*.lrz=01;31:*.lz=01;31:*.lzo=01;31:*.xz=01;31:*.zst=01;31:*.tzst=01;31:*.bz2=01;31:*.bz=01;31:*.tbz=01;31:*.tbz2=01;31:*.tz=01;31:*.deb=01;31:*.rpm=01;31:*.jar=01;31:*.war=01;31:*.ear=01;31:*.sar=01;31:*.rar=01;31:*.alz=01;31:*.ace=01;31:*.zoo=01;31:*.cpio=01;31:*.7z=01;31:*.rz=01;31:*.cab=01;31:*.wim=01;31:*.swm=01;31:*.dwm=01;31:*.esd=01;31:*.jpg=01;35:*.jpeg=01;35:*.mjpg=01;35:*.mjpeg=01;35:*.gif=01;35:*.bmp=01;35:*.pbm=01;35:*.pgm=01;35:*.ppm=01;35:*.tga=01;35:*.xbm=01;35:*.xpm=01;35:*.tif=01;35:*.tiff=01;35:*.png=01;35:*.svg=01;35:*.svgz=01;35:*.mng=01;35:*.pcx=01;35:*.mov=01;35:*.mpg=01;35:*.mpeg=01;35:*.m2v=01;35:*.mkv=01;35:*.webm=01;35:*.webp=01;35:*.ogm=01;35:*.mp4=01;35:*.m4v=01;35:*.mp4v=01;35:*.vob=01;35:*.qt=01;35:*.nuv=01;35:*.wmv=01;35:*.asf=01;35:*.rm=01;35:*.rmvb=01;35:*.flc=01;35:*.avi=01;35:*.fli=01;35:*.flv=01;35:*.gl=01;35:*.dl=01;35:*.xcf=01;35:*.xwd=01;35:*.yuv=01;35:*.cgm=01;35:*.emf=01;35:*.ogv=01;35:*.ogx=01;35:*.aac=00;36:*.au=00;36:*.flac=00;36:*.m4a=00;36:*.mid=00;36:*.midi=00;36:*.mka=00;36:*.mp3=00;36:*.mpc=00;36:*.ogg=00;36:*.ra=00;36:*.wav=00;36:*.oga=00;36:*.opus=00;36:*.spx=00;36:*.xspf=00;36:', 'TERM_PROGRAM': 'tmux', 'MLFLOW_EXPERIMENT': 'time_exp_v5_our_training_time_five_repeated', 'SHELL': '/bin/bash', 'PWD': '/mnt/sw_exp_data/tsc', 'SSH_CONNECTION': '10.233.106.128 41191 10.233.116.228 22', 'TZ': 'Asia/Shanghai', 'TMUX_PANE': '%0', 'HP__NUM_CONV_STAGES': '4', 'HP__D_MODEL': '128', '_MLFLOW_TELEMETRY_SESSION_ID': '560237b002274cffb1c39f6df13d440c', 'MLFLOW_TRACKING_USERNAME': 'sunwu', 'MLFLOW_TRACKING_PASSWORD': 'xxxxx', 'MLFLOW_TRACKING_URI': 'http://192.168.10.61:5000', 'MLFLOW_EXPERIMENT_ID': '37', 'KMP_DUPLICATE_LIB_OK': 'True', 'KMP_INIT_AT_FORK': 'FALSE', 'TRAIN_START': '1779237888277075683', 'TORCHINDUCTOR_CACHE_DIR': '/tmp/torchinductor_root', 'TRAIN_END': '1779238023807719013', 'TEST_START': '1779238023807779093', 'TEST_END': '1779238031113597746'} | CN7: 7 | CO7: [128, 128] | CP7: 0 | CQ7: SpokenArabicDigits | CR7: moving_avg | CS7: bb5dc45f9c54bcc3d000a01a3a4f6f5af0910c1d929934bcb09ac76be69d1a37_5 | CT7: 13 | CU7: FALSE | CV7: MSE | CW7: TRUE | CX7: FALSE | CY7: 1 | CZ7: 2 | DA7: FALSE | DB7: FALSE | DC7: FALSE | DD7: cuda:0 | DE7: h | DF7: ./checkpoints/ | DG7: 0.5 | DH7: 10 | DI7: 0.3 | DJ7: 1 | DK7: 1 | DL7: gelu | DM7: FALSE | DN7: 32 | DO7: 1 | DP7: LOCAL | DQ7: classification_SpokenArabicDigits_M2SFormerATPSelfRegulationSCP2_UEA_ftM_sl93_ll48_pl0_dm128_nh8_el3_dl1_df256_expand2_dc4_fc1_ebtimeF_dtTrue_Exp_0bb5dc45f9c54bcc3d000a01a3a4f6f5af0910c1d929934bcb09ac76be69d1a37_5 | DR7: run.py | DS7: sunwu | DT7: =_xlfn.XLOOKUP(CQ7,dataset!B:B,dataset!A:A) -> SAD
A8: 6 | B8: a542ffa592eb41c8b37fdfd8eea1b931 | C8: 37 | D8: FINISHED | E8: mlflow-artifacts:/37/a542ffa592eb41c8b37fdfd8eea1b931/artifacts | F8: 2026-05-20 00:46:46.355000+00:00 | G8: 2026-05-20 00:46:50.530000+00:00 | H8: 1.7792379999193298e+18 | I8: 0.9964103964011198 | J8: 0.99636592 | K8: 0.57345681 | L8: 0.9964104 | M8: 1.7792379999192384e+18 | N8: 0.99636198 | O8: 1.7792380062762263e+18 | P8: 1.7792378329630866e+18 | Q8: 140.14644 | R8: 0.25 | S8: 6 | T8: 0,1,2,3 | U8: Exp | V8: FALSE | W8: 25 | X8: 0 | Y8: 10 | Z8: 8 | AA8: FALSE | AB8: 4 | AC8: FALSE | AD8: FALSE | AE8: type1 | AF8: run.py --task_name classification --is_training 1 --root_path ./dataset/SpokenArabicDigits/ --model_id SpokenArabicDigits --model M2SFormerATPSelfRegulationSCP2 --data UEA --e_layers 3 --batch_size 256 --d_model 128 --d_ff 256 --top_k 3 --des Exp --itr 1 --learning_rate 0.001 --train_epochs 1000 --patience 20 --seed 42 --id bb5dc45f9c54bcc3d000a01a3a4f6f5af0910c1d929934bcb09ac76be69d1a37_4 | AG8: 1 | AH8: FALSE | AI8: FALSE | AJ8: M | AK8: 3 | AL8: FALSE | AM8: 10 | AN8: 0 | AO8: 0 | AP8: FALSE | AQ8: 0.001 | AR8: 256 | AS8: TRUE | AT8: 1 | AU8: 3 | AV8: 0.1 | AW8: 0.1 | AX8: FALSE | AY8: 32 | AZ8: 42 | BA8: 1 | BB8: 16 | BC8: ./dataset/SpokenArabicDigits/ | BD8: Monthly | BE8: 20 | BF8: FALSE | BG8: classification | BH8: bb5dc45f9c54bcc3d000a01a3a4f6f5af0910c1d929934bcb09ac76be69d1a37_4 | BI8: 0 | BJ8: OT | BK8: 2 | BM8: FALSE | BN8: 0 | BO8: 0 | BP8: cuda | BQ8: 128 | BR8: ETTh1.csv | BS8: 2 | BT8: timeF | BU8: 0 | BV8: 96 | BW8: FALSE | BX8: 1000 | BY8: 0.3 | BZ8: FALSE | CA8: Namespace(task_name='classification', is_training=1, model_id='SpokenArabicDigits', model='M2SFormerATPSelfRegulationSCP2', data='UEA', root_path='./dataset/SpokenArabicDigits/', data_path='ETTh1.csv', features='M', target='OT', freq='h', checkpoints='./checkpoints/', seq_len=93, label_len=48, pred_len=0, seasonal_patterns='Monthly', inverse=False, mask_rate=0.25, anomaly_ratio=0.25, expand=2, d_conv=4, tv_dt=0, tv_B=0, tv_C=0, use_D=0, top_k=3, num_kernels=6, enc_in=13, dec_in=7, c_out=7, d_model=128, n_heads=8, e_layers=3, d_layers=1, d_ff=256, moving_avg=25, factor=1, distil=True, dropout=0.1, embed='timeF', activation='gelu', channel_independence=1, decomp_method='moving_avg', use_norm=1, down_sampling_layers=0, down_sampling_window=1, down_sampling_method=None, seg_len=96, num_workers=10, itr=1, train_epochs=1000, batch_size=256, patience=20, learning_rate=0.001, des='Exp', loss='MSE', lradj='type1', use_amp=False, use_gpu=True, gpu=0, gpu_type='cuda', use_multi_gpu=False, devices='0,1,2,3', p_hidden_dims=[128, 128], p_hidden_layers=2, use_dtw=False, augmentation_ratio=0, jitter=False, scaling=False, permutation=False, randompermutation=False, magwarp=False, timewarp=False, windowslice=False, windowwarp=False, rotation=False, spawner=False, dtwwarp=False, shapedtwwarp=False, wdba=False, discdtw=False, discsdtw=False, extra_tag='', patch_len=16, node_dim=10, gcn_depth=2, gcn_dropout=0.3, propalpha=0.3, conv_channel=32, skip_channel=32, individual=False, alpha=0.1, top_p=0.5, seed=42, pos=1, id='bb5dc45f9c54bcc3d000a01a3a4f6f5af0910c1d929934bcb09ac76be69d1a37_4', device=device(type='cuda', index=0), num_class=10) | CB8: M2SFormerATPSelfRegulationSCP2 | CC8: classification_SpokenArabicDigits_M2SFormerATPSelfRegulationSCP2_UEA_ftM_sl93_ll48_pl0_dm128_nh8_el3_dl1_df256_expand2_dc4_fc1_ebtimeF_dtTrue_Exp_0bb5dc45f9c54bcc3d000a01a3a4f6f5af0910c1d929934bcb09ac76be69d1a37_4 | CD8: None | CE8: 93 | CF8: 256 | CG8: FALSE | CH8: UEA | CI8: 48 | CJ8: 1 | CK8: 0.25 | CL8: 7 | CM8: {'TMUX': '/tmp/tmux-0/default,1344,0', 'USER': 'root', 'SSH_CLIENT': '10.233.106.128 41191 22', 'SHLVL': '2', 'MOTD_SHOWN': 'pam', 'HOME': '/root', 'OLDPWD': '/root', 'TERM_PROGRAM_VERSION': '3.2a', 'SSH_TTY': '/dev/pts/1', 'LC_CTYPE': 'C.UTF-8', 'HP__HIDDEN_DIM': '512', 'CUDA_VISIBLE_DEVICES': '0', 'LOGNAME': 'root', '_': '/mnt/sw_exp_data/miniconda3/envs/tsc1/bin/python', 'HP__SEQ_LEN': '5000', 'TERM': 'screen', 'PATH': '/usr/local/nodejs/bin:/usr/local/nodejs/bin:/usr/local/sbin:/usr/local/bin:/usr/sbin:/usr/bin:/sbin:/bin:/usr/games:/usr/local/games:/snap/bin', 'HP__DROPOUT': '0.2', 'LS_COLORS': 'rs=0:di=01;34:ln=01;36:mh=00:pi=40;33:so=01;35:do=01;35:bd=40;33;01:cd=40;33;01:or=40;31;01:mi=00:su=37;41:sg=30;43:ca=30;41:tw=30;42:ow=34;42:st=37;44:ex=01;32:*.tar=01;31:*.tgz=01;31:*.arc=01;31:*.arj=01;31:*.taz=01;31:*.lha=01;31:*.lz4=01;31:*.lzh=01;31:*.lzma=01;31:*.tlz=01;31:*.txz=01;31:*.tzo=01;31:*.t7z=01;31:*.zip=01;31:*.z=01;31:*.dz=01;31:*.gz=01;31:*.lrz=01;31:*.lz=01;31:*.lzo=01;31:*.xz=01;31:*.zst=01;31:*.tzst=01;31:*.bz2=01;31:*.bz=01;31:*.tbz=01;31:*.tbz2=01;31:*.tz=01;31:*.deb=01;31:*.rpm=01;31:*.jar=01;31:*.war=01;31:*.ear=01;31:*.sar=01;31:*.rar=01;31:*.alz=01;31:*.ace=01;31:*.zoo=01;31:*.cpio=01;31:*.7z=01;31:*.rz=01;31:*.cab=01;31:*.wim=01;31:*.swm=01;31:*.dwm=01;31:*.esd=01;31:*.jpg=01;35:*.jpeg=01;35:*.mjpg=01;35:*.mjpeg=01;35:*.gif=01;35:*.bmp=01;35:*.pbm=01;35:*.pgm=01;35:*.ppm=01;35:*.tga=01;35:*.xbm=01;35:*.xpm=01;35:*.tif=01;35:*.tiff=01;35:*.png=01;35:*.svg=01;35:*.svgz=01;35:*.mng=01;35:*.pcx=01;35:*.mov=01;35:*.mpg=01;35:*.mpeg=01;35:*.m2v=01;35:*.mkv=01;35:*.webm=01;35:*.webp=01;35:*.ogm=01;35:*.mp4=01;35:*.m4v=01;35:*.mp4v=01;35:*.vob=01;35:*.qt=01;35:*.nuv=01;35:*.wmv=01;35:*.asf=01;35:*.rm=01;35:*.rmvb=01;35:*.flc=01;35:*.avi=01;35:*.fli=01;35:*.flv=01;35:*.gl=01;35:*.dl=01;35:*.xcf=01;35:*.xwd=01;35:*.yuv=01;35:*.cgm=01;35:*.emf=01;35:*.ogv=01;35:*.ogx=01;35:*.aac=00;36:*.au=00;36:*.flac=00;36:*.m4a=00;36:*.mid=00;36:*.midi=00;36:*.mka=00;36:*.mp3=00;36:*.mpc=00;36:*.ogg=00;36:*.ra=00;36:*.wav=00;36:*.oga=00;36:*.opus=00;36:*.spx=00;36:*.xspf=00;36:', 'TERM_PROGRAM': 'tmux', 'MLFLOW_EXPERIMENT': 'time_exp_v5_our_training_time_five_repeated', 'SHELL': '/bin/bash', 'PWD': '/mnt/sw_exp_data/tsc', 'SSH_CONNECTION': '10.233.106.128 41191 10.233.116.228 22', 'TZ': 'Asia/Shanghai', 'TMUX_PANE': '%0', 'HP__NUM_CONV_STAGES': '4', 'HP__D_MODEL': '128', '_MLFLOW_TELEMETRY_SESSION_ID': '55fa35ac321c4ef1b7642f26aab4cd82', 'MLFLOW_TRACKING_USERNAME': 'sunwu', 'MLFLOW_TRACKING_PASSWORD': 'xxxxx', 'MLFLOW_TRACKING_URI': 'http://192.168.10.61:5000', 'MLFLOW_EXPERIMENT_ID': '37', 'KMP_DUPLICATE_LIB_OK': 'True', 'KMP_INIT_AT_FORK': 'FALSE', 'TRAIN_START': '1779237832963086653', 'TORCHINDUCTOR_CACHE_DIR': '/tmp/torchinductor_root', 'TRAIN_END': '1779237999919238456', 'TEST_START': '1779237999919329801', 'TEST_END': '1779238006276226222'} | CN8: 7 | CO8: [128, 128] | CP8: 0 | CQ8: SpokenArabicDigits | CR8: moving_avg | CS8: bb5dc45f9c54bcc3d000a01a3a4f6f5af0910c1d929934bcb09ac76be69d1a37_4 | CT8: 13 | CU8: FALSE | CV8: MSE | CW8: TRUE | CX8: FALSE | CY8: 1 | CZ8: 2 | DA8: FALSE | DB8: FALSE | DC8: FALSE | DD8: cuda:0 | DE8: h | DF8: ./checkpoints/ | DG8: 0.5 | DH8: 10 | DI8: 0.3 | DJ8: 1 | DK8: 1 | DL8: gelu | DM8: FALSE | DN8: 32 | DO8: 1 | DP8: LOCAL | DQ8: classification_SpokenArabicDigits_M2SFormerATPSelfRegulationSCP2_UEA_ftM_sl93_ll48_pl0_dm128_nh8_el3_dl1_df256_expand2_dc4_fc1_ebtimeF_dtTrue_Exp_0bb5dc45f9c54bcc3d000a01a3a4f6f5af0910c1d929934bcb09ac76be69d1a37_4 | DR8: run.py | DS8: sunwu | DT8: =_xlfn.XLOOKUP(CQ8,dataset!B:B,dataset!A:A) -> SAD
